Workbook
Name \p: #REF!
Name \p: #REF!
Name __R: #REF!
Name _log2: #REF!
Name _log2: #REF!
Name _log3: #REF!
Name _log3: #REF!
Name _log4: #REF!
Name _log4: #REF!
Name _ph1: #REF!
Name _ph2: #REF!
Name _ph3: #REF!
Name _PH8: #REF!
Name _PH8: #REF!
Name _PH9: #REF!
Name _PH9: #REF!
Name _R: #REF!
Name _R: #REF!
Name _REV1: #REF!
Name _REV1: #REF!
Name a: #REF!
Name a: #REF!
Name aa: #REF!
Name abx: #REF!
Name accessories: #REF!
Name accr: #REF!
Name ACont: #REF!
Name Acont2: #REF!
Name AcquisitionProforma: #REF!
Name ad: #REF!
Name AGENCY_PRICING: #REF!,#REF!,#REF!,#REF!,#REF!,#REF!,#REF!,#REF!,#REF!,#REF!,#REF!,#REF!,#REF!,#REF!,#REF!,#REF!,#REF!,#REF!,#REF!,#REF!,#REF!
Name AGENCY_PRICING2: #REF!,#REF!,#REF!,#REF!,#REF!,#REF!,#REF!,#REF!,#REF!,#REF!,#REF!,#REF!
Name Allowances: #REF!
Name Allowances: #REF!
Name Altcashflow: #REF!
Name Am_2nd: #REF!
Name AMORTIZATION: #REF!
Name Amortization__Yrs: #REF!
Name Amortization__Yrs: #REF!
Name Analysis: #REF!
Name AP: #REF!
Name AP: #REF!
Name AR: #REF!
Name AR: #REF!
Name artwork: #REF!
Name asaasasa: #REF!
Name asbestos: #REF!
Name asdfasdf: #REF!
Name asdfasdf: #REF!
Name asSSAs: #REF!
Name Availability: #REF!
Name Bank: #REF!
Name Bankletter: #REF!
Name bathroom: #REF!
Name Binder: #REF!
Name bldgftprnt: #REF!
Name bldgftprnt: #REF!
Name BORDER: #REF!
Name BORDER: #REF!
Name BRIDGES12LAND: #REF!

Sheet Input CMHC MLI Select
A2: CMHC MLE SELECT
B4: TYPE OF FINANCING | C4: NEW CONSTRUCTION | E4: SHELTER TYPE | F4: Standard Rental Housing
B6: AFFORDABILITY
B8: REGION | C8: Urban Center - Toronto | E8: LOCATION&TYPE | F8: Ontario - Wood Frame 12 units and more
B10: MEDIAN ANNUAL SALARY | C10: =VLOOKUP(C8,DATA!B1:C82,2,FALSE) -> 53900
B11: MAX ANNUAL RENT | C11: =C10*0.3 -> 16170
B12: MAX MONTHLY RENT | C12: =C11/12 -> 1347.5
B14: # UNIT TOTAL | C14: =COUNTIFS(Table102[Rental Rate ($/mth)],">0") -> 170
B15: # UNIT AFFORDABLE | C15: =COUNTIFS(Table102[Market Unit],"No") -> 0
B16: UNIT AFFORDABLE % | C16: =IFERROR(C15/C14,0) -> 0 | D16: =IFERROR(C15/C14,"-") -> 0
B18: POINTS DISTRIBUTION | C18: LEVEL 1 | D18: LEVEL 2 | E18: LEVEL 3
B19: Points | C19: 50 | D19: 70 | E19: 100
B20: % of Units | C20: =IF(C4=DATA!F2,0.1,0.4) -> 0.1 | D20: =IF(C4=DATA!F2,0.15,0.6) -> 0.15 | E20: =IF(C4=DATA!F2,0.25,0.8) -> 0.25
B22: Commitment | C22: 10 YEARS
B24: TOTAL POINTS - AFFORDABILTY | D24: =IF(C16<C20,0,IF(AND(C16>=C20,C16<D20),C19,IF(AND(C16>=D20,C16<E20),D19,E19)))+IF(C16<=C20,0,IF(C22="10 YEARS",0,30)) -> 0
B27: ACCESSIBILITY
B29: POINTS DISTRIBUTION | C29: LEVEL 1 | D29: LEVEL 2
B30: Points | C30: 20 | D30: 30
B31: % UNIT CSA B651-18 or Universal Design | C31: 0.15 | D31: 1
B32: % UNIT CSA B651-18 and Universal Design | C32: N/A | D32: 15% accessible 85% build. Universale Design
B33: Rick Hansen Certification | C33: Score 60%-79% | D33: 80% or more
B35: Accesibility Level | C35: NONE
B37: TOTAL POINTS - ACCESSIBILITY | D37: =IF(C35=C29,20,IF(C35=D29,D30,0)) -> 0
B40: ENERGY EFFICIENCY AND GREENHOUSE GASES REDUCTIONS
B42: POINTS DISTRIBUTION | C42: LEVEL 1 | D42: LEVEL 2 | E42: LEVEL 3
B43: Points | C43: 20 | D43: 35 | E43: 50
B44: =IF(C4=DATA!$F$2,"Better Than 2017 NECB/2015 NBC","EE - GHG Reduction over current performance") -> Better Than 2017 NECB/2015 NBC | C44: =IF(C4=DATA!$F$2,0.2,0.15) -> 0.2 | D44: 0.25 | E44: 0.4
B46: ENERGY EFFICIENCY | C46: LEVEL 3
B48: TOTAL POINTS - ENERGY EFFICIENCY | D48: =IF(C46=C42,30,IF(C46=D42,D43,IF(C46=E42,E43,0))) -> 50
B52: TOTAL POINTS - MLI SELECT | E52: =D48+D37+D24 -> 50
B54: FLEXIBILITIES
B55: Points | C55: LTV | D55: DCR | E55: Amortization
B56: Min 50 points | C56: =IF($C$4=DATA!F$2,"Up to 95%","Up to 85%") -> Up to 95% | D56: 1.1 | E56: Up to 40 years
B57: Min 70 points | C57: =IF($C$4=DATA!F$2,"Up to 95%","Up to 95%") -> Up to 95% | D57: 1.1 | E57: Up to 45 years
B58: Min 100 points | C58: =IF($C$4=DATA!F$2,"Up to 95%","Up to 95%") -> Up to 95% | D58: 1.1 | E58: Up to 50 years
B62: Shelter Type | C62: =IF(F4=DATA!F58,DATA!F58,DATA!I58) -> Standard Rental Housing
B63: Type of Financing | C63: =C4 -> NEW CONSTRUCTION
B64: MLI Select Point | C64: =E52 -> 50
B65: Actual LTV | C65: ='Proforma Construction'!D50 -> 0.75998331
B66: LTV Tier | C66: {=_xlfn.IFS(C65<=65%,65%,C65<=70%,70%,C65<=75%,75%,C65<=80%,80%,C65<=85%,85%,C65<=90%,90%,C65>90%,">90%")} -> 0.8
...

Sheet Rent Roll(MLI Select)
A1: Unit Details (start with Unit #, Rental Rate or Unit Size) | L1: Unit Designations? | T1: What's included in the unit/rent?
A2: Unit Type | B2: Residential Stream Source | C2: Basement? | D2: Unit # | E2: Vacant? | F2: Rental Rate ($/mth) | G2: Monthly Rev. Accepted | H2: Annual Rev. Submitted | I2: Annual Rev. Accepted | J2: Unit Size (sq ft) | K2: Floor Area Accepted (SF) | L2: Market Unit | M2: Affordable Unit | N2: Subsidized Unit | O2: Care Services | P2: Affordable Care | Q2: Non-Res. Stream Source | R2: Business Type | S2: Lease Type | T2: Bulk Lease Unit | U2: Den Included Unit | V2: Second Bathroom | W2: Heating | X2: Electricity | Y2: Water | Z2: Washer/Dryer | AA2: Stove/Fridge | AB2: Dishwasher | AC2: Parking | AD2: Furniture | AE2: Other
A3: =IF(Table10[[#This Row],[Unit Type]]=0,"",Table10[[#This Row],[Unit Type]]) -> 1 Bedroom | B3: =IF(Table10[[#This Row],[Residential Stream Source]]=0,"",Table10[[#This Row],[Residential Stream Source]]) | C3: =IF(Table10[[#This Row],[Basement?]]=0,"",Table10[[#This Row],[Basement?]]) | D3: =IF(Table10[[#This Row],[Unit '#]]=0,"",Table10[[#This Row],[Unit '#]]) -> 1 | E3: =IF(Table10[[#This Row],[Vacant?]]=0,"",Table10[[#This Row],[Vacant?]]) -> Yes | F3: =IF(Table10[[#This Row],[Rental Rate ($/mth)]]=0,"",Table10[[#This Row],[Rental Rate ($/mth)]]) -> 2490 | J3: =IF(Table10[[#This Row],[Unit Size (sq ft)]]=0,"",Table10[[#This Row],[Unit Size (sq ft)]]) -> 624 | L3: =Table10[[#This Row],[Market Unit]] -> Yes | M3: =Table10[[#This Row],[Affordable Unit]] -> No | N3: =IF(Table10[[#This Row],[Subsidized Unit]]=0,"",Table10[[#This Row],[Subsidized Unit]]) | O3: =IF(Table10[[#This Row],[Care Services]]=0,"",Table10[[#This Row],[Care Services]]) | P3: =IF(Table10[[#This Row],[Affordable Care]]=0,"",Table10[[#This Row],[Affordable Care]]) | T3: =IF(Table10[[#This Row],[Bulk Lease Unit]]=0,"",Table10[[#This Row],[Bulk Lease Unit]]) | U3: =IF(Table10[[#This Row],[Den Included Unit]]=0,"",Table10[[#This Row],[Den Included Unit]]) | V3: =IF(Table10[[#This Row],[Second Bathroom]]=0,"",Table10[[#This Row],[Second Bathroom]]) | W3: =IF(Table10[[#This Row],[Heating]]=0,"",Table10[[#This Row],[Heating]]) | X3: =IF(Table10[[#This Row],[Electricity]]=0,"",Table10[[#This Row],[Electricity]]) | Y3: =IF(Table10[[#This Row],[Water]]=0,"",Table10[[#This Row],[Water]]) | Z3: =IF(Table10[[#This Row],[Washer/Dryer]]=0,"",Table10[[#This Row],[Washer/Dryer]]) | AA3: =IF(Table10[[#This Row],[Stove/Fridge]]=0,"",Table10[[#This Row],[Stove/Fridge]]) | AB3: =IF(Table10[[#This Row],[Dishwasher]]=0,"",Table10[[#This Row],[Dishwasher]]) | AC3: =IF(Table10[[#This Row],[Parking]]=0,"",Table10[[#This Row],[Parking]]) | AD3: =IF(Table10[[#This Row],[Furniture]]=0,"",Table10[[#This Row],[Furniture]]) -> No | AE3: =IF(Table10[[#This Row],[Other]]=0,"",Table10[[#This Row],[Other]])
A4: =IF(Table10[[#This Row],[Unit Type]]=0,"",Table10[[#This Row],[Unit Type]]) -> 1 Bedroom | B4: =IF(Table10[[#This Row],[Residential Stream Source]]=0,"",Table10[[#This Row],[Residential Stream Source]]) | C4: =IF(Table10[[#This Row],[Basement?]]=0,"",Table10[[#This Row],[Basement?]]) | D4: =IF(Table10[[#This Row],[Unit '#]]=0,"",Table10[[#This Row],[Unit '#]]) -> 2 | E4: =IF(Table10[[#This Row],[Vacant?]]=0,"",Table10[[#This Row],[Vacant?]]) -> Yes | F4: =IF(Table10[[#This Row],[Rental Rate ($/mth)]]=0,"",Table10[[#This Row],[Rental Rate ($/mth)]]) -> 2490 | J4: =IF(Table10[[#This Row],[Unit Size (sq ft)]]=0,"",Table10[[#This Row],[Unit Size (sq ft)]]) -> 624 | L4: =Table10[[#This Row],[Market Unit]] -> Yes | M4: =Table10[[#This Row],[Affordable Unit]] -> No | N4: =IF(Table10[[#This Row],[Subsidized Unit]]=0,"",Table10[[#This Row],[Subsidized Unit]]) | O4: =IF(Table10[[#This Row],[Care Services]]=0,"",Table10[[#This Row],[Care Services]]) | P4: =IF(Table10[[#This Row],[Affordable Care]]=0,"",Table10[[#This Row],[Affordable Care]]) | T4: =IF(Table10[[#This Row],[Bulk Lease Unit]]=0,"",Table10[[#This Row],[Bulk Lease Unit]]) | U4: =IF(Table10[[#This Row],[Den Included Unit]]=0,"",Table10[[#This Row],[Den Included Unit]]) | V4: =IF(Table10[[#This Row],[Second Bathroom]]=0,"",Table10[[#This Row],[Second Bathroom]]) | W4: =IF(Table10[[#This Row],[Heating]]=0,"",Table10[[#This Row],[Heating]]) | X4: =IF(Table10[[#This Row],[Electricity]]=0,"",Table10[[#This Row],[Electricity]]) | Y4: =IF(Table10[[#This Row],[Water]]=0,"",Table10[[#This Row],[Water]]) | Z4: =IF(Table10[[#This Row],[Washer/Dryer]]=0,"",Table10[[#This Row],[Washer/Dryer]]) | AA4: =IF(Table10[[#This Row],[Stove/Fridge]]=0,"",Table10[[#This Row],[Stove/Fridge]]) | AB4: =IF(Table10[[#This Row],[Dishwasher]]=0,"",Table10[[#This Row],[Dishwasher]]) | AC4: =IF(Table10[[#This Row],[Parking]]=0,"",Table10[[#This Row],[Parking]]) | AD4: =IF(Table10[[#This Row],[Furniture]]=0,"",Table10[[#This Row],[Furniture]]) | AE4: =IF(Table10[[#This Row],[Other]]=0,"",Table10[[#This Row],[Other]])
A5: =IF(Table10[[#This Row],[Unit Type]]=0,"",Table10[[#This Row],[Unit Type]]) -> 1 Bedroom | B5: =IF(Table10[[#This Row],[Residential Stream Source]]=0,"",Table10[[#This Row],[Residential Stream Source]]) | C5: =IF(Table10[[#This Row],[Basement?]]=0,"",Table10[[#This Row],[Basement?]]) | D5: =IF(Table10[[#This Row],[Unit '#]]=0,"",Table10[[#This Row],[Unit '#]]) -> 3 | E5: =IF(Table10[[#This Row],[Vacant?]]=0,"",Table10[[#This Row],[Vacant?]]) -> Yes | F5: =IF(Table10[[#This Row],[Rental Rate ($/mth)]]=0,"",Table10[[#This Row],[Rental Rate ($/mth)]]) -> 2490 | J5: =IF(Table10[[#This Row],[Unit Size (sq ft)]]=0,"",Table10[[#This Row],[Unit Size (sq ft)]]) -> 624 | L5: =Table10[[#This Row],[Market Unit]] -> Yes | M5: =Table10[[#This Row],[Affordable Unit]] -> No | N5: =IF(Table10[[#This Row],[Subsidized Unit]]=0,"",Table10[[#This Row],[Subsidized Unit]]) | O5: =IF(Table10[[#This Row],[Care Services]]=0,"",Table10[[#This Row],[Care Services]]) | P5: =IF(Table10[[#This Row],[Affordable Care]]=0,"",Table10[[#This Row],[Affordable Care]]) | T5: =IF(Table10[[#This Row],[Bulk Lease Unit]]=0,"",Table10[[#This Row],[Bulk Lease Unit]]) | U5: =IF(Table10[[#This Row],[Den Included Unit]]=0,"",Table10[[#This Row],[Den Included Unit]]) | V5: =IF(Table10[[#This Row],[Second Bathroom]]=0,"",Table10[[#This Row],[Second Bathroom]]) | W5: =IF(Table10[[#This Row],[Heating]]=0,"",Table10[[#This Row],[Heating]]) | X5: =IF(Table10[[#This Row],[Electricity]]=0,"",Table10[[#This Row],[Electricity]]) | Y5: =IF(Table10[[#This Row],[Water]]=0,"",Table10[[#This Row],[Water]]) | Z5: =IF(Table10[[#This Row],[Washer/Dryer]]=0,"",Table10[[#This Row],[Washer/Dryer]]) | AA5: =IF(Table10[[#This Row],[Stove/Fridge]]=0,"",Table10[[#This Row],[Stove/Fridge]]) | AB5: =IF(Table10[[#This Row],[Dishwasher]]=0,"",Table10[[#This Row],[Dishwasher]]) | AC5: =IF(Table10[[#This Row],[Parking]]=0,"",Table10[[#This Row],[Parking]]) | AD5: =IF(Table10[[#This Row],[Furniture]]=0,"",Table10[[#This Row],[Furniture]]) | AE5: =IF(Table10[[#This Row],[Other]]=0,"",Table10[[#This Row],[Other]])
A6: =IF(Table10[[#This Row],[Unit Type]]=0,"",Table10[[#This Row],[Unit Type]]) -> 1 Bedroom | B6: =IF(Table10[[#This Row],[Residential Stream Source]]=0,"",Table10[[#This Row],[Residential Stream Source]]) | C6: =IF(Table10[[#This Row],[Basement?]]=0,"",Table10[[#This Row],[Basement?]]) | D6: =IF(Table10[[#This Row],[Unit '#]]=0,"",Table10[[#This Row],[Unit '#]]) -> 4 | E6: =IF(Table10[[#This Row],[Vacant?]]=0,"",Table10[[#This Row],[Vacant?]]) -> Yes | F6: =IF(Table10[[#This Row],[Rental Rate ($/mth)]]=0,"",Table10[[#This Row],[Rental Rate ($/mth)]]) -> 2490 | J6: =IF(Table10[[#This Row],[Unit Size (sq ft)]]=0,"",Table10[[#This Row],[Unit Size (sq ft)]]) -> 624 | L6: =Table10[[#This Row],[Market Unit]] -> Yes | M6: =Table10[[#This Row],[Affordable Unit]] -> No | N6: =IF(Table10[[#This Row],[Subsidized Unit]]=0,"",Table10[[#This Row],[Subsidized Unit]]) | O6: =IF(Table10[[#This Row],[Care Services]]=0,"",Table10[[#This Row],[Care Services]]) | P6: =IF(Table10[[#This Row],[Affordable Care]]=0,"",Table10[[#This Row],[Affordable Care]]) | T6: =IF(Table10[[#This Row],[Bulk Lease Unit]]=0,"",Table10[[#This Row],[Bulk Lease Unit]]) | U6: =IF(Table10[[#This Row],[Den Included Unit]]=0,"",Table10[[#This Row],[Den Included Unit]]) | V6: =IF(Table10[[#This Row],[Second Bathroom]]=0,"",Table10[[#This Row],[Second Bathroom]]) | W6: =IF(Table10[[#This Row],[Heating]]=0,"",Table10[[#This Row],[Heating]]) | X6: =IF(Table10[[#This Row],[Electricity]]=0,"",Table10[[#This Row],[Electricity]]) | Y6: =IF(Table10[[#This Row],[Water]]=0,"",Table10[[#This Row],[Water]]) | Z6: =IF(Table10[[#This Row],[Washer/Dryer]]=0,"",Table10[[#This Row],[Washer/Dryer]]) | AA6: =IF(Table10[[#This Row],[Stove/Fridge]]=0,"",Table10[[#This Row],[Stove/Fridge]]) | AB6: =IF(Table10[[#This Row],[Dishwasher]]=0,"",Table10[[#This Row],[Dishwasher]]) | AC6: =IF(Table10[[#This Row],[Parking]]=0,"",Table10[[#This Row],[Parking]]) | AD6: =IF(Table10[[#This Row],[Furniture]]=0,"",Table10[[#This Row],[Furniture]]) | AE6: =IF(Table10[[#This Row],[Other]]=0,"",Table10[[#This Row],[Other]])
A7: =IF(Table10[[#This Row],[Unit Type]]=0,"",Table10[[#This Row],[Unit Type]]) -> 1 Bedroom | B7: =IF(Table10[[#This Row],[Residential Stream Source]]=0,"",Table10[[#This Row],[Residential Stream Source]]) | C7: =IF(Table10[[#This Row],[Basement?]]=0,"",Table10[[#This Row],[Basement?]]) | D7: =IF(Table10[[#This Row],[Unit '#]]=0,"",Table10[[#This Row],[Unit '#]]) -> 5 | E7: =IF(Table10[[#This Row],[Vacant?]]=0,"",Table10[[#This Row],[Vacant?]]) -> Yes | F7: =IF(Table10[[#This Row],[Rental Rate ($/mth)]]=0,"",Table10[[#This Row],[Rental Rate ($/mth)]]) -> 2490 | J7: =IF(Table10[[#This Row],[Unit Size (sq ft)]]=0,"",Table10[[#This Row],[Unit Size (sq ft)]]) -> 624 | L7: =Table10[[#This Row],[Market Unit]] -> Yes | M7: =Table10[[#This Row],[Affordable Unit]] -> No | N7: =IF(Table10[[#This Row],[Subsidized Unit]]=0,"",Table10[[#This Row],[Subsidized Unit]]) | O7: =IF(Table10[[#This Row],[Care Services]]=0,"",Table10[[#This Row],[Care Services]]) | P7: =IF(Table10[[#This Row],[Affordable Care]]=0,"",Table10[[#This Row],[Affordable Care]]) | T7: =IF(Table10[[#This Row],[Bulk Lease Unit]]=0,"",Table10[[#This Row],[Bulk Lease Unit]]) | U7: =IF(Table10[[#This Row],[Den Included Unit]]=0,"",Table10[[#This Row],[Den Included Unit]]) | V7: =IF(Table10[[#This Row],[Second Bathroom]]=0,"",Table10[[#This Row],[Second Bathroom]]) | W7: =IF(Table10[[#This Row],[Heating]]=0,"",Table10[[#This Row],[Heating]]) | X7: =IF(Table10[[#This Row],[Electricity]]=0,"",Table10[[#This Row],[Electricity]]) | Y7: =IF(Table10[[#This Row],[Water]]=0,"",Table10[[#This Row],[Water]]) | Z7: =IF(Table10[[#This Row],[Washer/Dryer]]=0,"",Table10[[#This Row],[Washer/Dryer]]) | AA7: =IF(Table10[[#This Row],[Stove/Fridge]]=0,"",Table10[[#This Row],[Stove/Fridge]]) | AB7: =IF(Table10[[#This Row],[Dishwasher]]=0,"",Table10[[#This Row],[Dishwasher]]) | AC7: =IF(Table10[[#This Row],[Parking]]=0,"",Table10[[#This Row],[Parking]]) | AD7: =IF(Table10[[#This Row],[Furniture]]=0,"",Table10[[#This Row],[Furniture]]) | AE7: =IF(Table10[[#This Row],[Other]]=0,"",Table10[[#This Row],[Other]])
A8: =IF(Table10[[#This Row],[Unit Type]]=0,"",Table10[[#This Row],[Unit Type]]) -> 1 Bedroom | D8: =IF(Table10[[#This Row],[Unit '#]]=0,"",Table10[[#This Row],[Unit '#]]) -> 6 | F8: =IF(Table10[[#This Row],[Rental Rate ($/mth)]]=0,"",Table10[[#This Row],[Rental Rate ($/mth)]]) -> 2490 | J8: =IF(Table10[[#This Row],[Unit Size (sq ft)]]=0,"",Table10[[#This Row],[Unit Size (sq ft)]]) -> 624 | L8: =Table10[[#This Row],[Market Unit]] -> Yes | M8: =Table10[[#This Row],[Affordable Unit]] -> No | N8: =IF(Table10[[#This Row],[Subsidized Unit]]=0,"",Table10[[#This Row],[Subsidized Unit]]) | O8: =IF(Table10[[#This Row],[Care Services]]=0,"",Table10[[#This Row],[Care Services]]) | P8: =IF(Table10[[#This Row],[Affordable Care]]=0,"",Table10[[#This Row],[Affordable Care]]) | T8: =IF(Table10[[#This Row],[Bulk Lease Unit]]=0,"",Table10[[#This Row],[Bulk Lease Unit]]) | U8: =IF(Table10[[#This Row],[Den Included Unit]]=0,"",Table10[[#This Row],[Den Included Unit]]) | V8: =IF(Table10[[#This Row],[Second Bathroom]]=0,"",Table10[[#This Row],[Second Bathroom]]) | W8: =IF(Table10[[#This Row],[Heating]]=0,"",Table10[[#This Row],[Heating]]) | X8: =IF(Table10[[#This Row],[Electricity]]=0,"",Table10[[#This Row],[Electricity]]) | Y8: =IF(Table10[[#This Row],[Water]]=0,"",Table10[[#This Row],[Water]]) | Z8: =IF(Table10[[#This Row],[Washer/Dryer]]=0,"",Table10[[#This Row],[Washer/Dryer]]) | AA8: =IF(Table10[[#This Row],[Stove/Fridge]]=0,"",Table10[[#This Row],[Stove/Fridge]]) | AB8: =IF(Table10[[#This Row],[Dishwasher]]=0,"",Table10[[#This Row],[Dishwasher]]) | AC8: =IF(Table10[[#This Row],[Parking]]=0,"",Table10[[#This Row],[Parking]]) | AD8: =IF(Table10[[#This Row],[Furniture]]=0,"",Table10[[#This Row],[Furniture]]) | AE8: =IF(Table10[[#This Row],[Other]]=0,"",Table10[[#This Row],[Other]])
A9: =IF(Table10[[#This Row],[Unit Type]]=0,"",Table10[[#This Row],[Unit Type]]) -> 1 Bedroom | D9: =IF(Table10[[#This Row],[Unit '#]]=0,"",Table10[[#This Row],[Unit '#]]) -> 7 | F9: =IF(Table10[[#This Row],[Rental Rate ($/mth)]]=0,"",Table10[[#This Row],[Rental Rate ($/mth)]]) -> 2490 | J9: =IF(Table10[[#This Row],[Unit Size (sq ft)]]=0,"",Table10[[#This Row],[Unit Size (sq ft)]]) -> 624 | L9: =Table10[[#This Row],[Market Unit]] -> Yes | M9: =Table10[[#This Row],[Affordable Unit]] -> No | N9: =IF(Table10[[#This Row],[Subsidized Unit]]=0,"",Table10[[#This Row],[Subsidized Unit]]) | O9: =IF(Table10[[#This Row],[Care Services]]=0,"",Table10[[#This Row],[Care Services]]) | P9: =IF(Table10[[#This Row],[Affordable Care]]=0,"",Table10[[#This Row],[Affordable Care]]) | T9: =IF(Table10[[#This Row],[Bulk Lease Unit]]=0,"",Table10[[#This Row],[Bulk Lease Unit]]) | U9: =IF(Table10[[#This Row],[Den Included Unit]]=0,"",Table10[[#This Row],[Den Included Unit]]) | V9: =IF(Table10[[#This Row],[Second Bathroom]]=0,"",Table10[[#This Row],[Second Bathroom]]) | W9: =IF(Table10[[#This Row],[Heating]]=0,"",Table10[[#This Row],[Heating]]) | X9: =IF(Table10[[#This Row],[Electricity]]=0,"",Table10[[#This Row],[Electricity]]) | Y9: =IF(Table10[[#This Row],[Water]]=0,"",Table10[[#This Row],[Water]]) | Z9: =IF(Table10[[#This Row],[Washer/Dryer]]=0,"",Table10[[#This Row],[Washer/Dryer]]) | AA9: =IF(Table10[[#This Row],[Stove/Fridge]]=0,"",Table10[[#This Row],[Stove/Fridge]]) | AB9: =IF(Table10[[#This Row],[Dishwasher]]=0,"",Table10[[#This Row],[Dishwasher]]) | AC9: =IF(Table10[[#This Row],[Parking]]=0,"",Table10[[#This Row],[Parking]]) | AD9: =IF(Table10[[#This Row],[Furniture]]=0,"",Table10[[#This Row],[Furniture]]) | AE9: =IF(Table10[[#This Row],[Other]]=0,"",Table10[[#This Row],[Other]])
A10: =IF(Table10[[#This Row],[Unit Type]]=0,"",Table10[[#This Row],[Unit Type]]) -> 1 Bedroom | D10: =IF(Table10[[#This Row],[Unit '#]]=0,"",Table10[[#This Row],[Unit '#]]) -> 8 | F10: =IF(Table10[[#This Row],[Rental Rate ($/mth)]]=0,"",Table10[[#This Row],[Rental Rate ($/mth)]]) -> 2490 | J10: =IF(Table10[[#This Row],[Unit Size (sq ft)]]=0,"",Table10[[#This Row],[Unit Size (sq ft)]]) -> 624 | L10: =Table10[[#This Row],[Market Unit]] -> Yes | M10: =Table10[[#This Row],[Affordable Unit]] -> No | N10: =IF(Table10[[#This Row],[Subsidized Unit]]=0,"",Table10[[#This Row],[Subsidized Unit]]) | O10: =IF(Table10[[#This Row],[Care Services]]=0,"",Table10[[#This Row],[Care Services]]) | P10: =IF(Table10[[#This Row],[Affordable Care]]=0,"",Table10[[#This Row],[Affordable Care]]) | T10: =IF(Table10[[#This Row],[Bulk Lease Unit]]=0,"",Table10[[#This Row],[Bulk Lease Unit]]) | U10: =IF(Table10[[#This Row],[Den Included Unit]]=0,"",Table10[[#This Row],[Den Included Unit]]) | V10: =IF(Table10[[#This Row],[Second Bathroom]]=0,"",Table10[[#This Row],[Second Bathroom]]) | W10: =IF(Table10[[#This Row],[Heating]]=0,"",Table10[[#This Row],[Heating]]) | X10: =IF(Table10[[#This Row],[Electricity]]=0,"",Table10[[#This Row],[Electricity]]) | Y10: =IF(Table10[[#This Row],[Water]]=0,"",Table10[[#This Row],[Water]]) | Z10: =IF(Table10[[#This Row],[Washer/Dryer]]=0,"",Table10[[#This Row],[Washer/Dryer]]) | AA10: =IF(Table10[[#This Row],[Stove/Fridge]]=0,"",Table10[[#This Row],[Stove/Fridge]]) | AB10: =IF(Table10[[#This Row],[Dishwasher]]=0,"",Table10[[#This Row],[Dishwasher]]) | AC10: =IF(Table10[[#This Row],[Parking]]=0,"",Table10[[#This Row],[Parking]]) | AD10: =IF(Table10[[#This Row],[Furniture]]=0,"",Table10[[#This Row],[Furniture]]) | AE10: =IF(Table10[[#This Row],[Other]]=0,"",Table10[[#This Row],[Other]])
A11: =IF(Table10[[#This Row],[Unit Type]]=0,"",Table10[[#This Row],[Unit Type]]) -> 1 Bedroom | D11: =IF(Table10[[#This Row],[Unit '#]]=0,"",Table10[[#This Row],[Unit '#]]) -> 9 | F11: =IF(Table10[[#This Row],[Rental Rate ($/mth)]]=0,"",Table10[[#This Row],[Rental Rate ($/mth)]]) -> 2490 | J11: =IF(Table10[[#This Row],[Unit Size (sq ft)]]=0,"",Table10[[#This Row],[Unit Size (sq ft)]]) -> 624 | L11: =Table10[[#This Row],[Market Unit]] -> Yes | M11: =Table10[[#This Row],[Affordable Unit]] -> No | N11: =IF(Table10[[#This Row],[Subsidized Unit]]=0,"",Table10[[#This Row],[Subsidized Unit]]) | O11: =IF(Table10[[#This Row],[Care Services]]=0,"",Table10[[#This Row],[Care Services]]) | P11: =IF(Table10[[#This Row],[Affordable Care]]=0,"",Table10[[#This Row],[Affordable Care]]) | T11: =IF(Table10[[#This Row],[Bulk Lease Unit]]=0,"",Table10[[#This Row],[Bulk Lease Unit]]) | U11: =IF(Table10[[#This Row],[Den Included Unit]]=0,"",Table10[[#This Row],[Den Included Unit]]) | V11: =IF(Table10[[#This Row],[Second Bathroom]]=0,"",Table10[[#This Row],[Second Bathroom]]) | W11: =IF(Table10[[#This Row],[Heating]]=0,"",Table10[[#This Row],[Heating]]) | X11: =IF(Table10[[#This Row],[Electricity]]=0,"",Table10[[#This Row],[Electricity]]) | Y11: =IF(Table10[[#This Row],[Water]]=0,"",Table10[[#This Row],[Water]]) | Z11: =IF(Table10[[#This Row],[Washer/Dryer]]=0,"",Table10[[#This Row],[Washer/Dryer]]) | AA11: =IF(Table10[[#This Row],[Stove/Fridge]]=0,"",Table10[[#This Row],[Stove/Fridge]]) | AB11: =IF(Table10[[#This Row],[Dishwasher]]=0,"",Table10[[#This Row],[Dishwasher]]) | AC11: =IF(Table10[[#This Row],[Parking]]=0,"",Table10[[#This Row],[Parking]]) | AD11: =IF(Table10[[#This Row],[Furniture]]=0,"",Table10[[#This Row],[Furniture]]) | AE11: =IF(Table10[[#This Row],[Other]]=0,"",Table10[[#This Row],[Other]])
A12: =IF(Table10[[#This Row],[Unit Type]]=0,"",Table10[[#This Row],[Unit Type]]) -> 1 Bedroom | D12: =IF(Table10[[#This Row],[Unit '#]]=0,"",Table10[[#This Row],[Unit '#]]) -> 10 | F12: =IF(Table10[[#This Row],[Rental Rate ($/mth)]]=0,"",Table10[[#This Row],[Rental Rate ($/mth)]]) -> 2490 | J12: =IF(Table10[[#This Row],[Unit Size (sq ft)]]=0,"",Table10[[#This Row],[Unit Size (sq ft)]]) -> 624 | L12: =Table10[[#This Row],[Market Unit]] -> Yes | M12: =Table10[[#This Row],[Affordable Unit]] -> No | N12: =IF(Table10[[#This Row],[Subsidized Unit]]=0,"",Table10[[#This Row],[Subsidized Unit]]) | O12: =IF(Table10[[#This Row],[Care Services]]=0,"",Table10[[#This Row],[Care Services]]) | P12: =IF(Table10[[#This Row],[Affordable Care]]=0,"",Table10[[#This Row],[Affordable Care]]) | T12: =IF(Table10[[#This Row],[Bulk Lease Unit]]=0,"",Table10[[#This Row],[Bulk Lease Unit]]) | U12: =IF(Table10[[#This Row],[Den Included Unit]]=0,"",Table10[[#This Row],[Den Included Unit]]) | V12: =IF(Table10[[#This Row],[Second Bathroom]]=0,"",Table10[[#This Row],[Second Bathroom]]) | W12: =IF(Table10[[#This Row],[Heating]]=0,"",Table10[[#This Row],[Heating]]) | X12: =IF(Table10[[#This Row],[Electricity]]=0,"",Table10[[#This Row],[Electricity]]) | Y12: =IF(Table10[[#This Row],[Water]]=0,"",Table10[[#This Row],[Water]]) | Z12: =IF(Table10[[#This Row],[Washer/Dryer]]=0,"",Table10[[#This Row],[Washer/Dryer]]) | AA12: =IF(Table10[[#This Row],[Stove/Fridge]]=0,"",Table10[[#This Row],[Stove/Fridge]]) | AB12: =IF(Table10[[#This Row],[Dishwasher]]=0,"",Table10[[#This Row],[Dishwasher]]) | AC12: =IF(Table10[[#This Row],[Parking]]=0,"",Table10[[#This Row],[Parking]]) | AD12: =IF(Table10[[#This Row],[Furniture]]=0,"",Table10[[#This Row],[Furniture]]) | AE12: =IF(Table10[[#This Row],[Other]]=0,"",Table10[[#This Row],[Other]])
A13: =IF(Table10[[#This Row],[Unit Type]]=0,"",Table10[[#This Row],[Unit Type]]) -> 1 Bedroom | D13: =IF(Table10[[#This Row],[Unit '#]]=0,"",Table10[[#This Row],[Unit '#]]) -> 11 | F13: =IF(Table10[[#This Row],[Rental Rate ($/mth)]]=0,"",Table10[[#This Row],[Rental Rate ($/mth)]]) -> 2490 | J13: =IF(Table10[[#This Row],[Unit Size (sq ft)]]=0,"",Table10[[#This Row],[Unit Size (sq ft)]]) -> 624 | L13: =Table10[[#This Row],[Market Unit]] -> Yes | M13: =Table10[[#This Row],[Affordable Unit]] -> No | N13: =IF(Table10[[#This Row],[Subsidized Unit]]=0,"",Table10[[#This Row],[Subsidized Unit]]) | O13: =IF(Table10[[#This Row],[Care Services]]=0,"",Table10[[#This Row],[Care Services]]) | P13: =IF(Table10[[#This Row],[Affordable Care]]=0,"",Table10[[#This Row],[Affordable Care]]) | T13: =IF(Table10[[#This Row],[Bulk Lease Unit]]=0,"",Table10[[#This Row],[Bulk Lease Unit]]) | U13: =IF(Table10[[#This Row],[Den Included Unit]]=0,"",Table10[[#This Row],[Den Included Unit]]) | V13: =IF(Table10[[#This Row],[Second Bathroom]]=0,"",Table10[[#This Row],[Second Bathroom]]) | W13: =IF(Table10[[#This Row],[Heating]]=0,"",Table10[[#This Row],[Heating]]) | X13: =IF(Table10[[#This Row],[Electricity]]=0,"",Table10[[#This Row],[Electricity]]) | Y13: =IF(Table10[[#This Row],[Water]]=0,"",Table10[[#This Row],[Water]]) | Z13: =IF(Table10[[#This Row],[Washer/Dryer]]=0,"",Table10[[#This Row],[Washer/Dryer]]) | AA13: =IF(Table10[[#This Row],[Stove/Fridge]]=0,"",Table10[[#This Row],[Stove/Fridge]]) | AB13: =IF(Table10[[#This Row],[Dishwasher]]=0,"",Table10[[#This Row],[Dishwasher]]) | AC13: =IF(Table10[[#This Row],[Parking]]=0,"",Table10[[#This Row],[Parking]]) | AD13: =IF(Table10[[#This Row],[Furniture]]=0,"",Table10[[#This Row],[Furniture]]) | AE13: =IF(Table10[[#This Row],[Other]]=0,"",Table10[[#This Row],[Other]])
A14: =IF(Table10[[#This Row],[Unit Type]]=0,"",Table10[[#This Row],[Unit Type]]) -> 1 Bedroom | D14: =IF(Table10[[#This Row],[Unit '#]]=0,"",Table10[[#This Row],[Unit '#]]) -> 12 | F14: =IF(Table10[[#This Row],[Rental Rate ($/mth)]]=0,"",Table10[[#This Row],[Rental Rate ($/mth)]]) -> 2490 | J14: =IF(Table10[[#This Row],[Unit Size (sq ft)]]=0,"",Table10[[#This Row],[Unit Size (sq ft)]]) -> 624 | L14: =Table10[[#This Row],[Market Unit]] -> Yes | M14: =Table10[[#This Row],[Affordable Unit]] -> No | N14: =IF(Table10[[#This Row],[Subsidized Unit]]=0,"",Table10[[#This Row],[Subsidized Unit]]) | O14: =IF(Table10[[#This Row],[Care Services]]=0,"",Table10[[#This Row],[Care Services]]) | P14: =IF(Table10[[#This Row],[Affordable Care]]=0,"",Table10[[#This Row],[Affordable Care]]) | T14: =IF(Table10[[#This Row],[Bulk Lease Unit]]=0,"",Table10[[#This Row],[Bulk Lease Unit]]) | U14: =IF(Table10[[#This Row],[Den Included Unit]]=0,"",Table10[[#This Row],[Den Included Unit]]) | V14: =IF(Table10[[#This Row],[Second Bathroom]]=0,"",Table10[[#This Row],[Second Bathroom]]) | W14: =IF(Table10[[#This Row],[Heating]]=0,"",Table10[[#This Row],[Heating]]) | X14: =IF(Table10[[#This Row],[Electricity]]=0,"",Table10[[#This Row],[Electricity]]) | Y14: =IF(Table10[[#This Row],[Water]]=0,"",Table10[[#This Row],[Water]]) | Z14: =IF(Table10[[#This Row],[Washer/Dryer]]=0,"",Table10[[#This Row],[Washer/Dryer]]) | AA14: =IF(Table10[[#This Row],[Stove/Fridge]]=0,"",Table10[[#This Row],[Stove/Fridge]]) | AB14: =IF(Table10[[#This Row],[Dishwasher]]=0,"",Table10[[#This Row],[Dishwasher]]) | AC14: =IF(Table10[[#This Row],[Parking]]=0,"",Table10[[#This Row],[Parking]]) | AD14: =IF(Table10[[#This Row],[Furniture]]=0,"",Table10[[#This Row],[Furniture]]) | AE14: =IF(Table10[[#This Row],[Other]]=0,"",Table10[[#This Row],[Other]])
A15: =IF(Table10[[#This Row],[Unit Type]]=0,"",Table10[[#This Row],[Unit Type]]) -> 1 Bedroom | D15: =IF(Table10[[#This Row],[Unit '#]]=0,"",Table10[[#This Row],[Unit '#]]) -> 13 | F15: =IF(Table10[[#This Row],[Rental Rate ($/mth)]]=0,"",Table10[[#This Row],[Rental Rate ($/mth)]]) -> 2490 | J15: =IF(Table10[[#This Row],[Unit Size (sq ft)]]=0,"",Table10[[#This Row],[Unit Size (sq ft)]]) -> 624 | L15: =Table10[[#This Row],[Market Unit]] -> Yes | M15: =Table10[[#This Row],[Affordable Unit]] -> No | N15: =IF(Table10[[#This Row],[Subsidized Unit]]=0,"",Table10[[#This Row],[Subsidized Unit]]) | O15: =IF(Table10[[#This Row],[Care Services]]=0,"",Table10[[#This Row],[Care Services]]) | P15: =IF(Table10[[#This Row],[Affordable Care]]=0,"",Table10[[#This Row],[Affordable Care]]) | T15: =IF(Table10[[#This Row],[Bulk Lease Unit]]=0,"",Table10[[#This Row],[Bulk Lease Unit]]) | U15: =IF(Table10[[#This Row],[Den Included Unit]]=0,"",Table10[[#This Row],[Den Included Unit]]) | V15: =IF(Table10[[#This Row],[Second Bathroom]]=0,"",Table10[[#This Row],[Second Bathroom]]) | W15: =IF(Table10[[#This Row],[Heating]]=0,"",Table10[[#This Row],[Heating]]) | X15: =IF(Table10[[#This Row],[Electricity]]=0,"",Table10[[#This Row],[Electricity]]) | Y15: =IF(Table10[[#This Row],[Water]]=0,"",Table10[[#This Row],[Water]]) | Z15: =IF(Table10[[#This Row],[Washer/Dryer]]=0,"",Table10[[#This Row],[Washer/Dryer]]) | AA15: =IF(Table10[[#This Row],[Stove/Fridge]]=0,"",Table10[[#This Row],[Stove/Fridge]]) | AB15: =IF(Table10[[#This Row],[Dishwasher]]=0,"",Table10[[#This Row],[Dishwasher]]) | AC15: =IF(Table10[[#This Row],[Parking]]=0,"",Table10[[#This Row],[Parking]]) | AD15: =IF(Table10[[#This Row],[Furniture]]=0,"",Table10[[#This Row],[Furniture]]) | AE15: =IF(Table10[[#This Row],[Other]]=0,"",Table10[[#This Row],[Other]])
A16: =IF(Table10[[#This Row],[Unit Type]]=0,"",Table10[[#This Row],[Unit Type]]) -> 1 Bedroom | D16: =IF(Table10[[#This Row],[Unit '#]]=0,"",Table10[[#This Row],[Unit '#]]) -> 14 | F16: =IF(Table10[[#This Row],[Rental Rate ($/mth)]]=0,"",Table10[[#This Row],[Rental Rate ($/mth)]]) -> 2490 | J16: =IF(Table10[[#This Row],[Unit Size (sq ft)]]=0,"",Table10[[#This Row],[Unit Size (sq ft)]]) -> 624 | L16: =Table10[[#This Row],[Market Unit]] -> Yes | M16: =Table10[[#This Row],[Affordable Unit]] -> No | N16: =IF(Table10[[#This Row],[Subsidized Unit]]=0,"",Table10[[#This Row],[Subsidized Unit]]) | O16: =IF(Table10[[#This Row],[Care Services]]=0,"",Table10[[#This Row],[Care Services]]) | P16: =IF(Table10[[#This Row],[Affordable Care]]=0,"",Table10[[#This Row],[Affordable Care]]) | T16: =IF(Table10[[#This Row],[Bulk Lease Unit]]=0,"",Table10[[#This Row],[Bulk Lease Unit]]) | U16: =IF(Table10[[#This Row],[Den Included Unit]]=0,"",Table10[[#This Row],[Den Included Unit]]) | V16: =IF(Table10[[#This Row],[Second Bathroom]]=0,"",Table10[[#This Row],[Second Bathroom]]) | W16: =IF(Table10[[#This Row],[Heating]]=0,"",Table10[[#This Row],[Heating]]) | X16: =IF(Table10[[#This Row],[Electricity]]=0,"",Table10[[#This Row],[Electricity]]) | Y16: =IF(Table10[[#This Row],[Water]]=0,"",Table10[[#This Row],[Water]]) | Z16: =IF(Table10[[#This Row],[Washer/Dryer]]=0,"",Table10[[#This Row],[Washer/Dryer]]) | AA16: =IF(Table10[[#This Row],[Stove/Fridge]]=0,"",Table10[[#This Row],[Stove/Fridge]]) | AB16: =IF(Table10[[#This Row],[Dishwasher]]=0,"",Table10[[#This Row],[Dishwasher]]) | AC16: =IF(Table10[[#This Row],[Parking]]=0,"",Table10[[#This Row],[Parking]]) | AD16: =IF(Table10[[#This Row],[Furniture]]=0,"",Table10[[#This Row],[Furniture]]) | AE16: =IF(Table10[[#This Row],[Other]]=0,"",Table10[[#This Row],[Other]])
A17: =IF(Table10[[#This Row],[Unit Type]]=0,"",Table10[[#This Row],[Unit Type]]) -> 1 Bedroom | D17: =IF(Table10[[#This Row],[Unit '#]]=0,"",Table10[[#This Row],[Unit '#]]) -> 15 | F17: =IF(Table10[[#This Row],[Rental Rate ($/mth)]]=0,"",Table10[[#This Row],[Rental Rate ($/mth)]]) -> 2490 | J17: =IF(Table10[[#This Row],[Unit Size (sq ft)]]=0,"",Table10[[#This Row],[Unit Size (sq ft)]]) -> 624 | L17: =Table10[[#This Row],[Market Unit]] -> Yes | M17: =Table10[[#This Row],[Affordable Unit]] -> No | N17: =IF(Table10[[#This Row],[Subsidized Unit]]=0,"",Table10[[#This Row],[Subsidized Unit]]) | O17: =IF(Table10[[#This Row],[Care Services]]=0,"",Table10[[#This Row],[Care Services]]) | P17: =IF(Table10[[#This Row],[Affordable Care]]=0,"",Table10[[#This Row],[Affordable Care]]) | T17: =IF(Table10[[#This Row],[Bulk Lease Unit]]=0,"",Table10[[#This Row],[Bulk Lease Unit]]) | U17: =IF(Table10[[#This Row],[Den Included Unit]]=0,"",Table10[[#This Row],[Den Included Unit]]) | V17: =IF(Table10[[#This Row],[Second Bathroom]]=0,"",Table10[[#This Row],[Second Bathroom]]) | W17: =IF(Table10[[#This Row],[Heating]]=0,"",Table10[[#This Row],[Heating]]) | X17: =IF(Table10[[#This Row],[Electricity]]=0,"",Table10[[#This Row],[Electricity]]) | Y17: =IF(Table10[[#This Row],[Water]]=0,"",Table10[[#This Row],[Water]]) | Z17: =IF(Table10[[#This Row],[Washer/Dryer]]=0,"",Table10[[#This Row],[Washer/Dryer]]) | AA17: =IF(Table10[[#This Row],[Stove/Fridge]]=0,"",Table10[[#This Row],[Stove/Fridge]]) | AB17: =IF(Table10[[#This Row],[Dishwasher]]=0,"",Table10[[#This Row],[Dishwasher]]) | AC17: =IF(Table10[[#This Row],[Parking]]=0,"",Table10[[#This Row],[Parking]]) | AD17: =IF(Table10[[#This Row],[Furniture]]=0,"",Table10[[#This Row],[Furniture]]) | AE17: =IF(Table10[[#This Row],[Other]]=0,"",Table10[[#This Row],[Other]])
A18: =IF(Table10[[#This Row],[Unit Type]]=0,"",Table10[[#This Row],[Unit Type]]) -> 1 Bedroom | D18: =IF(Table10[[#This Row],[Unit '#]]=0,"",Table10[[#This Row],[Unit '#]]) -> 16 | F18: =IF(Table10[[#This Row],[Rental Rate ($/mth)]]=0,"",Table10[[#This Row],[Rental Rate ($/mth)]]) -> 2490 | J18: =IF(Table10[[#This Row],[Unit Size (sq ft)]]=0,"",Table10[[#This Row],[Unit Size (sq ft)]]) -> 624 | L18: =Table10[[#This Row],[Market Unit]] -> Yes | M18: =Table10[[#This Row],[Affordable Unit]] -> No | N18: =IF(Table10[[#This Row],[Subsidized Unit]]=0,"",Table10[[#This Row],[Subsidized Unit]]) | O18: =IF(Table10[[#This Row],[Care Services]]=0,"",Table10[[#This Row],[Care Services]]) | P18: =IF(Table10[[#This Row],[Affordable Care]]=0,"",Table10[[#This Row],[Affordable Care]]) | T18: =IF(Table10[[#This Row],[Bulk Lease Unit]]=0,"",Table10[[#This Row],[Bulk Lease Unit]]) | U18: =IF(Table10[[#This Row],[Den Included Unit]]=0,"",Table10[[#This Row],[Den Included Unit]]) | V18: =IF(Table10[[#This Row],[Second Bathroom]]=0,"",Table10[[#This Row],[Second Bathroom]]) | W18: =IF(Table10[[#This Row],[Heating]]=0,"",Table10[[#This Row],[Heating]]) | X18: =IF(Table10[[#This Row],[Electricity]]=0,"",Table10[[#This Row],[Electricity]]) | Y18: =IF(Table10[[#This Row],[Water]]=0,"",Table10[[#This Row],[Water]]) | Z18: =IF(Table10[[#This Row],[Washer/Dryer]]=0,"",Table10[[#This Row],[Washer/Dryer]]) | AA18: =IF(Table10[[#This Row],[Stove/Fridge]]=0,"",Table10[[#This Row],[Stove/Fridge]]) | AB18: =IF(Table10[[#This Row],[Dishwasher]]=0,"",Table10[[#This Row],[Dishwasher]]) | AC18: =IF(Table10[[#This Row],[Parking]]=0,"",Table10[[#This Row],[Parking]]) | AD18: =IF(Table10[[#This Row],[Furniture]]=0,"",Table10[[#This Row],[Furniture]]) | AE18: =IF(Table10[[#This Row],[Other]]=0,"",Table10[[#This Row],[Other]])
A19: =IF(Table10[[#This Row],[Unit Type]]=0,"",Table10[[#This Row],[Unit Type]]) -> 1 Bedroom | D19: =IF(Table10[[#This Row],[Unit '#]]=0,"",Table10[[#This Row],[Unit '#]]) -> 17 | F19: =IF(Table10[[#This Row],[Rental Rate ($/mth)]]=0,"",Table10[[#This Row],[Rental Rate ($/mth)]]) -> 2490 | J19: =IF(Table10[[#This Row],[Unit Size (sq ft)]]=0,"",Table10[[#This Row],[Unit Size (sq ft)]]) -> 624 | L19: =Table10[[#This Row],[Market Unit]] -> Yes | M19: =Table10[[#This Row],[Affordable Unit]] -> No | N19: =IF(Table10[[#This Row],[Subsidized Unit]]=0,"",Table10[[#This Row],[Subsidized Unit]]) | O19: =IF(Table10[[#This Row],[Care Services]]=0,"",Table10[[#This Row],[Care Services]]) | P19: =IF(Table10[[#This Row],[Affordable Care]]=0,"",Table10[[#This Row],[Affordable Care]]) | T19: =IF(Table10[[#This Row],[Bulk Lease Unit]]=0,"",Table10[[#This Row],[Bulk Lease Unit]]) | U19: =IF(Table10[[#This Row],[Den Included Unit]]=0,"",Table10[[#This Row],[Den Included Unit]]) | V19: =IF(Table10[[#This Row],[Second Bathroom]]=0,"",Table10[[#This Row],[Second Bathroom]]) | W19: =IF(Table10[[#This Row],[Heating]]=0,"",Table10[[#This Row],[Heating]]) | X19: =IF(Table10[[#This Row],[Electricity]]=0,"",Table10[[#This Row],[Electricity]]) | Y19: =IF(Table10[[#This Row],[Water]]=0,"",Table10[[#This Row],[Water]]) | Z19: =IF(Table10[[#This Row],[Washer/Dryer]]=0,"",Table10[[#This Row],[Washer/Dryer]]) | AA19: =IF(Table10[[#This Row],[Stove/Fridge]]=0,"",Table10[[#This Row],[Stove/Fridge]]) | AB19: =IF(Table10[[#This Row],[Dishwasher]]=0,"",Table10[[#This Row],[Dishwasher]]) | AC19: =IF(Table10[[#This Row],[Parking]]=0,"",Table10[[#This Row],[Parking]]) | AD19: =IF(Table10[[#This Row],[Furniture]]=0,"",Table10[[#This Row],[Furniture]]) | AE19: =IF(Table10[[#This Row],[Other]]=0,"",Table10[[#This Row],[Other]])
... A27: =IF(Table10[[#This Row],[Unit Type]]=0,"",Table10[[#This Row],[Unit Type]]) -> 1 Bedroom | D27: =IF(Table10[[#This Row],[Unit '#]]=0,"",Table10[[#This Row],[Unit '#]]) -> 25 | F27: =IF(Table10[[#This Row],[Rental Rate ($/mth)]]=0,"",Table10[[#This Row],[Rental Rate ($/mth)]]) -> 2490 | J27: =IF(Table10[[#This Row],[Unit Size (sq ft)]]=0,"",Table10[[#This Row],[Unit Size (sq ft)]]) -> 624 | L27: =Table10[[#This Row],[Market Unit]] -> Yes | M27: =Table10[[#This Row],[Affordable Unit]] -> No | N27: =IF(Table10[[#This Row],[Subsidized Unit]]=0,"",Table10[[#This Row],[Subsidized Unit]]) | O27: =IF(Table10[[#This Row],[Care Services]]=0,"",Table10[[#This Row],[Care Services]]) | P27: =IF(Table10[[#This Row],[Affordable Care]]=0,"",Table10[[#This Row],[Affordable Care]]) | T27: =IF(Table10[[#This Row],[Bulk Lease Unit]]=0,"",Table10[[#This Row],[Bulk Lease Unit]]) | U27: =IF(Table10[[#This Row],[Den Included Unit]]=0,"",Table10[[#This Row],[Den Included Unit]]) | V27: =IF(Table10[[#This Row],[Second Bathroom]]=0,"",Table10[[#This Row],[Second Bathroom]]) | W27: =IF(Table10[[#This Row],[Heating]]=0,"",Table10[[#This Row],[Heating]]) | X27: =IF(Table10[[#This Row],[Electricity]]=0,"",Table10[[#This Row],[Electricity]]) | Y27: =IF(Table10[[#This Row],[Water]]=0,"",Table10[[#This Row],[Water]]) | Z27: =IF(Table10[[#This Row],[Washer/Dryer]]=0,"",Table10[[#This Row],[Washer/Dryer]]) | AA27: =IF(Table10[[#This Row],[Stove/Fridge]]=0,"",Table10[[#This Row],[Stove/Fridge]]) | AB27: =IF(Table10[[#This Row],[Dishwasher]]=0,"",Table10[[#This Row],[Dishwasher]]) | AC27: =IF(Table10[[#This Row],[Parking]]=0,"",Table10[[#This Row],[Parking]]) | AD27: =IF(Table10[[#This Row],[Furniture]]=0,"",Table10[[#This Row],[Furniture]]) | AE27: =IF(Table10[[#This Row],[Other]]=0,"",Table10[[#This Row],[Other]])
A28: =IF(Table10[[#This Row],[Unit Type]]=0,"",Table10[[#This Row],[Unit Type]]) -> 1 Bedroom | B28: =IF(Table10[[#This Row],[Residential Stream Source]]=0,"",Table10[[#This Row],[Residential Stream Source]]) | C28: =IF(Table10[[#This Row],[Basement?]]=0,"",Table10[[#This Row],[Basement?]]) | D28: =IF(Table10[[#This Row],[Unit '#]]=0,"",Table10[[#This Row],[Unit '#]]) -> 26 | E28: =IF(Table10[[#This Row],[Vacant?]]=0,"",Table10[[#This Row],[Vacant?]]) | F28: =IF(Table10[[#This Row],[Rental Rate ($/mth)]]=0,"",Table10[[#This Row],[Rental Rate ($/mth)]]) -> 2490 | J28: =IF(Table10[[#This Row],[Unit Size (sq ft)]]=0,"",Table10[[#This Row],[Unit Size (sq ft)]]) -> 624 | L28: =Table10[[#This Row],[Market Unit]] -> Yes | M28: =Table10[[#This Row],[Affordable Unit]] -> No | N28: =IF(Table10[[#This Row],[Subsidized Unit]]=0,"",Table10[[#This Row],[Subsidized Unit]]) | O28: =IF(Table10[[#This Row],[Care Services]]=0,"",Table10[[#This Row],[Care Services]]) | P28: =IF(Table10[[#This Row],[Affordable Care]]=0,"",Table10[[#This Row],[Affordable Care]]) | T28: =IF(Table10[[#This Row],[Bulk Lease Unit]]=0,"",Table10[[#This Row],[Bulk Lease Unit]]) | U28: =IF(Table10[[#This Row],[Den Included Unit]]=0,"",Table10[[#This Row],[Den Included Unit]]) | V28: =IF(Table10[[#This Row],[Second Bathroom]]=0,"",Table10[[#This Row],[Second Bathroom]]) | W28: =IF(Table10[[#This Row],[Heating]]=0,"",Table10[[#This Row],[Heating]]) | X28: =IF(Table10[[#This Row],[Electricity]]=0,"",Table10[[#This Row],[Electricity]]) | Y28: =IF(Table10[[#This Row],[Water]]=0,"",Table10[[#This Row],[Water]]) | Z28: =IF(Table10[[#This Row],[Washer/Dryer]]=0,"",Table10[[#This Row],[Washer/Dryer]]) | AA28: =IF(Table10[[#This Row],[Stove/Fridge]]=0,"",Table10[[#This Row],[Stove/Fridge]]) | AB28: =IF(Table10[[#This Row],[Dishwasher]]=0,"",Table10[[#This Row],[Dishwasher]]) | AC28: =IF(Table10[[#This Row],[Parking]]=0,"",Table10[[#This Row],[Parking]]) | AD28: =IF(Table10[[#This Row],[Furniture]]=0,"",Table10[[#This Row],[Furniture]]) | AE28: =IF(Table10[[#This Row],[Other]]=0,"",Table10[[#This Row],[Other]])
A29: =IF(Table10[[#This Row],[Unit Type]]=0,"",Table10[[#This Row],[Unit Type]]) -> 1 Bedroom | B29: =IF(Table10[[#This Row],[Residential Stream Source]]=0,"",Table10[[#This Row],[Residential Stream Source]]) | C29: =IF(Table10[[#This Row],[Basement?]]=0,"",Table10[[#This Row],[Basement?]]) | D29: =IF(Table10[[#This Row],[Unit '#]]=0,"",Table10[[#This Row],[Unit '#]]) -> 27 | E29: =IF(Table10[[#This Row],[Vacant?]]=0,"",Table10[[#This Row],[Vacant?]]) | F29: =IF(Table10[[#This Row],[Rental Rate ($/mth)]]=0,"",Table10[[#This Row],[Rental Rate ($/mth)]]) -> 2490 | J29: =IF(Table10[[#This Row],[Unit Size (sq ft)]]=0,"",Table10[[#This Row],[Unit Size (sq ft)]]) -> 624 | L29: =Table10[[#This Row],[Market Unit]] -> Yes | M29: =Table10[[#This Row],[Affordable Unit]] -> No | N29: =IF(Table10[[#This Row],[Subsidized Unit]]=0,"",Table10[[#This Row],[Subsidized Unit]]) | O29: =IF(Table10[[#This Row],[Care Services]]=0,"",Table10[[#This Row],[Care Services]]) | P29: =IF(Table10[[#This Row],[Affordable Care]]=0,"",Table10[[#This Row],[Affordable Care]]) | T29: =IF(Table10[[#This Row],[Bulk Lease Unit]]=0,"",Table10[[#This Row],[Bulk Lease Unit]]) | U29: =IF(Table10[[#This Row],[Den Included Unit]]=0,"",Table10[[#This Row],[Den Included Unit]]) | V29: =IF(Table10[[#This Row],[Second Bathroom]]=0,"",Table10[[#This Row],[Second Bathroom]]) | W29: =IF(Table10[[#This Row],[Heating]]=0,"",Table10[[#This Row],[Heating]]) | X29: =IF(Table10[[#This Row],[Electricity]]=0,"",Table10[[#This Row],[Electricity]]) | Y29: =IF(Table10[[#This Row],[Water]]=0,"",Table10[[#This Row],[Water]]) | Z29: =IF(Table10[[#This Row],[Washer/Dryer]]=0,"",Table10[[#This Row],[Washer/Dryer]]) | AA29: =IF(Table10[[#This Row],[Stove/Fridge]]=0,"",Table10[[#This Row],[Stove/Fridge]]) | AB29: =IF(Table10[[#This Row],[Dishwasher]]=0,"",Table10[[#This Row],[Dishwasher]]) | AC29: =IF(Table10[[#This Row],[Parking]]=0,"",Table10[[#This Row],[Parking]]) | AD29: =IF(Table10[[#This Row],[Furniture]]=0,"",Table10[[#This Row],[Furniture]]) | AE29: =IF(Table10[[#This Row],[Other]]=0,"",Table10[[#This Row],[Other]])
A30: =IF(Table10[[#This Row],[Unit Type]]=0,"",Table10[[#This Row],[Unit Type]]) -> 1 Bedroom | B30: =IF(Table10[[#This Row],[Residential Stream Source]]=0,"",Table10[[#This Row],[Residential Stream Source]]) | C30: =IF(Table10[[#This Row],[Basement?]]=0,"",Table10[[#This Row],[Basement?]]) | D30: =IF(Table10[[#This Row],[Unit '#]]=0,"",Table10[[#This Row],[Unit '#]]) -> 28 | E30: =IF(Table10[[#This Row],[Vacant?]]=0,"",Table10[[#This Row],[Vacant?]]) | F30: =IF(Table10[[#This Row],[Rental Rate ($/mth)]]=0,"",Table10[[#This Row],[Rental Rate ($/mth)]]) -> 2490 | J30: =IF(Table10[[#This Row],[Unit Size (sq ft)]]=0,"",Table10[[#This Row],[Unit Size (sq ft)]]) -> 624 | L30: =Table10[[#This Row],[Market Unit]] -> Yes | M30: =Table10[[#This Row],[Affordable Unit]] -> No | N30: =IF(Table10[[#This Row],[Subsidized Unit]]=0,"",Table10[[#This Row],[Subsidized Unit]]) | O30: =IF(Table10[[#This Row],[Care Services]]=0,"",Table10[[#This Row],[Care Services]]) | P30: =IF(Table10[[#This Row],[Affordable Care]]=0,"",Table10[[#This Row],[Affordable Care]]) | T30: =IF(Table10[[#This Row],[Bulk Lease Unit]]=0,"",Table10[[#This Row],[Bulk Lease Unit]]) | U30: =IF(Table10[[#This Row],[Den Included Unit]]=0,"",Table10[[#This Row],[Den Included Unit]]) | V30: =IF(Table10[[#This Row],[Second Bathroom]]=0,"",Table10[[#This Row],[Second Bathroom]]) | W30: =IF(Table10[[#This Row],[Heating]]=0,"",Table10[[#This Row],[Heating]]) | X30: =IF(Table10[[#This Row],[Electricity]]=0,"",Table10[[#This Row],[Electricity]]) | Y30: =IF(Table10[[#This Row],[Water]]=0,"",Table10[[#This Row],[Water]]) | Z30: =IF(Table10[[#This Row],[Washer/Dryer]]=0,"",Table10[[#This Row],[Washer/Dryer]]) | AA30: =IF(Table10[[#This Row],[Stove/Fridge]]=0,"",Table10[[#This Row],[Stove/Fridge]]) | AB30: =IF(Table10[[#This Row],[Dishwasher]]=0,"",Table10[[#This Row],[Dishwasher]]) | AC30: =IF(Table10[[#This Row],[Parking]]=0,"",Table10[[#This Row],[Parking]]) | AD30: =IF(Table10[[#This Row],[Furniture]]=0,"",Table10[[#This Row],[Furniture]]) | AE30: =IF(Table10[[#This Row],[Other]]=0,"",Table10[[#This Row],[Other]])
A31: =IF(Table10[[#This Row],[Unit Type]]=0,"",Table10[[#This Row],[Unit Type]]) -> 1 Bedroom | B31: =IF(Table10[[#This Row],[Residential Stream Source]]=0,"",Table10[[#This Row],[Residential Stream Source]]) | C31: =IF(Table10[[#This Row],[Basement?]]=0,"",Table10[[#This Row],[Basement?]]) | D31: =IF(Table10[[#This Row],[Unit '#]]=0,"",Table10[[#This Row],[Unit '#]]) -> 29 | E31: =IF(Table10[[#This Row],[Vacant?]]=0,"",Table10[[#This Row],[Vacant?]]) | F31: =IF(Table10[[#This Row],[Rental Rate ($/mth)]]=0,"",Table10[[#This Row],[Rental Rate ($/mth)]]) -> 2490 | J31: =IF(Table10[[#This Row],[Unit Size (sq ft)]]=0,"",Table10[[#This Row],[Unit Size (sq ft)]]) -> 624 | L31: =Table10[[#This Row],[Market Unit]] -> Yes | M31: =Table10[[#This Row],[Affordable Unit]] -> No | N31: =IF(Table10[[#This Row],[Subsidized Unit]]=0,"",Table10[[#This Row],[Subsidized Unit]]) | O31: =IF(Table10[[#This Row],[Care Services]]=0,"",Table10[[#This Row],[Care Services]]) | P31: =IF(Table10[[#This Row],[Affordable Care]]=0,"",Table10[[#This Row],[Affordable Care]]) | T31: =IF(Table10[[#This Row],[Bulk Lease Unit]]=0,"",Table10[[#This Row],[Bulk Lease Unit]]) | U31: =IF(Table10[[#This Row],[Den Included Unit]]=0,"",Table10[[#This Row],[Den Included Unit]]) | V31: =IF(Table10[[#This Row],[Second Bathroom]]=0,"",Table10[[#This Row],[Second Bathroom]]) | W31: =IF(Table10[[#This Row],[Heating]]=0,"",Table10[[#This Row],[Heating]]) | X31: =IF(Table10[[#This Row],[Electricity]]=0,"",Table10[[#This Row],[Electricity]]) | Y31: =IF(Table10[[#This Row],[Water]]=0,"",Table10[[#This Row],[Water]]) | Z31: =IF(Table10[[#This Row],[Washer/Dryer]]=0,"",Table10[[#This Row],[Washer/Dryer]]) | AA31: =IF(Table10[[#This Row],[Stove/Fridge]]=0,"",Table10[[#This Row],[Stove/Fridge]]) | AB31: =IF(Table10[[#This Row],[Dishwasher]]=0,"",Table10[[#This Row],[Dishwasher]]) | AC31: =IF(Table10[[#This Row],[Parking]]=0,"",Table10[[#This Row],[Parking]]) | AD31: =IF(Table10[[#This Row],[Furniture]]=0,"",Table10[[#This Row],[Furniture]]) | AE31: =IF(Table10[[#This Row],[Other]]=0,"",Table10[[#This Row],[Other]])
A32: =IF(Table10[[#This Row],[Unit Type]]=0,"",Table10[[#This Row],[Unit Type]]) -> 1 Bedroom | B32: =IF(Table10[[#This Row],[Residential Stream Source]]=0,"",Table10[[#This Row],[Residential Stream Source]]) | C32: =IF(Table10[[#This Row],[Basement?]]=0,"",Table10[[#This Row],[Basement?]]) | D32: =IF(Table10[[#This Row],[Unit '#]]=0,"",Table10[[#This Row],[Unit '#]]) -> 30 | E32: =IF(Table10[[#This Row],[Vacant?]]=0,"",Table10[[#This Row],[Vacant?]]) | F32: =IF(Table10[[#This Row],[Rental Rate ($/mth)]]=0,"",Table10[[#This Row],[Rental Rate ($/mth)]]) -> 2490 | J32: =IF(Table10[[#This Row],[Unit Size (sq ft)]]=0,"",Table10[[#This Row],[Unit Size (sq ft)]]) -> 624 | L32: =Table10[[#This Row],[Market Unit]] -> Yes | M32: =Table10[[#This Row],[Affordable Unit]] -> No | N32: =IF(Table10[[#This Row],[Subsidized Unit]]=0,"",Table10[[#This Row],[Subsidized Unit]]) | O32: =IF(Table10[[#This Row],[Care Services]]=0,"",Table10[[#This Row],[Care Services]]) | P32: =IF(Table10[[#This Row],[Affordable Care]]=0,"",Table10[[#This Row],[Affordable Care]]) | T32: =IF(Table10[[#This Row],[Bulk Lease Unit]]=0,"",Table10[[#This Row],[Bulk Lease Unit]]) | U32: =IF(Table10[[#This Row],[Den Included Unit]]=0,"",Table10[[#This Row],[Den Included Unit]]) | V32: =IF(Table10[[#This Row],[Second Bathroom]]=0,"",Table10[[#This Row],[Second Bathroom]]) | W32: =IF(Table10[[#This Row],[Heating]]=0,"",Table10[[#This Row],[Heating]]) | X32: =IF(Table10[[#This Row],[Electricity]]=0,"",Table10[[#This Row],[Electricity]]) | Y32: =IF(Table10[[#This Row],[Water]]=0,"",Table10[[#This Row],[Water]]) | Z32: =IF(Table10[[#This Row],[Washer/Dryer]]=0,"",Table10[[#This Row],[Washer/Dryer]]) | AA32: =IF(Table10[[#This Row],[Stove/Fridge]]=0,"",Table10[[#This Row],[Stove/Fridge]]) | AB32: =IF(Table10[[#This Row],[Dishwasher]]=0,"",Table10[[#This Row],[Dishwasher]]) | AC32: =IF(Table10[[#This Row],[Parking]]=0,"",Table10[[#This Row],[Parking]]) | AD32: =IF(Table10[[#This Row],[Furniture]]=0,"",Table10[[#This Row],[Furniture]]) | AE32: =IF(Table10[[#This Row],[Other]]=0,"",Table10[[#This Row],[Other]])
A33: =IF(Table10[[#This Row],[Unit Type]]=0,"",Table10[[#This Row],[Unit Type]]) -> 1 Bedroom | B33: =IF(Table10[[#This Row],[Residential Stream Source]]=0,"",Table10[[#This Row],[Residential Stream Source]]) | C33: =IF(Table10[[#This Row],[Basement?]]=0,"",Table10[[#This Row],[Basement?]]) | D33: =IF(Table10[[#This Row],[Unit '#]]=0,"",Table10[[#This Row],[Unit '#]]) -> 31 | E33: =IF(Table10[[#This Row],[Vacant?]]=0,"",Table10[[#This Row],[Vacant?]]) | F33: =IF(Table10[[#This Row],[Rental Rate ($/mth)]]=0,"",Table10[[#This Row],[Rental Rate ($/mth)]]) -> 2490 | J33: =IF(Table10[[#This Row],[Unit Size (sq ft)]]=0,"",Table10[[#This Row],[Unit Size (sq ft)]]) -> 624 | L33: =Table10[[#This Row],[Market Unit]] -> Yes | M33: =Table10[[#This Row],[Affordable Unit]] -> No | N33: =IF(Table10[[#This Row],[Subsidized Unit]]=0,"",Table10[[#This Row],[Subsidized Unit]]) | O33: =IF(Table10[[#This Row],[Care Services]]=0,"",Table10[[#This Row],[Care Services]]) | P33: =IF(Table10[[#This Row],[Affordable Care]]=0,"",Table10[[#This Row],[Affordable Care]]) | T33: =IF(Table10[[#This Row],[Bulk Lease Unit]]=0,"",Table10[[#This Row],[Bulk Lease Unit]]) | U33: =IF(Table10[[#This Row],[Den Included Unit]]=0,"",Table10[[#This Row],[Den Included Unit]]) | V33: =IF(Table10[[#This Row],[Second Bathroom]]=0,"",Table10[[#This Row],[Second Bathroom]]) | W33: =IF(Table10[[#This Row],[Heating]]=0,"",Table10[[#This Row],[Heating]]) | X33: =IF(Table10[[#This Row],[Electricity]]=0,"",Table10[[#This Row],[Electricity]]) | Y33: =IF(Table10[[#This Row],[Water]]=0,"",Table10[[#This Row],[Water]]) | Z33: =IF(Table10[[#This Row],[Washer/Dryer]]=0,"",Table10[[#This Row],[Washer/Dryer]]) | AA33: =IF(Table10[[#This Row],[Stove/Fridge]]=0,"",Table10[[#This Row],[Stove/Fridge]]) | AB33: =IF(Table10[[#This Row],[Dishwasher]]=0,"",Table10[[#This Row],[Dishwasher]]) | AC33: =IF(Table10[[#This Row],[Parking]]=0,"",Table10[[#This Row],[Parking]]) | AD33: =IF(Table10[[#This Row],[Furniture]]=0,"",Table10[[#This Row],[Furniture]]) | AE33: =IF(Table10[[#This Row],[Other]]=0,"",Table10[[#This Row],[Other]])
A34: =IF(Table10[[#This Row],[Unit Type]]=0,"",Table10[[#This Row],[Unit Type]]) -> 1 Bedroom | B34: =IF(Table10[[#This Row],[Residential Stream Source]]=0,"",Table10[[#This Row],[Residential Stream Source]]) | C34: =IF(Table10[[#This Row],[Basement?]]=0,"",Table10[[#This Row],[Basement?]]) | D34: =IF(Table10[[#This Row],[Unit '#]]=0,"",Table10[[#This Row],[Unit '#]]) -> 32 | E34: =IF(Table10[[#This Row],[Vacant?]]=0,"",Table10[[#This Row],[Vacant?]]) | F34: =IF(Table10[[#This Row],[Rental Rate ($/mth)]]=0,"",Table10[[#This Row],[Rental Rate ($/mth)]]) -> 2490 | J34: =IF(Table10[[#This Row],[Unit Size (sq ft)]]=0,"",Table10[[#This Row],[Unit Size (sq ft)]]) -> 624 | L34: =Table10[[#This Row],[Market Unit]] -> Yes | M34: =Table10[[#This Row],[Affordable Unit]] -> No | N34: =IF(Table10[[#This Row],[Subsidized Unit]]=0,"",Table10[[#This Row],[Subsidized Unit]]) | O34: =IF(Table10[[#This Row],[Care Services]]=0,"",Table10[[#This Row],[Care Services]]) | P34: =IF(Table10[[#This Row],[Affordable Care]]=0,"",Table10[[#This Row],[Affordable Care]]) | T34: =IF(Table10[[#This Row],[Bulk Lease Unit]]=0,"",Table10[[#This Row],[Bulk Lease Unit]]) | U34: =IF(Table10[[#This Row],[Den Included Unit]]=0,"",Table10[[#This Row],[Den Included Unit]]) | V34: =IF(Table10[[#This Row],[Second Bathroom]]=0,"",Table10[[#This Row],[Second Bathroom]]) | W34: =IF(Table10[[#This Row],[Heating]]=0,"",Table10[[#This Row],[Heating]]) | X34: =IF(Table10[[#This Row],[Electricity]]=0,"",Table10[[#This Row],[Electricity]]) | Y34: =IF(Table10[[#This Row],[Water]]=0,"",Table10[[#This Row],[Water]]) | Z34: =IF(Table10[[#This Row],[Washer/Dryer]]=0,"",Table10[[#This Row],[Washer/Dryer]]) | AA34: =IF(Table10[[#This Row],[Stove/Fridge]]=0,"",Table10[[#This Row],[Stove/Fridge]]) | AB34: =IF(Table10[[#This Row],[Dishwasher]]=0,"",Table10[[#This Row],[Dishwasher]]) | AC34: =IF(Table10[[#This Row],[Parking]]=0,"",Table10[[#This Row],[Parking]]) | AD34: =IF(Table10[[#This Row],[Furniture]]=0,"",Table10[[#This Row],[Furniture]]) | AE34: =IF(Table10[[#This Row],[Other]]=0,"",Table10[[#This Row],[Other]])
A35: =IF(Table10[[#This Row],[Unit Type]]=0,"",Table10[[#This Row],[Unit Type]]) -> 1 Bedroom | B35: =IF(Table10[[#This Row],[Residential Stream Source]]=0,"",Table10[[#This Row],[Residential Stream Source]]) | C35: =IF(Table10[[#This Row],[Basement?]]=0,"",Table10[[#This Row],[Basement?]]) | D35: =IF(Table10[[#This Row],[Unit '#]]=0,"",Table10[[#This Row],[Unit '#]]) -> 33 | E35: =IF(Table10[[#This Row],[Vacant?]]=0,"",Table10[[#This Row],[Vacant?]]) | F35: =IF(Table10[[#This Row],[Rental Rate ($/mth)]]=0,"",Table10[[#This Row],[Rental Rate ($/mth)]]) -> 2490 | J35: =IF(Table10[[#This Row],[Unit Size (sq ft)]]=0,"",Table10[[#This Row],[Unit Size (sq ft)]]) -> 624 | L35: =Table10[[#This Row],[Market Unit]] -> Yes | M35: =Table10[[#This Row],[Affordable Unit]] -> No | N35: =IF(Table10[[#This Row],[Subsidized Unit]]=0,"",Table10[[#This Row],[Subsidized Unit]]) | O35: =IF(Table10[[#This Row],[Care Services]]=0,"",Table10[[#This Row],[Care Services]]) | P35: =IF(Table10[[#This Row],[Affordable Care]]=0,"",Table10[[#This Row],[Affordable Care]]) | T35: =IF(Table10[[#This Row],[Bulk Lease Unit]]=0,"",Table10[[#This Row],[Bulk Lease Unit]]) | U35: =IF(Table10[[#This Row],[Den Included Unit]]=0,"",Table10[[#This Row],[Den Included Unit]]) | V35: =IF(Table10[[#This Row],[Second Bathroom]]=0,"",Table10[[#This Row],[Second Bathroom]]) | W35: =IF(Table10[[#This Row],[Heating]]=0,"",Table10[[#This Row],[Heating]]) | X35: =IF(Table10[[#This Row],[Electricity]]=0,"",Table10[[#This Row],[Electricity]]) | Y35: =IF(Table10[[#This Row],[Water]]=0,"",Table10[[#This Row],[Water]]) | Z35: =IF(Table10[[#This Row],[Washer/Dryer]]=0,"",Table10[[#This Row],[Washer/Dryer]]) | AA35: =IF(Table10[[#This Row],[Stove/Fridge]]=0,"",Table10[[#This Row],[Stove/Fridge]]) | AB35: =IF(Table10[[#This Row],[Dishwasher]]=0,"",Table10[[#This Row],[Dishwasher]]) | AC35: =IF(Table10[[#This Row],[Parking]]=0,"",Table10[[#This Row],[Parking]]) | AD35: =IF(Table10[[#This Row],[Furniture]]=0,"",Table10[[#This Row],[Furniture]]) | AE35: =IF(Table10[[#This Row],[Other]]=0,"",Table10[[#This Row],[Other]])
A36: =IF(Table10[[#This Row],[Unit Type]]=0,"",Table10[[#This Row],[Unit Type]]) -> 1 Bedroom | B36: =IF(Table10[[#This Row],[Residential Stream Source]]=0,"",Table10[[#This Row],[Residential Stream Source]]) | C36: =IF(Table10[[#This Row],[Basement?]]=0,"",Table10[[#This Row],[Basement?]]) | D36: =IF(Table10[[#This Row],[Unit '#]]=0,"",Table10[[#This Row],[Unit '#]]) -> 34 | E36: =IF(Table10[[#This Row],[Vacant?]]=0,"",Table10[[#This Row],[Vacant?]]) | F36: =IF(Table10[[#This Row],[Rental Rate ($/mth)]]=0,"",Table10[[#This Row],[Rental Rate ($/mth)]]) -> 2490 | J36: =IF(Table10[[#This Row],[Unit Size (sq ft)]]=0,"",Table10[[#This Row],[Unit Size (sq ft)]]) -> 624 | L36: =Table10[[#This Row],[Market Unit]] -> Yes | M36: =Table10[[#This Row],[Affordable Unit]] -> No | N36: =IF(Table10[[#This Row],[Subsidized Unit]]=0,"",Table10[[#This Row],[Subsidized Unit]]) | O36: =IF(Table10[[#This Row],[Care Services]]=0,"",Table10[[#This Row],[Care Services]]) | P36: =IF(Table10[[#This Row],[Affordable Care]]=0,"",Table10[[#This Row],[Affordable Care]]) | T36: =IF(Table10[[#This Row],[Bulk Lease Unit]]=0,"",Table10[[#This Row],[Bulk Lease Unit]]) | U36: =IF(Table10[[#This Row],[Den Included Unit]]=0,"",Table10[[#This Row],[Den Included Unit]]) | V36: =IF(Table10[[#This Row],[Second Bathroom]]=0,"",Table10[[#This Row],[Second Bathroom]]) | W36: =IF(Table10[[#This Row],[Heating]]=0,"",Table10[[#This Row],[Heating]]) | X36: =IF(Table10[[#This Row],[Electricity]]=0,"",Table10[[#This Row],[Electricity]]) | Y36: =IF(Table10[[#This Row],[Water]]=0,"",Table10[[#This Row],[Water]]) | Z36: =IF(Table10[[#This Row],[Washer/Dryer]]=0,"",Table10[[#This Row],[Washer/Dryer]]) | AA36: =IF(Table10[[#This Row],[Stove/Fridge]]=0,"",Table10[[#This Row],[Stove/Fridge]]) | AB36: =IF(Table10[[#This Row],[Dishwasher]]=0,"",Table10[[#This Row],[Dishwasher]]) | AC36: =IF(Table10[[#This Row],[Parking]]=0,"",Table10[[#This Row],[Parking]]) | AD36: =IF(Table10[[#This Row],[Furniture]]=0,"",Table10[[#This Row],[Furniture]]) | AE36: =IF(Table10[[#This Row],[Other]]=0,"",Table10[[#This Row],[Other]])
A37: =IF(Table10[[#This Row],[Unit Type]]=0,"",Table10[[#This Row],[Unit Type]]) -> 1 Bedroom | B37: =IF(Table10[[#This Row],[Residential Stream Source]]=0,"",Table10[[#This Row],[Residential Stream Source]]) | C37: =IF(Table10[[#This Row],[Basement?]]=0,"",Table10[[#This Row],[Basement?]]) | D37: =IF(Table10[[#This Row],[Unit '#]]=0,"",Table10[[#This Row],[Unit '#]]) -> 35 | E37: =IF(Table10[[#This Row],[Vacant?]]=0,"",Table10[[#This Row],[Vacant?]]) | F37: =IF(Table10[[#This Row],[Rental Rate ($/mth)]]=0,"",Table10[[#This Row],[Rental Rate ($/mth)]]) -> 2490 | J37: =IF(Table10[[#This Row],[Unit Size (sq ft)]]=0,"",Table10[[#This Row],[Unit Size (sq ft)]]) -> 624 | L37: =Table10[[#This Row],[Market Unit]] -> Yes | M37: =Table10[[#This Row],[Affordable Unit]] -> No | N37: =IF(Table10[[#This Row],[Subsidized Unit]]=0,"",Table10[[#This Row],[Subsidized Unit]]) | O37: =IF(Table10[[#This Row],[Care Services]]=0,"",Table10[[#This Row],[Care Services]]) | P37: =IF(Table10[[#This Row],[Affordable Care]]=0,"",Table10[[#This Row],[Affordable Care]]) | T37: =IF(Table10[[#This Row],[Bulk Lease Unit]]=0,"",Table10[[#This Row],[Bulk Lease Unit]]) | U37: =IF(Table10[[#This Row],[Den Included Unit]]=0,"",Table10[[#This Row],[Den Included Unit]]) | V37: =IF(Table10[[#This Row],[Second Bathroom]]=0,"",Table10[[#This Row],[Second Bathroom]]) | W37: =IF(Table10[[#This Row],[Heating]]=0,"",Table10[[#This Row],[Heating]]) | X37: =IF(Table10[[#This Row],[Electricity]]=0,"",Table10[[#This Row],[Electricity]]) | Y37: =IF(Table10[[#This Row],[Water]]=0,"",Table10[[#This Row],[Water]]) | Z37: =IF(Table10[[#This Row],[Washer/Dryer]]=0,"",Table10[[#This Row],[Washer/Dryer]]) | AA37: =IF(Table10[[#This Row],[Stove/Fridge]]=0,"",Table10[[#This Row],[Stove/Fridge]]) | AB37: =IF(Table10[[#This Row],[Dishwasher]]=0,"",Table10[[#This Row],[Dishwasher]]) | AC37: =IF(Table10[[#This Row],[Parking]]=0,"",Table10[[#This Row],[Parking]]) | AD37: =IF(Table10[[#This Row],[Furniture]]=0,"",Table10[[#This Row],[Furniture]]) | AE37: =IF(Table10[[#This Row],[Other]]=0,"",Table10[[#This Row],[Other]])
