Workbook
Name AltusCC: #REF!
Name AltusParking: #REF!
Name Amenities: '[1]Amenities DDM'!$B$2:$C$11
Name CMHCActualAverage: '[1]CMHC vs Actual Rents'!$B$3:$G$73
Name CMHCGap: '[1]CMHC Gap'!$B$3:$F$73
Name CMHCRentDensity: '[1]CMHC - Rental Density'!$A$5:$F$75
Name CMHCRents: '[1]CMHC - Rental Rates'!$A$5:$G$74
Name CMHCSecondary: '[1]CMHC - Secondary Universe'!$A$4:$E$74
Name CMHCUniverse: '[1]CMHC - Universe'!$A$5:$J$76
Name CMHCVac: '[1]CMHC - Vacancy'!$A$5:$G$74
Name PrizmGroups: '[1]PRIZM Profiles'!$B$5:$E$72
Name PrizmNameRange: '[1]PRIZM Profiles'!$B$6:$B$72
Name PrizmPicLookup1: INDEX(PrizmNameRange,MATCH('[1]7 - Prizm'!A1,PrizmNameRange,0))
Name Proforma: #REF!
Name RentalDensity: '[1]CMHC - Rental Density'!$A$6:$F$75
Name SecondaryU: '[1]CMHC - Secondary Universe'!$A$5:$E$74

Sheet 1. 1A Proforma
F2: Estimated Stabilized Value - Today
F3: 2240 Birchmount Road, Scarborough, ON
D5: RECOMMENDED RENTAL RATES | G5: Unit Mix
D6: Unit Type | E6: Unit Size (SF) | F6: Unit Count | H6: Total SF | I6: Monthly Per Unit | J6: $/SF | K6: Monthly | L6: Total Annual
D7: 1 Bed | E7: 624 | F7: 84 | G7: =F7/$F$10 -> 0.49411765 | H7: =F7*E7 -> 52416 | I7: 2490 | J7: =I7/E7 -> 3.9903846 | K7: =I7*F7 -> 209160 | L7: =K7*12 -> 2509920
D8: 2 Bed | E8: 855.4 | F8: 68 | G8: =F8/$F$10 -> 0.4 | H8: =F8*E8 -> 58167.2 | I8: 3155 | J8: =I8/E8 -> 3.6883329 | K8: =I8*F8 -> 214540 | L8: =K8*12 -> 2574480
D9: 3 Bed | E9: 1015 | F9: 18 | G9: =F9/$F$10 -> 0.10588235 | H9: =F9*E9 -> 18270 | I9: 3675 | J9: =I9/E9 -> 3.6206897 | K9: =I9*F9 -> 66150 | L9: =K9*12 -> 793800
D10: TOTAL/AVG.: | E10: =SUMPRODUCT(E7:E9,F7:F9)/F10 -> 757.96 | F10: =SUM(F7:F9) -> 170 | G10: =SUM(G7:G9) -> 1 | H10: =SUM(H7:H9) -> 128853.2 | I10: =K10/F10 -> 2881.4706 | J10: =K10/H10 -> 3.801613 | K10: =SUM(K7:K9) -> 489850 | L10: =SUM(L7:L9) -> 5878200
C12: =SUM(C7:C7) -> 0
E13: Total Residential Units: | F13: =F10 -> 170 | I13: Net Rentable SF (Residential Units): | J13: =H10 -> 128853.2
I14: Total Monthly Rent Revenue: | J14: =K10 -> 489850
E16: ESTIMATED OPERATING REVENUES | F16: #Spaces | G16: Monthly Fee | H16: Annual Per Unit | I16: Monthly Per Unit | J16: Monthly | K16: Total Annual
E17: Rent | H17: =K17/$F$13 -> 34577.647 | I17: =I10 -> 2881.4706 | J17: =K10 -> 489850 | K17: =L10 -> 5878200
E18: Underground Parking | F18: 162 | G18: 200 | H18: =K18/$F$13 -> 2287.0588 | I18: =J18/$F$13 -> 190.58824 | J18: =F18*G18 -> 32400 | K18: =J18*12 -> 388800
E19: Visitor Parking | F19: 15 | G19: 0
E20: Retail Parking | F20: 15 | G20: 0
E21: Storage Lockers | F21: 100 | G21: 40 | H21: =K21/$F$13 -> 282.35294 | I21: =J21/$F$13 -> 23.529412 | J21: =F21*G21 -> 4000 | K21: =J21*12 -> 48000
E22: Submetering Reimbursement | F22: =F13 -> 170 | G22: =+'[2]Typical Conv.Operating Expenses'!BU96 -> 20 | H22: =K22/F13 -> 240 | I22: =G22 -> 20 | J22: =I22*F13 -> 3400 | K22: =J22*12 -> 40800
E23: SUB-TOTAL: | H23: =SUM(H17:H22) -> 37387.059 | I23: =SUM(I17:I22) -> 3115.5882 | J23: =SUM(J17:J22) -> 529650 | K23: =SUM(K17:K22) -> 6355800
E24: Vacancies (Rent & Parking) | F24: 0.03 | H24: =-H23*$F$24 -> -1121.6118 | I24: =-I23*$F$24 -> -93.467647 | J24: =+K24/12 -> -15889.5 | K24: =-+K23*F24 -> -190674
E25: Other Income | G25: Rate
E26: Net Commercial Retail $/SF | F26: 4370 | G26: 40 | J26: =K26/12 -> 14566.667 | K26: =+F26*G26 -> 174800
E27: Vacancies (Commercial) | F27: 0.04 | J27: =K27/12 -> -582.66667 | K27: =-K26*$F$27 -> -6992
E28: TOTAL: | H28: =SUM(H23:H26) -> 36265.447 | I28: =SUM(I23:I26) -> 3022.1206 | J28: =SUM(J23:J27) -> 527744.5 | K28: =SUM(K23:K27) -> 6332934
E30: ESTIMATED OPERATING EXPENSES (INDUSTRY STANDARD) | H30: Annual Per Unit | I30: Monthly Per Unit | J30: Monthly | K30: Total Annual | L30: % of Revenue
E31: Utilities (Common Area Only) | F31: =$F$13 -> 170 | G31: units @ | H31: =+H80 -> 1130 | I31: =H31/12 -> 94.166667 | J31: =K31/12 -> 16008.333 | K31: =H31*F31 -> 192100 | L31: =+K31/$K$28 -> 0.030333492
E32: Repairs & Maintenance | F32: =$F$13 -> 170 | G32: units @ | H32: =+I93 -> 1050 | I32: =H32/12 -> 87.5 | J32: =K32/12 -> 14875 | K32: =H32*F32 -> 178500 | L32: =+K32/$K$28 -> 0.028185988
E33: Staffing | F33: =$F$13 -> 170 | G33: units @ | H33: =+I109 -> 1200 | I33: =J33/F13 -> 100 | J33: =K33/12 -> 17000 | K33: =+H33*F13 -> 204000 | L33: =+K33/$K$28 -> 0.032212557
E34: Insurance | F34: =$F$13 -> 170 | G34: units @ | H34: =+F117 -> 450 | I34: =H34/12 -> 37.5 | J34: =K34/12 -> 6375 | K34: =H34*F34 -> 76500 | L34: =+K34/$K$28 -> 0.012079709
E35: Marketing | F35: =$F$13 -> 170 | G35: units @ | H35: =+F122 -> 300 | I35: =H35/12 -> 25 | J35: =K35/12 -> 4250 | K35: =H35*F35 -> 51000 | L35: =+K35/$K$28 -> 0.0080531394
E36: General & Admin | F36: =$F$13 -> 170 | G36: units @ | H36: =+F127 -> 250 | I36: =H36/12 -> 20.833333 | J36: =K36/12 -> 3541.6667 | K36: =H36*F36 -> 42500 | L36: =+K36/$K$28 -> 0.0067109495
E37: Management Fee | F37: % of Gross Revenue | G37: 0.0425 | H37: =ROUND(K37/F13,-1) -> 1580 | I37: =J37/F13 -> 131.93613 | J37: =K37/12 -> 22429.141 | K37: =K28*G37 -> 269149.7 | L37: =+K37/$K$28 -> 0.0425
E38: Property Taxes (Per Municipal Rate)* | F38: 0.00754087 | G38: 450000 | H38: =ROUND(K38/F13,-1) -> 3390 | I38: =J38/F13 -> 282.78262 | J38: =K38/12 -> 48073.046 | K38: =F13*G38*F38 -> 576876.55 | L38: =+K38/$K$28 -> 0.091091515
E39: Reserve for Asset Replacement | F39: % of Gross Revenue | G39: =+I137 -> 0.02 | H39: =ROUND(K39/F13,-1) -> 750 | I39: =J39/F13 -> 62.087588 | J39: =K39/12 -> 10554.89 | K39: =K28*G39 -> 126658.68 | L39: =+K39/$K$28 -> 0.02
E40: TOTAL: | F40: =K40/K28 -> 0.27116735 | H40: =SUM(H31:H39) -> 10100 | I40: =SUM(I31:I39) -> 841.80634 | J40: =SUM(J31:J39) -> 143107.08 | K40: =SUM(K31:K39) -> 1717284.9 | L40: =+K40/$K$28 -> 0.27116735
E42: ESTIMATED NET OPERATING INCOME | H42: =H28-H40 -> 26165.447 | I42: =I28-I40 -> 2180.3143 | J42: =J28-J40 -> 384637.42 | K42: =K28-K40 -> 4615649.1
G45: ESTIMATED VALUATION | H45: Residential CAP Rate | I45: Est. Market Value Per Unit | J45: Est. Market Value Per SF | K45: Est. Market Value
G46: Market Value @ | H46: 0.0425 | I46: =ROUND(K46/$F$13,-2) -> 638800 | J46: =K46/$J$13 -> 842.85062 | K46: =ROUND($K$42/H46,-3) -> 108604000
G47: Market Value @ | H47: 0.045 | I47: =ROUND(K47/$F$13,-2) -> 603400 | J47: =K47/$J$13 -> 796.02214 | K47: =ROUND($K$42/H47,-3) -> 102570000
G48: Market Value @ | H48: 0.0475 | I48: =ROUND(K48/$F$13,-2) -> 571600 | J48: =K48/$J$13 -> 754.12951 | K48: =ROUND($K$42/H48,-3) -> 97172000
...

Sheet 2. Rev 1B Exec Summary
J1: ="Currently running: "&CHOOSE('12. Sensitivity'!$E$8,'12. Sensitivity'!$B$11,'12. Sensitivity'!$B$12,'12. Sensitivity'!$B$13) -> Currently running: Base Case
B3: ='3. Headline #s'!A10 -> Apartment Development Model Reverse 1B
B4: ='3. Headline #s'!A12 -> 2240 Birchmount Road, Scarborough, ON
B5: Executive Summary
A8: OVERVIEW | G8: Worst | H8: Base | I8: Best
B9: Net Operating Income @ Stabilization at Completion | G9: =H9 -> 4899902.8 | H9: ='7. Op Rev and Exp'!H57 -> 4899902.8 | I9: =H9 -> 4899902.8
B10: Capitalization Rate | G10: ='12. Sensitivity'!H13 -> 0.0475 | H10: ='12. Sensitivity'!H10 -> 0.045 | I10: ='12. Sensitivity'!H12 -> 0.0425
B11: Valuation @ | D11: ='7. Op Rev and Exp'!D57 -> 4.4820546 | E11: per sqft average revenue | G11: =G9/G10 -> 1.0315585e+08 | H11: =H9/H10 -> 1.0888673e+08 | I11: =I9/I10 -> 1.1529183e+08
B12: Selling costs @ | D12: ='11. 10-Yr Cash Flow IRR'!E11 -> 0.01 | G12: =-'11. 10-Yr Cash Flow IRR'!$E$11*'2. Rev 1B Exec Summary'!G11 -> -1031558.5 | H12: =-'11. 10-Yr Cash Flow IRR'!$E$11*'2. Rev 1B Exec Summary'!H11 -> -1088867.3 | I12: =-'11. 10-Yr Cash Flow IRR'!$E$11*'2. Rev 1B Exec Summary'!I11 -> -1152918.3
B13: Sales Proceeds | G13: =SUM(G11:G12) -> 1.0212429e+08 | H13: =SUM(H11:H12) -> 1.0779786e+08 | I13: =SUM(I11:I12) -> 1.1413891e+08
B14: Total Costs | G14: =H14 -> -94440551 | H14: =-G48 -> -94440551 | I14: =H14 -> -94440551
B15: Profit before taxes if sold | G15: =SUM(G13:G14) -> 7683738.6 | H15: =SUM(H13:H14) -> 13357310 | I15: =SUM(I13:I14) -> 19698361
B17: Merchant Builder Return on Cost | G17: =-G15/G14 -> 0.081360586 | H17: =-H15/H14 -> 0.14143617 | I17: =-I15/I14 -> 0.20857948
B18: Merchant Builder IRR if sold upon stabilization | H18: ='10. Development Cash Flow'!G105 -> 0.27897087
B19: ="IRR "&'11. 10-Yr Cash Flow IRR'!A66&"-Year" -> IRR 10-Year | H19: ='11. 10-Yr Cash Flow IRR'!B67 -> 0.20617253
A21: SCHEDULE
G22: From | H22: To | I22: Months
B23: Land Purchase | G23: ='8. Schedule'!D13 -> 46069 | H23: ='8. Schedule'!E13 -> 46069 | I23: ='8. Schedule'!C13 -> 0
B24: Pre-Development | G24: ='8. Schedule'!D15 -> 46097 | H24: ='8. Schedule'!E15 -> 46462 | I24: ='8. Schedule'!C15 -> 12
B25: Construction period | G25: ='8. Schedule'!D17 -> 46493 | H25: ='8. Schedule'!E17 -> 47042 | I25: ='8. Schedule'!C17 -> 18
B26: Lease-up | G26: ='8. Schedule'!D19 -> 46981 | H26: ='8. Schedule'!E19 -> 47315 | I26: ='8. Schedule'!C19 -> 11.333333
B27: Stabilized | G27: ='8. Schedule'!D21 -> 47346 | H27: ='8. Schedule'!E21 -> 47346 | I27: ='8. Schedule'!C21 -> 0
A29: UNIT MIX
B30: Unit Type | E30: Sq. Ft. | F30: No. Units | G30: % of Total | H30: Rent | I30: $/SF
B31: ='7. Op Rev and Exp'!B16 -> 1 Bed | E31: ='7. Op Rev and Exp'!D16 -> 52416 | F31: ='7. Op Rev and Exp'!E16 -> 84 | G31: ='7. Op Rev and Exp'!F16 -> 0.49411765 | H31: ='7. Op Rev and Exp'!G16 -> 2490 | I31: ='7. Op Rev and Exp'!I16 -> 3.9903846
B32: ='7. Op Rev and Exp'!B17 -> 2 Bed | E32: ='7. Op Rev and Exp'!D17 -> 58167.2 | F32: ='7. Op Rev and Exp'!E17 -> 68 | G32: ='7. Op Rev and Exp'!F17 -> 0.4 | H32: ='7. Op Rev and Exp'!G17 -> 3155 | I32: ='7. Op Rev and Exp'!I17 -> 3.6883329
B33: Res 2B part | E33: ='7. Op Rev and Exp'!D19 -> 0 | F33: =+'7. Op Rev and Exp'!E19 -> 0 | G33: ='7. Op Rev and Exp'!F19 -> 0 | H33: ='7. Op Rev and Exp'!G19 -> 0 | I33: ='7. Op Rev and Exp'!I19 -> 0
B34: Total Res Units | E34: ='7. Op Rev and Exp'!D20 -> 128853.2 | F34: ='7. Op Rev and Exp'!E20 -> 170 | G34: ='7. Op Rev and Exp'!F20 -> 1 | H34: ='7. Op Rev and Exp'!G20 -> 2881.4706 | I34: =+H34/E35 -> 3.801613
B35: Average Res | E35: ='7. Op Rev and Exp'!D21 -> 757.96 | H35: ='7. Op Rev and Exp'!G21 -> 2881.4706 | I35: ='7. Op Rev and Exp'!I21 -> 3.801613
A37: DEVELOPMENT COSTS
G38: Total | H38: Per Res unit | I38: Per Sqft | J38: %
B39: Land | G39: ='9. Development Costs'!H16 -> 10407367 | H39: ='9. Development Costs'!I16 -> 61219.804 | I39: ='9. Development Costs'!J16 -> 80.769176 | J39: =G39/$G$48 -> 0.11020019
B40: Construction | G40: ='9. Development Costs'!H22 -> 65683716 | H40: ='9. Development Costs'!I22 -> 508814.41 | I40: ='9. Development Costs'!J22 -> 509.75619 | J40: =G40/$G$48 -> 0.69550331
B41: Professional Fees | G41: ='9. Development Costs'!H41 -> 2028467.7 | H41: ='9. Development Costs'!I41 -> 11932.163 | I41: ='9. Development Costs'!J41 -> 15.742471 | J41: =G41/$G$48 -> 0.021478779
B42: Development Management | G42: ='9. Development Costs'!H46 -> 1692804.6 | H42: ='9. Development Costs'!I46 -> 9957.6741 | I42: ='9. Development Costs'!J46 -> 13.137466 | J42: =G42/$G$48 -> 0.017924552
B43: Permits and Approvals | G43: ='9. Development Costs'!H59 -> 7449711.3 | H43: ='9. Development Costs'!I59 -> 43821.831 | I43: ='9. Development Costs'!J59 -> 57.815493 | J43: =G43/$G$48 -> 0.078882548
B44: Marketing and Leasing | G44: ='9. Development Costs'!H66 -> 1676350 | H44: ='9. Development Costs'!I66 -> 9860.8824 | I44: ='9. Development Costs'!J66 -> 13.009766 | J44: =G44/$G$48 -> 0.01775032
B45: Financing and Interest | G45: ='9. Development Costs'!H80-'9. Development Costs'!H77 -> 8970071.7 | H45: ='9. Development Costs'!I80 -> 52765.128 | I45: ='9. Development Costs'!J80 -> 69.61466 | J45: =G45/$G$48 -> 0.094981146
B46: Taxes, HST, VAT | G46: ='9. Development Costs'!H77 -> 0 | H46: ='9. Development Costs'!I77 -> 0 | I46: ='9. Development Costs'!J77 -> 0 | J46: =G46/$G$48 -> 0
B47: Operating income during lease-up incl Sec Deposit | G47: ='9. Development Costs'!H87 -> -3467937.3 | H47: ='9. Development Costs'!I87 -> -20399.631 | I47: ='9. Development Costs'!J87 -> -26.913862 | J47: =G47/$G$48 -> -0.03672085
...

Sheet 3. Headline #s
A5: =TODAY() -> 46069
A10: Apartment Development Model Reverse 1B
A12: ='1. 1A Proforma'!F3 -> 2240 Birchmount Road, Scarborough, ON
A14: ='2. Rev 1B Exec Summary'!F34&" Units" -> 170 Units
A17: Apartment Pro-forma
A20: Prepared by:
A22: SVN Rock Advisors Inc.
C26: HEADLINE NUMBERS
C28: NOI at stabilization after completion | G28: ='2. Rev 1B Exec Summary'!H9 -> 4899902.8
C29: Capitalization Rate | G29: ='2. Rev 1B Exec Summary'!H10 -> 0.045
C30: Valuation | D30: @ | E30: ='2. Rev 1B Exec Summary'!D11 -> 4.4820546 | F30: per sqft avg revenue | G30: ='2. Rev 1B Exec Summary'!H11 -> 1.0888673e+08
C31: Less: Selling costs | G31: ='2. Rev 1B Exec Summary'!H12 -> -1088867.3
C32: Sales Proceeds | G32: ='2. Rev 1B Exec Summary'!H13 -> 1.0779786e+08
C33: Total Cost | G33: ='2. Rev 1B Exec Summary'!H14 -> -94440551
C34: Profit before taxes if sold at stabilization | G34: ='2. Rev 1B Exec Summary'!H15 -> 13357310
C36: Return on cost | G36: ='2. Rev 1B Exec Summary'!H17 -> 0.14143617
C37: Development Yield | G37: =G28/(-G33) -> 0.051883462
A39: Merchant Builder | C39: Equity IRR, if sold upon stabilization | G39: ='2. Rev 1B Exec Summary'!H18 -> 0.27897087
A40: Investment Hold | C40: ="Equity IRR "&'11. 10-Yr Cash Flow IRR'!A66&"-Year" -> Equity IRR 10-Year | G40: ='2. Rev 1B Exec Summary'!H19 -> 0.20617253
C42: Construction Costs per unit | G42: ='9. Development Costs'!I89 -> 555532.65
C43: Construction Costs per sqft | G43: ='9. Development Costs'!J89 -> 732.93136
C44: Value per unit at stabilization | G44: =G30/'7. Op Rev and Exp'!E20 -> 640510.17
C45: Value per sqft at stabilization | G45: =G30/'9. Development Costs'!I10 -> 845.04481
A48: Disclaimer: RE: Use of the New Apartment Construction Financial Model
A49: SVN Rock Advisors Inc. Brokerage, Derek A. Lobo & Associates (DALA) and/or SVN Canada Inc. (herein described as "the Consultant") has developed the New Apartment Construction Financial Model (herein described as "the model") as a general guide to help a user understand the high level profitability of rental apartment construction development on a given site. The Model is developed in Microsoft Excel, and it is expected by the consultant, that the user of the model is proficient in Excel. Any accidental deletion of a cell may corrupt the entire file and/or show inaccurate results that the Consultant is not responsible for. The model is intended to provide a high level understanding of the profitability, and does not assure and/or guarantee success of a project in any way.
A50: Confidentiality Policy
A51: Intellecutal rights on this file remain with the Consultant
A52: Disclaimers:
A53: We make no guarantees and do not undertake to confirm independently that the information, result and or data provided is accurate or comprehensive. We recommend the client independently review data sources and periodically update and confirm the data used in the excel file.
A54: The consultant's principals, management, staff, contractors and associates are real estate consultants only.
A55: The Consultant makes no guarantees, written or otherwise, that if the client adopts or acts on the excel model's observations, findings, analysis or recommendations in the report that the client's project will be successful, nor do we, as real estate consultants, accept any legal or financial responsibility or liability for failure, under-performance, or termination of the client's project.
A56: Limitation of Liability:
A57: To the fullest extent permitted by applicable law, in no event shall the consultant be liable to the client or any other user for any direct, indirect, incidental, special, punitive, or consequential damages whatsoever resulting from any (i) use of the excel file, (ii) errors, mistakes, or inaccuracies of content, (iii) any bugs, viruses, or like, which may be transmitted to or through the excel file to or by any party, (iv) any loss of your data or content, (v) any errors or omissions in any content or for any loss or damage of any kind incurred as a result of your use of the file, whether based on warranty, contract, tort, or any other legal theory, and whether or not the client/users are advised of the possibility of such damanges, and/or (vi) the disclosure of information pursuant to these terms of use or a privacy policy.
A58: Despite the above, our total liability to you for any cause of action you take against us will at all times be limited to no more than $100/ - (one hundred dollars)

Sheet 4. Area Schedule
A1: AREA SCHEDULE
A2: 2240 Birchmount Road, Scarborough, Ontario
A4: # | B4: Description | C4: Quantity | D4: Unit Area (SF) | E4: Total Area (SF) | F4: Notes
A5: 1 | B5: RESIDENTIAL AREAS
A6: 1.1 | B6: Residential Units
B7: 1 Bedroom Units | C7: 84 | D7: 624 | E7: =C7*D7 -> 52416 | F7: 49% of total units
B8: 2 Bedroom Units | C8: 68 | D8: 855 | E8: =C8*D8 -> 58140 | F8: 40% of total units
B9: 3 Bedroom Units | C9: 18 | D9: 1015 | E9: =C9*D9 -> 18270 | F9: 11% of total units
B10: Total Residential Units | C10: =SUM(C7:C9) -> 170 | D10: =SUMPRODUCT(C7:C9,D7:D9)/C10 -> 757.8 | E10: =SUM(E7:E9) -> 128826 | F10: Net Rentable Area
A12: 2 | B12: AMENITY & COMMON AREAS
A13: 2.1 | B13: Resident Amenities
B14: Fitness Centre | C14: 1 | D14: 1200 | E14: 1200 | F14: Cardio & weights
B15: Multi-Purpose/Party Room | C15: 1 | D15: 1000 | E15: 1000 | F15: Events & gatherings
B16: Co-Working Space | C16: 1 | D16: 600 | E16: 600 | F16: Work from home area
B17: Games/Lounge Area | C17: 1 | D17: 500 | E17: 500 | F17: Recreation space
B18: Outdoor Terrace/BBQ Area | C18: 1 | D18: 403 | E18: 403 | F18: Rooftop or ground level
B19: Total Amenity Space | E19: =SUM(E14:E18) -> 3703 | F19: As per proforma
A21: 2.2 | B21: Building Common Areas
B22: Main Lobby | C22: 1 | D22: 600 | E22: 800 | F22: With concierge desk
B23: Corridors & Hallways | C23: 170 | D23: 25 | E23: =C23*D23 -> 4250 | F23: Per unit average
B24: Elevator Lobbies | C24: 6 | D24: 60 | E24: =C24*D24 -> 360 | F24: Per floor (15 floors)
B25: Stairwells (2) | C25: 2 | D25: 600 | E25: =C25*D25 -> 1200 | F25: Exit stairs
B26: Elevators (3) | C26: 3 | D26: 60 | E26: =C26*D26 -> 180 | F26: Passenger elevators
B27: Mail/Parcel Room | C27: 3 | D27: 150 | E27: 300 | F27: Package lockers
B28: Garbage/Recycling Rooms | C28: 4 | D28: 200 | E28: =C28*D28 -> 800 | F28: Per floor grouping
B29: Electrical/Mechanical Rooms | C29: 2 | D29: 200 | E29: =C29*D29 -> 400 | F29: Service rooms
B30: Storage Lockers | C30: 85 | D30: 25 | E30: =C30*D30 -> 2125 | F30: Resident storage
B31: Janitor/Housekeeping Closets | C31: 3 | D31: 40 | E31: =C31*D31 -> 120 | F31: Per floor grouping
B32: Total Common Areas | E32: =SUM(E22:E31) -> 10535
A34: 3 | B34: COMMERCIAL AREAS
B35: Ground Floor Retail | C35: 1 | D35: 4370 | E35: 4370 | F35: Net leasable area
A37: 4 | B37: PARKING & BACK OF HOUSE
A38: 4.1 | B38: Parking
B39: Underground Parking | C39: 162 | D39: 350 | E39: =C39*D39 -> 56700 | F39: Resident parking
B40: Visitor Parking | C40: 15 | D40: 350 | E40: =C40*D40 -> 5250 | F40: Surface/underground
B41: Retail Parking | C41: 15 | D41: 350 | E41: =C41*D41 -> 5250 | F41: Dedicated retail
B42: Total Parking Area | C42: =SUM(C39:C41) -> 192 | E42: =SUM(E39:E41) -> 67200
A44: 4.2 | B44: Back of House
B45: Loading Dock | C45: 1 | D45: 300 | E45: 500 | F45: Service area
B46: Building Management Office | C46: 1 | D46: 150 | E46: 200 | F46: Admin space
...

Sheet 5. Key Assumptions
B3: =+'3. Headline #s'!$A$10 -> Apartment Development Model Reverse 1B
B4: =+'3. Headline #s'!A12 -> 2240 Birchmount Road, Scarborough, ON
B6: KEY ASSUMPTIONS
B8: 1. Development Schedule
C10: Project Start Date: | G10: =TODAY() -> 46069
E11: Duration | F11: Offset
C12: Land Purchase | E12: 0
C13: Pre-Development | E13: 12
C14: Construction | E14: 18
C15: Lease-up | E15: ='7. Op Rev and Exp'!E20/15 -> 11.333333 | F15: -3
C16: Stabilized | E16: 0
B18: 2. Building Area Schedule Summary
C20: Net Residential Area | F20: ='4. Area Schedule'!E54 -> 128826 | H20: ='4. Area Schedule'!F54 -> From proforma
C21: Total Amenity Space | F21: ='4. Area Schedule'!E55 -> 3703 | H21: ='4. Area Schedule'!F55 -> From proforma
C22: Total Common Areas | F22: ='4. Area Schedule'!E56 -> 10535 | H22: ='4. Area Schedule'!F56 -> Calculated to match GFA
C23: Commercial/Retail Area | F23: ='4. Area Schedule'!E57 -> 4370 | H23: ='4. Area Schedule'!F57 -> From proforma
C24: Parking Area (below grade) | F24: ='4. Area Schedule'!E58 -> 67200 | H24: ='4. Area Schedule'!F58 -> Not included in GFA
C25: Back of House Area | F25: ='4. Area Schedule'!E59 -> 3150 | H25: ='4. Area Schedule'!F59 -> Calculated to match GFA
C26: TOTAL GROSS FLOOR AREA (GFA) | F26: =SUM(F20:F25)-F24 -> 150584 | H26: ='4. Area Schedule'!F60 -> Calculated total
C28: Res No. of Units | F28: ='7. Op Rev and Exp'!E20 -> 170
C29: Building Number of Floors | F29: ='13. Altus Cost Guide 25'!A7 -> 13-39 Storeys | H29: TBC
B32: 2. Development Cost
D34: Cap Rate | E34: % of Value | F34: Numbers | G34: Rentable/SF | H34: Numbers on | I34: % of Value | J34: Rentable/SF
D35: Running | E35: Today | F35: Today | G35: ='7. Op Rev and Exp'!D20 -> 128853.2 | H35: Completion | I35: on Compl | J35: =+G35 -> 128853.2
C36: Value | D36: ='7. Op Rev and Exp'!D56 -> 0.045 | E36: 1 | F36: =+'7. Op Rev and Exp'!H56 -> 1.026064e+08 | G36: =+F36/$G$35 -> 796.3046 | H36: =+'3. Headline #s'!G30 -> 1.0888673e+08 | I36: 1 | J36: =+H36/$J$35 -> 845.04481
C37: Profit (bef commission) | E37: 0.08 | F37: =+F36*E37 -> 8208511.7 | G37: =+F37/$G$35 -> 63.704368 | H37: =+'3. Headline #s'!G34-'3. Headline #s'!G31 -> 14446177 | I37: =+H37/H36 -> 0.13267161 | J37: =+H37/$J$35 -> 112.11346
C38: Total Development Cost | E38: =+E36-E37 -> 0.92 | F38: =+F36*E38 -> 94397884 | G38: =+F38/$G$35 -> 732.60023 | H38: =-'3. Headline #s'!G33 -> 94440551 | I38: =+H38/H36 -> 0.86732839 | J38: =+H38/$J$35 -> 732.93136
G39: * | J39: *
C40: * Net Res Rentable PSF
E41: % of Total | G41: PSF of
E42: Devpt Cost | F42: Amount | G42: Res Rentable
B43: A | C43: Land
C44: Land Purchase | E44: =+E37+0.025 -> 0.105 | F44: =+F38*E44 -> 9911777.9 | G44: =+F44/$G$35 -> 76.923024
C45: Closing & Contingency (% of Land) | D45: 0.05 | F45: =F44*D45 -> 495588.89 | G45: =+F45/$G$35 -> 3.8461512 | M45: Hard Cost Calc
O46: Altus Cost/SF | Q46: Total Cost
B47: B | C47: Construction | N47: SF | O47: Low | P47: High | Q47: Low | R47: High | S47: Average
C48: Hard Cost | E48: =F48/F38 -> 0.68217419 | F48: =S50 -> 64395800 | G48: =+F48/$G$35 -> 499.76097 | M48: GFA | N48: =F26 -> 150584 | O48: ='13. Altus Cost Guide 25'!H7 -> $310 | P48: ='13. Altus Cost Guide 25'!I7 -> $340 | Q48: =O48*N48 -> 46681040 | R48: =P48*N48 -> 51198560 | S48: =(Q48+R48)/2 -> 48939800
C49: Contingency (% of HC) | D49: 0.02 | F49: =F48*D49 -> 1287916 | G49: =+F49/$G$35 -> 9.9952194 | M49: Parking (below grade) | N49: =F24 -> 67200 | O49: ='13. Altus Cost Guide 25'!F38 -> $175 | P49: ='13. Altus Cost Guide 25'!G38 -> $285 | Q49: =O49*N49 -> 11760000 | R49: =P49*N49 -> 19152000 | S49: =(Q49+R49)/2 -> 15456000
M50: Total | Q50: =Q48+Q49 -> 58441040 | R50: =R48+R49 -> 70350560 | S50: =(Q50+R50)/2 -> 64395800
B51: C | C51: Professional Fees (% of HC) | D51: 0.03 | E51: =F51/F38 -> 0.020465226 | F51: =F48*D51 -> 1931874 | G51: =+F51/$G$35 -> 14.992829 | M51: Hard Cost - Proforma | S51: =F48 -> 64395800
...

Sheet 6. Debt Stack & Financing
I1: ='2. Rev 1B Exec Summary'!J1 -> Currently running: Base Case
B4: ='2. Rev 1B Exec Summary'!B3:I3 -> Apartment Development Model Reverse 1B
B5: ='2. Rev 1B Exec Summary'!B4:I4 -> 2240 Birchmount Road, Scarborough, ON
B8: DEBT STACK & FINANCING ASSUMPTIONS
B11: Blended Construction Interest Rate Calucator
E12: Int Rate | F12: Component Int
B13: Total Equity | D13: =+'10. Development Cash Flow'!D108 -> 0.099954838
B14: Total Debt | D14: =1-D13 -> 0.90004516
B16: Total Debt | D16: =+'5. Key Assumptions'!E71 -> 0.9
B17: Mezannine Debt | D17: =+'5. Key Assumptions'!E69 -> 0.15 | E17: ='5. Key Assumptions'!G69 -> 0.0795 | F17: =+D17*E17 -> 0.011925
B18: Regular Bank Debt | D18: =+D16-D17 -> 0.75 | E18: ='5. Key Assumptions'!G70 -> 0.0545 | F18: =+D18*E18 -> 0.040875
B19: Total Debt | D19: =D17+D18 -> 0.9 | F19: =+F17+F18 -> 0.0528
B20: Blended Construction Interest Rate | D20: =+F19/D19 -> 0.058666667
B23: Note 1: Double check the Total Debt Ratio from DCF page.
B24: 2: Client to confirm if Mezannine Debt, otherwise take 0%
B27: CMHC Permanent Take-Out Loan Assumptions
B29: CMHC - MLI Select Program :
B31: Loan to Value Ratio | D31: 0.95
B32: DSCR | D32: 1.1
B33: Amortization | D33: 40 | E33: Years, can go higher
B34: Interest Rate | D34: 0.037
B35: CMHC Premium Cost | D35: 0.0518
B37: Value @ Cap Rate Running | C37: ='11. 10-Yr Cash Flow IRR'!K10 -> 0.045 | D37: ='11. 10-Yr Cash Flow IRR'!K11 -> 1.0888673e+08
B38: Loan Amount | D38: ='11. 10-Yr Cash Flow IRR'!K14 -> 92243039
B39: LTV Ratio | D39: =D38/D37 -> 0.84714676
B40: CMHC Premium Amount | D40: =D38*D35 -> 4778189.4
B42: Stabilized NOI | D42: ='11. 10-Yr Cash Flow IRR'!K9 -> 4899902.8
B43: Annual Debt Service | D43: ='11. 10-Yr Cash Flow IRR'!K16 -> 4421871.7
B44: DSCR | D44: =D42/D43 -> 1.1081061

Sheet 7. Op Rev and Exp
I1: ="Currently running: "&CHOOSE('12. Sensitivity'!$E$8,'12. Sensitivity'!$B$11,'12. Sensitivity'!$B$12,'12. Sensitivity'!$B$13) -> Currently running: Base Case
B3: ='3. Headline #s'!A10 -> Apartment Development Model Reverse 1B
B4: ='3. Headline #s'!A12 -> 2240 Birchmount Road, Scarborough, ON
B5: Operating Revenue and Expenses
B8: Parking
B9: Residential Stalls | D9: =C24 -> 162
B10: Visitor Stalls | D10: =C25 -> 15
B11: Extra Stalls | D11: =C26 -> 15
B12: Total | D12: =SUM(D9:D11) -> 192 | F12: Ratio | G12: =(D9+D10)/E20 -> 1.0411765 | H12: stall per Res unit
B14: Revenue
B15: Residential | C15: Avg Sq Ft | D15: Total Area | E15: No. Units | F15: % Total | G15: Monthly $ | H15: Annual $ | I15: $/Sqft
B16: ='1. 1A Proforma'!D7 -> 1 Bed | C16: ='1. 1A Proforma'!E7 -> 624 | D16: =+C16*E16 -> 52416 | E16: ='1. 1A Proforma'!F7 -> 84 | F16: =E16/$E$20 -> 0.49411765 | G16: ='1. 1A Proforma'!I7 -> 2490 | H16: =+G16*E16*12 -> 2509920 | I16: =H16/D16/12 -> 3.9903846
B17: ='1. 1A Proforma'!D8 -> 2 Bed | C17: ='1. 1A Proforma'!E8 -> 855.4 | D17: =+C17*E17 -> 58167.2 | E17: ='1. 1A Proforma'!F8 -> 68 | F17: =E17/$E$20 -> 0.4 | G17: ='1. 1A Proforma'!I8 -> 3155 | H17: =+G17*E17*12 -> 2574480 | I17: =H17/D17/12 -> 3.6883329
B18: ='1. 1A Proforma'!D9 -> 3 Bed | C18: ='1. 1A Proforma'!E9 -> 1015 | D18: =+C18*E18 -> 18270 | E18: ='1. 1A Proforma'!F9 -> 18 | F18: =E18/$E$20 -> 0.10588235 | G18: ='1. 1A Proforma'!I9 -> 3675 | H18: =+G18*E18*12 -> 793800 | I18: =H18/D18/12 -> 3.6206897
L19: Sensitize Rent - S2 | M19: ='14. Sensitivity 2'!D6 -> 1
B20: Total | C20: =+D20/E20 -> 757.96 | D20: =SUM(D16:D19) -> 128853.2 | E20: =SUM(E16:E19) -> 170 | F20: =SUM(F16:F19) -> 1 | G20: =+H20/12/E20 -> 2881.4706 | H20: =SUM(H16:H19)*M19 -> 5878200 | I20: =H20/D20/12 -> 3.801613 | L20: =H20 -> 5878200
B21: Average Res | D21: =(D16+D17+D19+D18)/E20 -> 757.96 | G21: =(H16+H17+H18+H19)/(E16+E17+E18+E19)/12 -> 2881.4706 | I21: =G21/D21 -> 3.801613 | L21: =H20-L20 -> 0
B23: Other Income | C23: # Spaces | D23: Monthly Fee | E23: Annual/Res Unit | F23: Monthly/Res Unit | G23: Monthly | H23: Annual $
B24: Underground Parking | C24: ='1. 1A Proforma'!F18 -> 162 | D24: ='1. 1A Proforma'!G18 -> 200 | E24: =H24/$E$20 -> 2287.0588 | F24: =G24/$E$20 -> 190.58824 | G24: =D24*C24 -> 32400 | H24: =G24*12 -> 388800
B25: Visitor Parking | C25: ='1. 1A Proforma'!F19 -> 15 | D25: ='1. 1A Proforma'!G19 -> 0 | E25: =H25/$E$20 -> 0 | F25: =G25/$E$20 -> 0 | G25: =D25*C25 -> 0 | H25: =G25*12 -> 0
B26: Retail Parking | C26: ='1. 1A Proforma'!F20 -> 15 | D26: ='1. 1A Proforma'!G20 -> 0 | E26: =H26/$E$20 -> 0 | F26: =G26/$E$20 -> 0 | G26: =D26*C26 -> 0 | H26: =G26*12 -> 0
B27: Storage Lockers | C27: ='1. 1A Proforma'!F21 -> 100 | D27: ='1. 1A Proforma'!G21 -> 40 | E27: =H27/$E$20 -> 282.35294 | F27: =G27/$E$20 -> 23.529412 | G27: =D27*C27 -> 4000 | H27: =G27*12 -> 48000
B28: Submetering Reimbursement | C28: ='1. 1A Proforma'!F22 -> 170 | D28: ='1. 1A Proforma'!G22 -> 20 | E28: =H28/$E$20 -> 240 | F28: =G28/$E$20 -> 20 | G28: =D28*C28 -> 3400 | H28: =G28*12 -> 40800
B29: Commercial / Retail | C29: ='1. 1A Proforma'!F26 -> 4370 | D29: ='1. 1A Proforma'!G26 -> 40 | G29: =H29/12 -> 14566.667 | H29: =C29*D29 -> 174800
B30: Total Other Income | G30: =SUM(G24:G29) -> 54366.667 | H30: =SUM(H24:H29) -> 652400
B32: Total Potential Gross Revenue (including parking & storage) | G32: =H32/12 -> 544216.67 | H32: =H30+H20 -> 6530600
B33: Vacancies (Rent & Others) | C33: ='1. 1A Proforma'!F24 -> 0.03 | G33: =H33/12 -> 16326.5 | H33: =H32*C33 -> 195918
B34: Effective Gross Income | G34: =G32-G33 -> 527890.17 | H34: =H32-H33 -> 6334682
B37: Operating Expenses
E38: Annual/Unit | F38: Monthly Per Unit | G38: Monthly | H38: Total Annual | I38: %
B39: Utilities (Common Area Only) | C39: ='1. 1A Proforma'!F31 -> 170 | D39: ='1. 1A Proforma'!G31 -> units @ | E39: ='1. 1A Proforma'!H31 -> 1130 | F39: =G39/C39 -> 94.166667 | G39: =H39/12 -> 16008.333 | H39: =E39*C39*M39 -> 192100 | I39: =H39/$H$34 -> 0.030325121 | L39: Sensitize Op Cost - S2 | M39: =+'14. Sensitivity 2'!$D$8 -> 1
B40: Repairs & Maintenance | C40: ='1. 1A Proforma'!F32 -> 170 | D40: ='1. 1A Proforma'!G32 -> units @ | E40: ='1. 1A Proforma'!H32 -> 1050 | F40: =G40/C40 -> 87.5 | G40: =H40/12 -> 14875 | H40: =E40*C40*M40 -> 178500 | I40: =H40/$H$34 -> 0.02817821 | L40: Sensitize Op Cost - S2 | M40: =+M39 -> 1
B41: Staffing | C41: ='1. 1A Proforma'!F33 -> 170 | D41: ='1. 1A Proforma'!G33 -> units @ | E41: ='1. 1A Proforma'!H33 -> 1200 | F41: =G41/C41 -> 100 | G41: =H41/12 -> 17000 | H41: =E41*C41*M41 -> 204000 | I41: =H41/$H$34 -> 0.032203669 | L41: Sensitize Op Cost - S2 | M41: =+M40 -> 1
B42: Insurance | C42: ='1. 1A Proforma'!F34 -> 170 | D42: ='1. 1A Proforma'!G34 -> units @ | E42: ='1. 1A Proforma'!H34 -> 450 | F42: =G42/C42 -> 37.5 | G42: =H42/12 -> 6375 | H42: =E42*C42*M42 -> 76500 | I42: =H42/$H$34 -> 0.012076376 | L42: Sensitize Op Cost - S2 | M42: =+M41 -> 1
B43: Marketing | C43: ='1. 1A Proforma'!F35 -> 170 | D43: ='1. 1A Proforma'!G35 -> units @ | E43: ='1. 1A Proforma'!H35 -> 300 | F43: =G43/C43 -> 25 | G43: =H43/12 -> 4250 | H43: =E43*C43*M43 -> 51000 | I43: =H43/$H$34 -> 0.0080509172 | L43: Sensitize Op Cost - S2 | M43: =+M42 -> 1
B44: General & Admin | C44: ='1. 1A Proforma'!F36 -> 170 | D44: ='1. 1A Proforma'!G36 -> units @ | E44: ='1. 1A Proforma'!H36 -> 250 | F44: =G44/C44 -> 20.833333 | G44: =H44/12 -> 3541.6667 | H44: =E44*C44*M44 -> 42500 | I44: =H44/$H$34 -> 0.0067090976 | L44: Sensitize Op Cost - S2 | M44: =+M43 -> 1
B45: Management Fee | C45: ='1. 1A Proforma'!F37 -> % of Gross Revenue | D45: ='1. 1A Proforma'!G37 -> 0.0425 | E45: =H45/C44 -> 1583.6705 | F45: =G45/C44 -> 131.97254 | G45: =H45/12 -> 22435.332 | H45: =H34*D45*M45 -> 269223.99 | I45: =H45/$H$34 -> 0.0425 | L45: Sensitize Op Cost - S2 | M45: =+M44 -> 1
B46: Property Taxes (Municipal Rate)* | C46: ='1. 1A Proforma'!F38 -> 0.00754087 | D46: ='1. 1A Proforma'!G38 -> 450000 | E46: =H46/$E$20 -> 3393.3915 | F46: =G46/$E$20 -> 282.78262 | G46: =H46/12 -> 48073.046 | H46: =C46*D46*E20*M46 -> 576876.55 | I46: =H46/$H$34 -> 0.091066379 | L46: Sensitize Op Cost - S2 | M46: =+M45 -> 1
B47: Reserve for Asset Replacement | C47: ='1. 1A Proforma'!F39 -> % of Gross Revenue | D47: ='1. 1A Proforma'!G39 -> 0.02 | E47: =H47/$E$20 -> 745.25671 | F47: =G47/$E$20 -> 62.104725 | G47: =H47/12 -> 10557.803 | H47: =D47*H34*M47 -> 126693.64 | I47: =H47/$H$34 -> 0.02 | L47: Sensitize Op Cost - S2 | M47: =+M46 -> 1
B48: Total Expenses | E48: =SUM(E39:E47) -> 10102.319 | F48: =SUM(F39:F47) -> 841.85989 | G48: =H48/12 -> 143116.18 | H48: =SUM(H39:H47) -> 1717394.2 | I48: =H48/$H$34 -> 0.27110977
...

Sheet 8. Schedule
BP1: ="Currently running: "&CHOOSE('12. Sensitivity'!$E$8,'12. Sensitivity'!$B$11,'12. Sensitivity'!$B$12,'12. Sensitivity'!$B$13) -> Currently running: Base Case
B3: ='3. Headline #s'!A10 -> Apartment Development Model Reverse 1B
B4: ='3. Headline #s'!A12 -> 2240 Birchmount Road, Scarborough, ON
B5: Schedule
B8: Project Start Date | D8: ='5. Key Assumptions'!G10 -> 46069
I10: =D8 -> 46069 | J10: =EDATE(I10,1) -> 46097 | K10: =EDATE(J10,1) -> 46128 | L10: =EDATE(K10,1) -> 46158 | M10: =EDATE(L10,1) -> 46189 | N10: =EDATE(M10,1) -> 46219 | O10: =EDATE(N10,1) -> 46250 | P10: =EDATE(O10,1) -> 46281 | Q10: =EDATE(P10,1) -> 46311 | ... BP10: =EDATE(BO10,1) -> 47864
C11: Duration | D11: Start Date | E11: End Date | F11: Anchored to | G11: Offset | I11: ="Q"&ROUNDUP(MONTH(I10)/3,0)&" "&YEAR(I10) -> Q1 2026 | L11: ="Q"&ROUNDUP(MONTH(L10)/3,0)&" "&YEAR(L10) -> Q2 2026 | O11: ="Q"&ROUNDUP(MONTH(O10)/3,0)&" "&YEAR(O10) -> Q3 2026 | R11: ="Q"&ROUNDUP(MONTH(R10)/3,0)&" "&YEAR(R10) -> Q4 2026 | U11: ="Q"&ROUNDUP(MONTH(U10)/3,0)&" "&YEAR(U10) -> Q1 2027 | X11: ="Q"&ROUNDUP(MONTH(X10)/3,0)&" "&YEAR(X10) -> Q2 2027 | AA11: ="Q"&ROUNDUP(MONTH(AA10)/3,0)&" "&YEAR(AA10) -> Q3 2027 | AD11: ="Q"&ROUNDUP(MONTH(AD10)/3,0)&" "&YEAR(AD10) -> Q4 2027 | AG11: ="Q"&ROUNDUP(MONTH(AG10)/3,0)&" "&YEAR(AG10) -> Q1 2028 | AJ11: ="Q"&ROUNDUP(MONTH(AJ10)/3,0)&" "&YEAR(AJ10) -> Q2 2028 | AM11: ="Q"&ROUNDUP(MONTH(AM10)/3,0)&" "&YEAR(AM10) -> Q3 2028 | AP11: ="Q"&ROUNDUP(MONTH(AP10)/3,0)&" "&YEAR(AP10) -> Q4 2028 | AS11: ="Q"&ROUNDUP(MONTH(AS10)/3,0)&" "&YEAR(AS10) -> Q1 2029 | AV11: ="Q"&ROUNDUP(MONTH(AV10)/3,0)&" "&YEAR(AV10) -> Q2 2029 | AY11: ="Q"&ROUNDUP(MONTH(AY10)/3,0)&" "&YEAR(AY10) -> Q3 2029 | BB11: ="Q"&ROUNDUP(MONTH(BB10)/3,0)&" "&YEAR(BB10) -> Q4 2029 | BE11: ="Q"&ROUNDUP(MONTH(BE10)/3,0)&" "&YEAR(BE10) -> Q1 2030 | BH11: ="Q"&ROUNDUP(MONTH(BH10)/3,0)&" "&YEAR(BH10) -> Q2 2030 | BK11: ="Q"&ROUNDUP(MONTH(BK10)/3,0)&" "&YEAR(BK10) -> Q3 2030 | BN11: ="Q"&ROUNDUP(MONTH(BN10)/3,0)&" "&YEAR(BN10) -> Q4 2030
B13: Land Purchase | C13: =+'5. Key Assumptions'!E12 -> 0 | D13: =D8 -> 46069 | E13: =EDATE(D13,C13) -> 46069 | F13: =B8 -> Project Start Date | G13: =+'5. Key Assumptions'!F12 -> 0 | I13: =IF(AND(I$10>=$D13,I$10<=$E13),1,"") -> 1 | J13: =IF(AND(J$10>=$D13,J$10<=$E13),1,"") | K13: =IF(AND(K$10>=$D13,K$10<=$E13),1,"") | L13: =IF(AND(L$10>=$D13,L$10<=$E13),1,"") | M13: =IF(AND(M$10>=$D13,M$10<=$E13),1,"") | N13: =IF(AND(N$10>=$D13,N$10<=$E13),1,"") | O13: =IF(AND(O$10>=$D13,O$10<=$E13),1,"") | P13: =IF(AND(P$10>=$D13,P$10<=$E13),1,"") | ... BP13: =IF(AND(BP$10>=$D13,BP$10<=$E13),1,"")
B15: Pre-Development | C15: =+'5. Key Assumptions'!E13 -> 12 | D15: =EDATE(E13,G15+1) -> 46097 | E15: =EDATE(D15,C15) -> 46462 | F15: =B13 -> Land Purchase | G15: =+'5. Key Assumptions'!F13 -> 0 | I15: =IF(AND(I$10>=$D15,I$10<=$E15),1,"") | J15: =IF(AND(J$10>=$D15,J$10<=$E15),1,"") -> 1 | K15: =IF(AND(K$10>=$D15,K$10<=$E15),1,"") -> 1 | L15: =IF(AND(L$10>=$D15,L$10<=$E15),1,"") -> 1 | M15: =IF(AND(M$10>=$D15,M$10<=$E15),1,"") -> 1 | N15: =IF(AND(N$10>=$D15,N$10<=$E15),1,"") -> 1 | O15: =IF(AND(O$10>=$D15,O$10<=$E15),1,"") -> 1 | P15: =IF(AND(P$10>=$D15,P$10<=$E15),1,"") -> 1 | ... BP15: =IF(AND(BP$10>=$D15,BP$10<=$E15),1,"")
B17: Construction | C17: =+'12. Sensitivity'!H20 -> 18 | D17: =EDATE(E15,G17+1) -> 46493 | E17: =EDATE(D17,C17) -> 47042 | F17: =B15 -> Pre-Development | G17: =+'5. Key Assumptions'!F14 -> 0 | I17: =IF(AND(I$10>=$D17,I$10<=$E17),1,"") | J17: =IF(AND(J$10>=$D17,J$10<=$E17),1,"") | K17: =IF(AND(K$10>=$D17,K$10<=$E17),1,"") | L17: =IF(AND(L$10>=$D17,L$10<=$E17),1,"") | M17: =IF(AND(M$10>=$D17,M$10<=$E17),1,"") | N17: =IF(AND(N$10>=$D17,N$10<=$E17),1,"") | O17: =IF(AND(O$10>=$D17,O$10<=$E17),1,"") | P17: =IF(AND(P$10>=$D17,P$10<=$E17),1,"") | ... BP17: =IF(AND(BP$10>=$D17,BP$10<=$E17),1,"")
B19: Lease-up | C19: =+'12. Sensitivity'!H25 -> 11.333333 | D19: =EDATE(E17,G19+1) -> 46981 | E19: =EDATE(D19,C19) -> 47315 | F19: =B17 -> Construction | G19: =+'5. Key Assumptions'!F15 -> -3 | I19: =IF(AND(I$10>=$D19,I$10<=$E19),1,"") | J19: =IF(AND(J$10>=$D19,J$10<=$E19),1,"") | K19: =IF(AND(K$10>=$D19,K$10<=$E19),1,"") | L19: =IF(AND(L$10>=$D19,L$10<=$E19),1,"") | M19: =IF(AND(M$10>=$D19,M$10<=$E19),1,"") | N19: =IF(AND(N$10>=$D19,N$10<=$E19),1,"") | O19: =IF(AND(O$10>=$D19,O$10<=$E19),1,"") | P19: =IF(AND(P$10>=$D19,P$10<=$E19),1,"") | ... BP19: =IF(AND(BP$10>=$D19,BP$10<=$E19),1,"")
I20: =IF(AND(I$10>=$D20,I$10<=$E20),1,"") | J20: =IF(AND(J$10>=$D20,J$10<=$E20),1,"") | K20: =IF(AND(K$10>=$D20,K$10<=$E20),1,"") | L20: =IF(AND(L$10>=$D20,L$10<=$E20),1,"") | M20: =IF(AND(M$10>=$D20,M$10<=$E20),1,"") | N20: =IF(AND(N$10>=$D20,N$10<=$E20),1,"") | O20: =IF(AND(O$10>=$D20,O$10<=$E20),1,"") | P20: =IF(AND(P$10>=$D20,P$10<=$E20),1,"") | ... BP20: =IF(AND(BP$10>=$D20,BP$10<=$E20),1,"")
B21: Stabilized | C21: =+'5. Key Assumptions'!E16 -> 0 | D21: =EDATE(E19,G21+1) -> 47346 | E21: =EDATE(D21,C21) -> 47346 | F21: =B19 -> Lease-up | G21: =+'5. Key Assumptions'!F16 -> 0 | I21: =IF(AND(I$10>=$D21,I$10<=$E21),1,"") | J21: =IF(AND(J$10>=$D21,J$10<=$E21),1,"") | K21: =IF(AND(K$10>=$D21,K$10<=$E21),1,"") | L21: =IF(AND(L$10>=$D21,L$10<=$E21),1,"") | M21: =IF(AND(M$10>=$D21,M$10<=$E21),1,"") | N21: =IF(AND(N$10>=$D21,N$10<=$E21),1,"") | O21: =IF(AND(O$10>=$D21,O$10<=$E21),1,"") | P21: =IF(AND(P$10>=$D21,P$10<=$E21),1,"") | ... BP21: =IF(AND(BP$10>=$D21,BP$10<=$E21),1,"")

Sheet 9. Development Costs
J1: ="Currently running: "&CHOOSE('12. Sensitivity'!$E$8,'12. Sensitivity'!$B$11,'12. Sensitivity'!$B$12,'12. Sensitivity'!$B$13) -> Currently running: Base Case
B3: ='3. Headline #s'!A10 -> Apartment Development Model Reverse 1B
B4: ='3. Headline #s'!A12 -> 2240 Birchmount Road, Scarborough, ON
B5: Development Costs
B9: Number of Units: | I9: ='7. Op Rev and Exp'!E20 -> 170 | J9: Res only
B10: Net Rentable Area: | I10: ='7. Op Rev and Exp'!D20 -> 128853.2 | J10: Res
H12: Total | I12: Per unit | J12: Per Sqft
B13: LAND | M13: Contingency Prov
B14: Land | H14: =+'5. Key Assumptions'!F44 -> 9911777.9 | I14: =H14/$I$9 -> 58304.576 | J14: =H14/$I$10 -> 76.923024
B15: Closing / Other Cost | G15: =+H15/H14 -> 0.05 | H15: =+'5. Key Assumptions'!F45 -> 495588.89 | I15: =H15/$I$9 -> 2915.2288 | J15: =H15/$I$10 -> 3.8461512
B16: Total Land Costs | G16: =H16/$H$89 -> 0.11020019 | H16: =SUM(H14:H15) -> 10407367 | I16: =SUM(I14:I15) -> 61219.804 | J16: =SUM(J14:J15) -> 80.769176
B18: CONSTRUCTION
B19: Construction hard cost | H19: =+'5. Key Assumptions'!F48*M19 -> 64395800 | I19: =H19/$I$9 -> 378798.82 | J19: =H19/$I$10 -> 499.76097 | L19: Sensitize | M19: =+'14. Sensitivity 2'!D10 -> 1
B20: Offsite/Sitework Costs | H20: 0 | I20: =H20/$I$9 -> 0 | J20: =H20/$I$10 -> 0
B21: Construction contingency | G21: =+H21/H19 -> 0.02 | H21: =+'5. Key Assumptions'!F49 -> 1287916 | I21: =H21/$I$9 -> 7575.9765 | J21: =H21/$I$10 -> 9.9952194 | K21: =+H21/H19 -> 0.02 | L21: =+H19 -> 64395800 | M21: =+H21 -> 1287916 | N21: =+M21/L21 -> 0.02
B22: Total Construction Costs | G22: =H22/$H$89 -> 0.69550331 | H22: =SUM(H19:H21) -> 65683716 | I22: =SUM(I14:I21) -> 508814.41 | J22: =SUM(J19:J21) -> 509.75619
B24: PROFESSIONAL FEES
B25: Architect | H25: =+'5. Key Assumptions'!F51 -> 1931874 | I25: =H25/$I$9 -> 11363.965 | J25: =H25/$I$10 -> 14.992829
B26: Landscape architect | I26: =H26/$I$9 -> 0 | J26: =H26/$I$10 -> 0
B27: Structural engineer | I27: =H27/$I$9 -> 0 | J27: =H27/$I$10 -> 0
B28: Civil engineer | I28: =H28/$I$9 -> 0 | J28: =H28/$I$10 -> 0
B29: Mechanical & Electrical engineer | I29: =H29/$I$9 -> 0 | J29: =H29/$I$10 -> 0
B30: Geotechnical engineer | I30: =H30/$I$9 -> 0 | J30: =H30/$I$10 -> 0
B31: Site Servicing Engineer | I31: =H31/$I$9 -> 0 | J31: =H31/$I$10 -> 0
B32: Survey | I32: =H32/$I$9 -> 0 | J32: =H32/$I$10 -> 0
I33: =H33/$I$9 -> 0 | J33: =H33/$I$10 -> 0
I34: =H34/$I$9 -> 0 | J34: =H34/$I$10 -> 0
B35: Others | I35: =H35/$I$9 -> 0 | J35: =H35/$I$10 -> 0
B36: Environmental consultant | H36: 0 | I36: =H36/$I$9 -> 0 | J36: =H36/$I$10 -> 0
B37: Interior design | H37: 0 | I37: =H37/$I$9 -> 0 | J37: =H37/$I$10 -> 0
B38: Traffic consultant | H38: 0 | I38: =H38/$I$9 -> 0 | J38: =H38/$I$10 -> 0
B39: Disbursements | H39: 0 | I39: =H39/$I$9 -> 0 | J39: =H39/$I$10 -> 0
B40: Professional fee contingency | G40: 0.1 | H40: =+'5. Key Assumptions'!F52 -> 96593.7 | I40: =H40/$I$9 -> 568.19824 | J40: =H40/$I$10 -> 0.74964145
B41: Total Professional Fees | G41: =H41/$H$89 -> 0.021478779 | H41: =SUM(H25:H40) -> 2028467.7 | I41: =SUM(I25:I40) -> 11932.163 | J41: =SUM(J25:J40) -> 15.742471 | K41: =+H41/H22 -> 0.030882353 | L41: =+H41-H40 -> 1931874 | M41: =+H40 -> 96593.7 | N41: =+M41/L41 -> 0.05
B43: DEVELOPMENT MANAGEMENT
B45: Development Management Fee | H45: =+'5. Key Assumptions'!F54 -> 1692804.6 | I45: =H45/$I$9 -> 9957.6741 | J45: =H45/$I$10 -> 13.137466
B46: Total Development Management Fee | G46: =H46/$H$89 -> 0.017924552 | H46: =SUM(H44:H45) -> 1692804.6 | I46: =SUM(I44:I45) -> 9957.6741 | J46: =SUM(J44:J45) -> 13.137466
B48: PERMITS AND APPROVALS
B49: Development Permit | H49: 0 | I49: =H49/$I$9 -> 0 | J49: =H49/$I$10 -> 0
B50: Rezoning | H50: 0 | I50: =H50/$I$9 -> 0 | J50: =H50/$I$10 -> 0
...

Sheet 10. Development Cash Flow
B2: ='3. Headline #s'!A10 -> Apartment Development Model Reverse 1B
B3: ='3. Headline #s'!A12 -> 2240 Birchmount Road, Scarborough, ON
B5: Cash Flow | I5: =YEAR(I7) -> 2026 | J5: =YEAR(J7) -> 2026 | K5: =YEAR(K7) -> 2026 | L5: =YEAR(L7) -> 2026 | M5: =YEAR(M7) -> 2026 | N5: =YEAR(N7) -> 2026 | O5: =YEAR(O7) -> 2026 | P5: =YEAR(P7) -> 2026 | ... CZ5: =YEAR(CZ7) -> 2034
I6: 1 | J6: 2 | K6: 3 | L6: 4 | M6: 5 | N6: 6 | O6: 7 | P6: 8 | Q6: 9 | R6: 10 | S6: 11 | T6: 12 | U6: 13 | V6: 14 | W6: 15 | X6: 16 | Y6: 17 | Z6: 18 | AA6: 19 | AB6: 20 | AC6: 21 | AD6: 22 | AE6: 23 | AF6: 24 | AG6: 25 | AH6: 26 | AI6: 27 | AJ6: 28 | AK6: 29 | AL6: 30 | AM6: 31 | AN6: 32 | AO6: 33 | AP6: 34 | AQ6: 35 | AR6: 36 | AS6: 37 | AT6: 38 | AU6: 39 | AV6: 40 | AW6: 41 | AX6: 42 | AY6: 43 | AZ6: 44 | BA6: 45 | BB6: 46 | BC6: 47 | BD6: 48 | BE6: 49 | BF6: 50 | BG6: 51 | BH6: 52 | BI6: 53 | BJ6: 54 | BK6: 55 | BL6: 56 | BM6: 57 | BN6: 58 | BO6: 59 | BP6: 60 | BQ6: 61 | BR6: 62 | BS6: 63 | BT6: 64 | BU6: 65 | BV6: 66 | BW6: 67 | BX6: 68 | BY6: 69 | BZ6: 70 | CA6: 71 | CB6: 72 | CC6: 73 | CD6: 74 | CE6: 75 | CF6: 76 | CG6: 77 | CH6: 78 | CI6: 79 | CJ6: 80 | CK6: 81 | CL6: 82 | CM6: 83 | CN6: 84 | CO6: 85 | CP6: 86 | CQ6: 87 | CR6: 88 | CS6: 89 | CT6: 90 | CU6: 91 | CV6: 92 | CW6: 93 | CX6: 94 | CY6: 95 | CZ6: 96
B7: Items | C7: Budget | D7: Variance | E7: Total Cashflow | F7: Start | G7: End | H7: Months | I7: ='8. Schedule'!D8 -> 46069 | J7: =EDATE(I7,1) -> 46097 | K7: =EDATE(J7,1) -> 46128 | L7: =EDATE(K7,1) -> 46158 | M7: =EDATE(L7,1) -> 46189 | N7: =EDATE(M7,1) -> 46219 | O7: =EDATE(N7,1) -> 46250 | P7: =EDATE(O7,1) -> 46281 | Q7: =EDATE(P7,1) -> 46311 | ... CZ7: =EDATE(CY7,1) -> 48960
B8: LEASE-UP SCHEDULE
B9: Number of Units Completed | C9: ='9. Development Costs'!$I$9 -> 170 | D9: =ROUND(C9-E9,0) -> 0 | E9: =SUM(I9:CZ9) -> 170 | I9: =IF(I7='8. Schedule'!$E$17,'10. Development Cash Flow'!$C$9,0) -> 0 | J9: =IF(J7='8. Schedule'!$E$17,'10. Development Cash Flow'!$C$9,0) -> 0 | K9: =IF(K7='8. Schedule'!$E$17,'10. Development Cash Flow'!$C$9,0) -> 0 | L9: =IF(L7='8. Schedule'!$E$17,'10. Development Cash Flow'!$C$9,0) -> 0 | M9: =IF(M7='8. Schedule'!$E$17,'10. Development Cash Flow'!$C$9,0) -> 0 | N9: =IF(N7='8. Schedule'!$E$17,'10. Development Cash Flow'!$C$9,0) -> 0 | O9: =IF(O7='8. Schedule'!$E$17,'10. Development Cash Flow'!$C$9,0) -> 0 | P9: =IF(P7='8. Schedule'!$E$17,'10. Development Cash Flow'!$C$9,0) -> 0 | ... CZ9: =IF(CZ7='8. Schedule'!$E$17,'10. Development Cash Flow'!$C$9,0) -> 0
B10: Cumulative Units Complete | C10: ='9. Development Costs'!$I$9 -> 170 | D10: =ROUND(C10-E10,0) -> 0 | E10: =MAX(I10:CZ10) -> 170 | I10: =I9 -> 0 | J10: =I10+J9 -> 0 | K10: =J10+K9 -> 0 | L10: =K10+L9 -> 0 | M10: =L10+M9 -> 0 | N10: =M10+N9 -> 0 | O10: =N10+O9 -> 0 | P10: =O10+P9 -> 0 | Q10: =P10+Q9 -> 0 | ... CZ10: =CY10+CZ9 -> 170
B11: Percentage Completed | E11: =MAX(I11:CZ11) -> 1 | I11: =I10/'9. Development Costs'!$I$9 -> 0 | J11: =J10/'9. Development Costs'!$I$9 -> 0 | K11: =K10/'9. Development Costs'!$I$9 -> 0 | L11: =L10/'9. Development Costs'!$I$9 -> 0 | M11: =M10/'9. Development Costs'!$I$9 -> 0 | N11: =N10/'9. Development Costs'!$I$9 -> 0 | O11: =O10/'9. Development Costs'!$I$9 -> 0 | P11: =P10/'9. Development Costs'!$I$9 -> 0 | ... CZ11: =CZ10/'9. Development Costs'!$I$9 -> 1
B12: New Units Leased | C12: ='9. Development Costs'!$I$9 -> 170 | D12: =ROUND(C12-E12,0) -> 0 | E12: =SUM(I12:CZ12) -> 170 | F12: ='8. Schedule'!D19 -> 46981 | G12: ='8. Schedule'!E19 -> 47315 | H12: =DATEDIF(F12,G12,"m")+1 -> 12 | I12: =IF(AND(I$7<=$G12,I$7>=$F12,$H12<>0,$H12<>""),$C12/$H12,0) -> 0 | J12: =IF(AND(J$7<=$G12,J$7>=$F12,$H12<>0,$H12<>""),$C12/$H12,0) -> 0 | K12: =IF(AND(K$7<=$G12,K$7>=$F12,$H12<>0,$H12<>""),$C12/$H12,0) -> 0 | L12: =IF(AND(L$7<=$G12,L$7>=$F12,$H12<>0,$H12<>""),$C12/$H12,0) -> 0 | M12: =IF(AND(M$7<=$G12,M$7>=$F12,$H12<>0,$H12<>""),$C12/$H12,0) -> 0 | N12: =IF(AND(N$7<=$G12,N$7>=$F12,$H12<>0,$H12<>""),$C12/$H12,0) -> 0 | O12: =IF(AND(O$7<=$G12,O$7>=$F12,$H12<>0,$H12<>""),$C12/$H12,0) -> 0 | P12: =IF(AND(P$7<=$G12,P$7>=$F12,$H12<>0,$H12<>""),$C12/$H12,0) -> 0 | ... CZ12: =IF(AND(CZ$7<=$G12,CZ$7>=$F12,$H12<>0,$H12<>""),$C12/$H12,0) -> 0
B13: Cumulative Units Leased | C13: ='9. Development Costs'!$I$9 -> 170 | D13: =ROUND(C13-E13,0) -> 0 | E13: =MAX(I13:CZ13) -> 170 | I13: =I12 -> 0 | J13: =I13+J12 -> 0 | K13: =J13+K12 -> 0 | L13: =K13+L12 -> 0 | M13: =L13+M12 -> 0 | N13: =M13+N12 -> 0 | O13: =N13+O12 -> 0 | P13: =O13+P12 -> 0 | Q13: =P13+Q12 -> 0 | ... CZ13: =CY13+CZ12 -> 170
B14: Percentage Leased | E14: =MAX(I14:CZ14) -> 1 | I14: =I13/'9. Development Costs'!$I$9 -> 0 | J14: =J13/'9. Development Costs'!$I$9 -> 0 | K14: =K13/'9. Development Costs'!$I$9 -> 0 | L14: =L13/'9. Development Costs'!$I$9 -> 0 | M14: =M13/'9. Development Costs'!$I$9 -> 0 | N14: =N13/'9. Development Costs'!$I$9 -> 0 | O14: =O13/'9. Development Costs'!$I$9 -> 0 | P14: =P13/'9. Development Costs'!$I$9 -> 0 | ... CZ14: =CZ13/'9. Development Costs'!$I$9 -> 1
B15: Units Occupied | C15: ='9. Development Costs'!$I$9 -> 170 | D15: =ROUND(C15-E15,0) -> 0 | E15: =SUM(I15:CZ15) -> 170 | I15: 0 | J15: =IF(I$7>=$F$9,MIN(J10,J13)-I16,0) -> 0 | K15: =IF(J$7>=$F$9,MIN(K10,K13)-J16,0) -> 0 | L15: =IF(K$7>=$F$9,MIN(L10,L13)-K16,0) -> 0 | M15: =IF(L$7>=$F$9,MIN(M10,M13)-L16,0) -> 0 | N15: =IF(M$7>=$F$9,MIN(N10,N13)-M16,0) -> 0 | O15: =IF(N$7>=$F$9,MIN(O10,O13)-N16,0) -> 0 | P15: =IF(O$7>=$F$9,MIN(P10,P13)-O16,0) -> 0 | Q15: =IF(P$7>=$F$9,MIN(Q10,Q13)-P16,0) -> 0 | ... CZ15: =IF(CY$7>=$F$9,MIN(CZ10,CZ13)-CY16,0) -> 0
B16: Cumulative Units Occupied | C16: ='9. Development Costs'!$I$9 -> 170 | D16: =ROUND(C16-E16,0) -> 0 | E16: =MAX(I16:CZ16) -> 170 | I16: =I15 -> 0 | J16: =I16+J15 -> 0 | K16: =J16+K15 -> 0 | L16: =K16+L15 -> 0 | M16: =L16+M15 -> 0 | N16: =M16+N15 -> 0 | O16: =N16+O15 -> 0 | P16: =O16+P15 -> 0 | Q16: =P16+Q15 -> 0 | ... CZ16: =CY16+CZ15 -> 170
B17: Percentage Occupied | E17: =MAX(I17:CZ17) -> 1 | I17: =I16/'9. Development Costs'!$I$9 -> 0 | J17: =J16/'9. Development Costs'!$I$9 -> 0 | K17: =K16/'9. Development Costs'!$I$9 -> 0 | L17: =L16/'9. Development Costs'!$I$9 -> 0 | M17: =M16/'9. Development Costs'!$I$9 -> 0 | N17: =N16/'9. Development Costs'!$I$9 -> 0 | O17: =O16/'9. Development Costs'!$I$9 -> 0 | P17: =P16/'9. Development Costs'!$I$9 -> 0 | ... CZ17: =CZ16/'9. Development Costs'!$I$9 -> 1
B19: OPERATING INCOME
B20: Revenue Inflation Factor | I20: =(1+'11. 10-Yr Cash Flow IRR'!$E$9)^(YEAR(I7)-YEAR('8. Schedule'!$D$8)) -> 1 | J20: =(1+'11. 10-Yr Cash Flow IRR'!$E$9)^(YEAR(J7)-YEAR('8. Schedule'!$D$8)) -> 1 | K20: =(1+'11. 10-Yr Cash Flow IRR'!$E$9)^(YEAR(K7)-YEAR('8. Schedule'!$D$8)) -> 1 | L20: =(1+'11. 10-Yr Cash Flow IRR'!$E$9)^(YEAR(L7)-YEAR('8. Schedule'!$D$8)) -> 1 | M20: =(1+'11. 10-Yr Cash Flow IRR'!$E$9)^(YEAR(M7)-YEAR('8. Schedule'!$D$8)) -> 1 | N20: =(1+'11. 10-Yr Cash Flow IRR'!$E$9)^(YEAR(N7)-YEAR('8. Schedule'!$D$8)) -> 1 | O20: =(1+'11. 10-Yr Cash Flow IRR'!$E$9)^(YEAR(O7)-YEAR('8. Schedule'!$D$8)) -> 1 | P20: =(1+'11. 10-Yr Cash Flow IRR'!$E$9)^(YEAR(P7)-YEAR('8. Schedule'!$D$8)) -> 1 | ... CZ20: =(1+'11. 10-Yr Cash Flow IRR'!$E$9)^(YEAR(CZ7)-YEAR('8. Schedule'!$D$8)) -> 1.1716594
B21: Cost Inflation Factor | I21: =(1+'11. 10-Yr Cash Flow IRR'!$E$10)^(YEAR(I7)-YEAR('8. Schedule'!$D$8)) -> 1 | J21: =(1+'11. 10-Yr Cash Flow IRR'!$E$9)^(YEAR(J7)-YEAR('8. Schedule'!$D$8)) -> 1 | K21: =(1+'11. 10-Yr Cash Flow IRR'!$E$9)^(YEAR(K7)-YEAR('8. Schedule'!$D$8)) -> 1 | L21: =(1+'11. 10-Yr Cash Flow IRR'!$E$9)^(YEAR(L7)-YEAR('8. Schedule'!$D$8)) -> 1 | M21: =(1+'11. 10-Yr Cash Flow IRR'!$E$9)^(YEAR(M7)-YEAR('8. Schedule'!$D$8)) -> 1 | N21: =(1+'11. 10-Yr Cash Flow IRR'!$E$9)^(YEAR(N7)-YEAR('8. Schedule'!$D$8)) -> 1 | O21: =(1+'11. 10-Yr Cash Flow IRR'!$E$9)^(YEAR(O7)-YEAR('8. Schedule'!$D$8)) -> 1 | P21: =(1+'11. 10-Yr Cash Flow IRR'!$E$9)^(YEAR(P7)-YEAR('8. Schedule'!$D$8)) -> 1 | Q21: =(1+'11. 10-Yr Cash Flow IRR'!$E$9)^(YEAR(Q7)-YEAR('8. Schedule'!$D$8)) -> 1 | ... CZ21: =(1+'11. 10-Yr Cash Flow IRR'!$E$9)^(YEAR(CZ7)-YEAR('8. Schedule'!$D$8)) -> 1.1716594
B22: Security Deposit | C22: =-'9. Development Costs'!H83 -> 515585.74 | E22: =SUM(I22:CZ22) -> 515585.74 | I22: =+'7. Op Rev and Exp'!$H$20/'7. Op Rev and Exp'!$E$20/12*I12*I20 -> 0 | J22: =+'7. Op Rev and Exp'!$H$20/'7. Op Rev and Exp'!$E$20/12*J12*J20 -> 0 | K22: =+'7. Op Rev and Exp'!$H$20/'7. Op Rev and Exp'!$E$20/12*K12*K20 -> 0 | L22: =+'7. Op Rev and Exp'!$H$20/'7. Op Rev and Exp'!$E$20/12*L12*L20 -> 0 | M22: =+'7. Op Rev and Exp'!$H$20/'7. Op Rev and Exp'!$E$20/12*M12*M20 -> 0 | N22: =+'7. Op Rev and Exp'!$H$20/'7. Op Rev and Exp'!$E$20/12*N12*N20 -> 0 | O22: =+'7. Op Rev and Exp'!$H$20/'7. Op Rev and Exp'!$E$20/12*O12*O20 -> 0 | P22: =+'7. Op Rev and Exp'!$H$20/'7. Op Rev and Exp'!$E$20/12*P12*P20 -> 0 | ... CZ22: =+'7. Op Rev and Exp'!$H$20/'7. Op Rev and Exp'!$E$20/12*CZ12*CZ20 -> 0
B23: Revenue | C23: =-'9. Development Costs'!H84 -> 4175747.3 | D23: =ROUND(C23-E23,0) -> 0 | E23: =SUM(I23:CZ23) -> 4175747.3 | I23: =IF(I110="PUD",'7. Op Rev and Exp'!$H$32/12*I$17*I$20,0) -> 0 | J23: =IF(J110="PUD",'7. Op Rev and Exp'!$H$32/12*J$17*J$20,0) -> 0 | K23: =IF(K110="PUD",'7. Op Rev and Exp'!$H$32/12*K$17*K$20,0) -> 0 | L23: =IF(L110="PUD",'7. Op Rev and Exp'!$H$32/12*L$17*L$20,0) -> 0 | M23: =IF(M110="PUD",'7. Op Rev and Exp'!$H$32/12*M$17*M$20,0) -> 0 | N23: =IF(N110="PUD",'7. Op Rev and Exp'!$H$32/12*N$17*N$20,0) -> 0 | O23: =IF(O110="PUD",'7. Op Rev and Exp'!$H$32/12*O$17*O$20,0) -> 0 | P23: =IF(P110="PUD",'7. Op Rev and Exp'!$H$32/12*P$17*P$20,0) -> 0 | ... CZ23: =IF(CZ110="PUD",'7. Op Rev and Exp'!$H$32/12*CZ$17*CZ$20,0) -> 0
B24: Vacancy Provision | C24: =-'9. Development Costs'!H85 -> -125272.42 | D24: =ROUND(C24-E24,0) -> 0 | E24: =SUM(I24:CZ24) -> -125272.42 | I24: =IF(I110="PUD",-'7. Op Rev and Exp'!$H$33/12*I$17*I$20,0) -> 0 | J24: =IF(J110="PUD",-'7. Op Rev and Exp'!$H$33/12*J$17*J$20,0) -> 0 | K24: =IF(K110="PUD",-'7. Op Rev and Exp'!$H$33/12*K$17*K$20,0) -> 0 | L24: =IF(L110="PUD",-'7. Op Rev and Exp'!$H$33/12*L$17*L$20,0) -> 0 | M24: =IF(M110="PUD",-'7. Op Rev and Exp'!$H$33/12*M$17*M$20,0) -> 0 | N24: =IF(N110="PUD",-'7. Op Rev and Exp'!$H$33/12*N$17*N$20,0) -> 0 | O24: =IF(O110="PUD",-'7. Op Rev and Exp'!$H$33/12*O$17*O$20,0) -> 0 | P24: =IF(P110="PUD",-'7. Op Rev and Exp'!$H$33/12*P$17*P$20,0) -> 0 | ... CZ24: =IF(CZ110="PUD",-'7. Op Rev and Exp'!$H$33/12*CZ$17*CZ$20,0) -> 0
B25: Operating Expenses | C25: =-'9. Development Costs'!H86 -> -1098123.3 | D25: =ROUND(C25-E25,0) -> 0 | E25: =SUM(I25:CZ25) -> -1098123.3 | I25: =IF(I110="PUD",-'7. Op Rev and Exp'!$H$50/12*I$17*I$21,0) -> 0 | J25: =IF(J110="PUD",-'7. Op Rev and Exp'!$H$50/12*J$17*J$21,0) -> 0 | K25: =IF(K110="PUD",-'7. Op Rev and Exp'!$H$50/12*K$17*K$21,0) -> 0 | L25: =IF(L110="PUD",-'7. Op Rev and Exp'!$H$50/12*L$17*L$21,0) -> 0 | M25: =IF(M110="PUD",-'7. Op Rev and Exp'!$H$50/12*M$17*M$21,0) -> 0 | N25: =IF(N110="PUD",-'7. Op Rev and Exp'!$H$50/12*N$17*N$21,0) -> 0 | O25: =IF(O110="PUD",-'7. Op Rev and Exp'!$H$50/12*O$17*O$21,0) -> 0 | P25: =IF(P110="PUD",-'7. Op Rev and Exp'!$H$50/12*P$17*P$21,0) -> 0 | ... CZ25: =IF(CZ110="PUD",-'7. Op Rev and Exp'!$H$50/12*CZ$17*CZ$21,0) -> 0
B26: NOI | C26: =SUM(C23:C25) -> 2952351.5 | E26: =SUM(I26:CZ26)+E21 -> 2952351.5 | I26: =SUM(I23:I25) -> 0 | J26: =SUM(J23:J25) -> 0 | K26: =SUM(K23:K25) -> 0 | L26: =SUM(L23:L25) -> 0 | M26: =SUM(M23:M25) -> 0 | N26: =SUM(N23:N25) -> 0 | O26: =SUM(O23:O25) -> 0 | P26: =SUM(P23:P25) -> 0 | ... CZ26: =SUM(CZ23:CZ25) -> 0
B28: LAND
B29: ='9. Development Costs'!B14 -> Land | C29: =-'9. Development Costs'!H14 -> -9911777.9 | D29: =ROUND(C29-E29,0) -> 0 | E29: =SUM(I29:CZ29) -> -9911777.9 | F29: ='8. Schedule'!D13 -> 46069 | G29: ='8. Schedule'!E13 -> 46069 | H29: =DATEDIF(F29,G29,"m")+1 -> 1 | I29: =IF(AND(I$7<=$G29,I$7>=$F29,$H29<>0,$H29<>""),$C29/$H29,0) -> -9911777.9 | J29: =IF(AND(J$7<=$G29,J$7>=$F29,$H29<>0,$H29<>""),$C29/$H29,0) -> 0 | K29: =IF(AND(K$7<=$G29,K$7>=$F29,$H29<>0,$H29<>""),$C29/$H29,0) -> 0 | L29: =IF(AND(L$7<=$G29,L$7>=$F29,$H29<>0,$H29<>""),$C29/$H29,0) -> 0 | M29: =IF(AND(M$7<=$G29,M$7>=$F29,$H29<>0,$H29<>""),$C29/$H29,0) -> 0 | N29: =IF(AND(N$7<=$G29,N$7>=$F29,$H29<>0,$H29<>""),$C29/$H29,0) -> 0 | O29: =IF(AND(O$7<=$G29,O$7>=$F29,$H29<>0,$H29<>""),$C29/$H29,0) -> 0 | P29: =IF(AND(P$7<=$G29,P$7>=$F29,$H29<>0,$H29<>""),$C29/$H29,0) -> 0 | ... CZ29: =IF(AND(CZ$7<=$G29,CZ$7>=$F29,$H29<>0,$H29<>""),$C29/$H29,0) -> 0
B30: ='9. Development Costs'!B15 -> Closing / Other Cost | C30: =-'9. Development Costs'!H15 -> -495588.89 | D30: =ROUND(C30-E30,0) -> 0 | E30: =SUM(I30:CZ30) -> -495588.89 | F30: =F29 -> 46069 | G30: =G29 -> 46069 | H30: =DATEDIF(F30,G30,"m")+1 -> 1 | I30: =IF(AND(I$7<=$G30,I$7>=$F30,$H30<>0,$H30<>""),$C30/$H30,0) -> -495588.89 | J30: =IF(AND(J$7<=$G30,J$7>=$F30,$H30<>0,$H30<>""),$C30/$H30,0) -> 0 | K30: =IF(AND(K$7<=$G30,K$7>=$F30,$H30<>0,$H30<>""),$C30/$H30,0) -> 0 | L30: =IF(AND(L$7<=$G30,L$7>=$F30,$H30<>0,$H30<>""),$C30/$H30,0) -> 0 | M30: =IF(AND(M$7<=$G30,M$7>=$F30,$H30<>0,$H30<>""),$C30/$H30,0) -> 0 | N30: =IF(AND(N$7<=$G30,N$7>=$F30,$H30<>0,$H30<>""),$C30/$H30,0) -> 0 | O30: =IF(AND(O$7<=$G30,O$7>=$F30,$H30<>0,$H30<>""),$C30/$H30,0) -> 0 | P30: =IF(AND(P$7<=$G30,P$7>=$F30,$H30<>0,$H30<>""),$C30/$H30,0) -> 0 | ... CZ30: =IF(AND(CZ$7<=$G30,CZ$7>=$F30,$H30<>0,$H30<>""),$C30/$H30,0) -> 0
B31: ='9. Development Costs'!B16 -> Total Land Costs | C31: =-'9. Development Costs'!H16 -> -10407367 | D31: =C31-E31 -> 0 | E31: =SUM(I31:CZ31) -> -10407367 | I31: =SUM(I29:I30) -> -10407367 | J31: =SUM(J29:J30) -> 0 | K31: =SUM(K29:K30) -> 0 | L31: =SUM(L29:L30) -> 0 | M31: =SUM(M29:M30) -> 0 | N31: =SUM(N29:N30) -> 0 | O31: =SUM(O29:O30) -> 0 | P31: =SUM(P29:P30) -> 0 | ... CZ31: =SUM(CZ29:CZ30) -> 0
B33: CONSTRUCTION
A34: Steep | B34: S Curve Option:
A35: Moderately Steep | B35: 2 | C35: S-curve StDev: | D35: =H36/B35 -> 9.5
A36: Moderate | B36: S Curve Distribution | C36: 1 | D36: =C36-E36 -> 0 | E36: =SUM(I36:CZ36) -> 1 | F36: =F41 -> 46493 | G36: =G41 -> 47042 | H36: =DATEDIF(F36,G36,"m")+1 -> 19 | I36: =IF(AND(I$7>=$F36,I$7<=$G36),(_xlfn.NORM.DIST((YEAR(I$7)-YEAR($F36))*12+MONTH(I$7)-MONTH($F36)+1,$H36/2,$D35,TRUE)-_xlfn.NORM.DIST((YEAR(I$7)-YEAR($F36))*12+MONTH(I$7)-MONTH($F36),$H36/2,$D35,TRUE))/(1-2*_xlfn.NORM.DIST(0,$H36/2,$D35,TRUE))*$C36,0) -> 0 | J36: =IF(AND(J$7>=$F36,J$7<=$G36),(_xlfn.NORM.DIST((YEAR(J$7)-YEAR($F36))*12+MONTH(J$7)-MONTH($F36)+1,$H36/2,$D35,TRUE)-_xlfn.NORM.DIST((YEAR(J$7)-YEAR($F36))*12+MONTH(J$7)-MONTH($F36),$H36/2,$D35,TRUE))/(1-2*_xlfn.NORM.DIST(0,$H36/2,$D35,TRUE))*$C36,0) -> 0 | K36: =IF(AND(K$7>=$F36,K$7<=$G36),(_xlfn.NORM.DIST((YEAR(K$7)-YEAR($F36))*12+MONTH(K$7)-MONTH($F36)+1,$H36/2,$D35,TRUE)-_xlfn.NORM.DIST((YEAR(K$7)-YEAR($F36))*12+MONTH(K$7)-MONTH($F36),$H36/2,$D35,TRUE))/(1-2*_xlfn.NORM.DIST(0,$H36/2,$D35,TRUE))*$C36,0) -> 0 | L36: =IF(AND(L$7>=$F36,L$7<=$G36),(_xlfn.NORM.DIST((YEAR(L$7)-YEAR($F36))*12+MONTH(L$7)-MONTH($F36)+1,$H36/2,$D35,TRUE)-_xlfn.NORM.DIST((YEAR(L$7)-YEAR($F36))*12+MONTH(L$7)-MONTH($F36),$H36/2,$D35,TRUE))/(1-2*_xlfn.NORM.DIST(0,$H36/2,$D35,TRUE))*$C36,0) -> 0 | M36: =IF(AND(M$7>=$F36,M$7<=$G36),(_xlfn.NORM.DIST((YEAR(M$7)-YEAR($F36))*12+MONTH(M$7)-MONTH($F36)+1,$H36/2,$D35,TRUE)-_xlfn.NORM.DIST((YEAR(M$7)-YEAR($F36))*12+MONTH(M$7)-MONTH($F36),$H36/2,$D35,TRUE))/(1-2*_xlfn.NORM.DIST(0,$H36/2,$D35,TRUE))*$C36,0) -> 0 | N36: =IF(AND(N$7>=$F36,N$7<=$G36),(_xlfn.NORM.DIST((YEAR(N$7)-YEAR($F36))*12+MONTH(N$7)-MONTH($F36)+1,$H36/2,$D35,TRUE)-_xlfn.NORM.DIST((YEAR(N$7)-YEAR($F36))*12+MONTH(N$7)-MONTH($F36),$H36/2,$D35,TRUE))/(1-2*_xlfn.NORM.DIST(0,$H36/2,$D35,TRUE))*$C36,0) -> 0 | O36: =IF(AND(O$7>=$F36,O$7<=$G36),(_xlfn.NORM.DIST((YEAR(O$7)-YEAR($F36))*12+MONTH(O$7)-MONTH($F36)+1,$H36/2,$D35,TRUE)-_xlfn.NORM.DIST((YEAR(O$7)-YEAR($F36))*12+MONTH(O$7)-MONTH($F36),$H36/2,$D35,TRUE))/(1-2*_xlfn.NORM.DIST(0,$H36/2,$D35,TRUE))*$C36,0) -> 0 | P36: =IF(AND(P$7>=$F36,P$7<=$G36),(_xlfn.NORM.DIST((YEAR(P$7)-YEAR($F36))*12+MONTH(P$7)-MONTH($F36)+1,$H36/2,$D35,TRUE)-_xlfn.NORM.DIST((YEAR(P$7)-YEAR($F36))*12+MONTH(P$7)-MONTH($F36),$H36/2,$D35,TRUE))/(1-2*_xlfn.NORM.DIST(0,$H36/2,$D35,TRUE))*$C36,0) -> 0 | ... CZ36: =IF(AND(CZ$7>=$F36,CZ$7<=$G36),(_xlfn.NORM.DIST((YEAR(CZ$7)-YEAR($F36))*12+MONTH(CZ$7)-MONTH($F36)+1,$H36/2,$D35,TRUE)-_xlfn.NORM.DIST((YEAR(CZ$7)-YEAR($F36))*12+MONTH(CZ$7)-MONTH($F36),$H36/2,$D35,TRUE))/(1-2*_xlfn.NORM.DIST(0,$H36/2,$D35,TRUE))*$C36,0) -> 0
A37: Moderately Flat | B37: Even Distribution | C37: 1 | D37: =C37-E37 -> 0 | E37: =SUM(I37:CZ37) -> 1 | F37: =F41 -> 46493 | G37: =G41 -> 47042 | H37: =DATEDIF(F37,G37,"m")+1 -> 19 | I37: =IF(AND(I$7<=$G37,I$7>=$F37,$H37<>0,$H37<>""),$C37/$H37,0) -> 0 | J37: =IF(AND(J$7<=$G37,J$7>=$F37,$H37<>0,$H37<>""),$C37/$H37,0) -> 0 | K37: =IF(AND(K$7<=$G37,K$7>=$F37,$H37<>0,$H37<>""),$C37/$H37,0) -> 0 | L37: =IF(AND(L$7<=$G37,L$7>=$F37,$H37<>0,$H37<>""),$C37/$H37,0) -> 0 | M37: =IF(AND(M$7<=$G37,M$7>=$F37,$H37<>0,$H37<>""),$C37/$H37,0) -> 0 | N37: =IF(AND(N$7<=$G37,N$7>=$F37,$H37<>0,$H37<>""),$C37/$H37,0) -> 0 | O37: =IF(AND(O$7<=$G37,O$7>=$F37,$H37<>0,$H37<>""),$C37/$H37,0) -> 0 | P37: =IF(AND(P$7<=$G37,P$7>=$F37,$H37<>0,$H37<>""),$C37/$H37,0) -> 0 | ... CZ37: =IF(AND(CZ$7<=$G37,CZ$7>=$F37,$H37<>0,$H37<>""),$C37/$H37,0) -> 0
B38: Construction Cost Option:
B39: 1
B40: Construction % Completion | I40: =CHOOSE($B$39,I36,I37) -> 0 | J40: =CHOOSE($B$39,J36,J37)+I40 -> 0 | K40: =CHOOSE($B$39,K36,K37)+J40 -> 0 | L40: =CHOOSE($B$39,L36,L37)+K40 -> 0 | M40: =CHOOSE($B$39,M36,M37)+L40 -> 0 | N40: =CHOOSE($B$39,N36,N37)+M40 -> 0 | O40: =CHOOSE($B$39,O36,O37)+N40 -> 0 | P40: =CHOOSE($B$39,P36,P37)+O40 -> 0 | Q40: =CHOOSE($B$39,Q36,Q37)+P40 -> 0 | ... CZ40: =CHOOSE($B$39,CZ36,CZ37)+CY40 -> 1
B41: ='9. Development Costs'!B19 -> Construction hard cost | C41: =-'9. Development Costs'!H19 -> -64395800 | D41: =ROUND(C41-E41,0) -> 0 | E41: =SUM(I41:CZ41) -> -64395800 | F41: ='8. Schedule'!D17 -> 46493 | G41: ='8. Schedule'!E17 -> 47042 | H41: =DATEDIF(F41,G41,"m")+1 -> 19 | I41: =I40*$C$41 -> 0 | J41: =(J40-I40)*$C$41 -> 0 | K41: =(K40-J40)*$C$41 -> 0 | L41: =(L40-K40)*$C$41 -> 0 | M41: =(M40-L40)*$C$41 -> 0 | N41: =(N40-M40)*$C$41 -> 0 | O41: =(O40-N40)*$C$41 -> 0 | P41: =(P40-O40)*$C$41 -> 0 | Q41: =(Q40-P40)*$C$41 -> 0 | ... CZ41: =(CZ40-CY40)*$C$41 -> 0
