Workbook

Sheet DevCon Pres Tbl
B3: Sensitivity Analysis of a Res Development Project
B4: Development Summary
B6: Scenario | C6: Area Sq Ft | D6: Unit | E6: NOI Now | I6: NOI Stabilized | N6: Sale Proceeds | O6: Development Costs | V6: Profit Before | X6: Return on | Y6: Development | Z6: IRR if | AA6: IRR
E7: Res Rent/SF | F7: Revenue | G7: Op Costs | H7: NOI | I7: Res Rent/SF | J7: Revenue | K7: Op Exp | L7: NOI | N7: (Value-sale costs) | O7: Land | P7: Construction | Q7: Soft Costs | R7: HST | S7: Financing | T7: Ops NOI | U7: Net Dev Costs | V7: Tax | X7: Cost | Y7: Yield | Z7: Sold on Stab | AA7: 10 Year
B9: Running Model | C9: =+'Executive Summary'!E34 -> 85975 | D9: =+'Executive Summary'!F34 -> 100 | E9: =+'Operating Revenue and Expenses'!J19 -> 2.6246002 | F9: =+'Operating Revenue and Expenses'!I29 -> 2834325 | G9: =+'Operating Revenue and Expenses'!I43 -> 765110 | H9: =+F9-G9 -> 2069215 | I9: =+E9/H9*L9 -> 3.8151156 | J9: =MAX('Development Cash Flow'!I23:CZ23)*12*0.975 -> 3007808.4 | K9: ='Development Cash Flow'!BT25*12 -> 0 | L9: =+J9+K9 -> 3007808.4 | N9: =(+L9/0.04)*0.99 -> 74443257 | O9: =+'Executive Summary'!G39 -> 5989000 | P9: =+'Executive Summary'!G40 -> 30000000 | Q9: =SUM('Executive Summary'!G41:G44) -> 6743750 | R9: =+'Executive Summary'!G46 -> 3820151.5 | S9: =+'Executive Summary'!G45 -> 3714932.5 | T9: =+'Executive Summary'!G47 -> -1080051.6 | U9: =SUM(O9:T9) -> 49187782 | V9: =+N9-U9 -> 25255475 | X9: =+V9/U9 -> 0.51345016 | Y9: =L9/U9 -> 0.061149501 | Z9: =+Cover!G39 -> 0.25094511 | AA9: =+Cover!G40 -> 0.13515738
B11: Base | C11: 81675 | D11: 100 | E11: 2.5414141 | F11: 2659644 | G11: 694735.2 | H11: 1964908.8 | I11: 3.6505396 | J11: 2822435.5 | K11: 0 | L11: 2822435.5 | N11: 69855278 | O11: 5700000 | P11: 26500000 | Q11: 5396560 | R11: 2236939.7 | S11: 2217278.5 | T11: -735677.33 | U11: 41315101 | V11: 28540178 | X11: 0.69079288 | Y11: 0.068314864 | Z11: 0.24825976 | AA11: 0.16138068
C12: =+C9-C11 -> 4300 | D12: =+D9-D11 -> 0 | E12: =+E9-E11 -> 0.083186033 | F12: =+F9-F11 -> 174681 | G12: =+G9-G11 -> 70374.8 | H12: =+H9-H11 -> 104306.2 | I12: =+I9-I11 -> 0.16457593 | J12: =+J9-J11 -> 185372.87 | ... L12: =+L9-L11 -> 185372.87 | N12: =+N9-N11 -> 4587978.6 | O12: =+O9-O11 -> 289000 | P12: =+P9-P11 -> 3500000 | Q12: =+Q9-Q11 -> 1347190 | R12: =+R9-R11 -> 1583211.8 | S12: =+S9-S11 -> 1497654.1 | T12: =+T9-T11 -> -344374.3 | U12: =+U9-U11 -> 7872681.6 | V12: =+V9-V11 -> -3284702.9 | X12: =+X9-X11 -> -0.17734272 | Y12: =+Y9-Y11 -> -0.0071653626 | Z12: =+Z9-Z11 -> 0.0026853473 | AA12: =+AA9-AA11 -> -0.026223309
B13: Sensitivity
B14: Revenue + 5% | C14: 81675 | D14: 100 | E14: 2.5414141 | F14: 2659644 | G14: 694735.2 | H14: 1964908.8 | I14: 3.6505396 | J14: 2822435.5 | K14: 0 | L14: 2822435.5 | N14: 69855278 | O14: 5700000 | P14: 26500000 | Q14: 5396560 | R14: 2236939.7 | S14: 2217278.5 | T14: -735677.33 | U14: 41315101 | V14: 28540178 | X14: 0.69079288 | Y14: 0.068314864 | Z14: 0.24825976 | AA14: 0.16138068
B15: Variance | C15: =(+C14-$C$11)/$C$11 -> 0 | D15: =(+D14-$D$11)/$D$11 -> 0 | E15: =(+E14-$E$11)/$E$11 -> 0 | F15: =(+F14-$F$11)/$F$11 -> 0 | G15: =(+G14-$G$11)/$G$11 -> 0 | H15: =(+H14-$H$11)/$H$11 -> 0 | I15: =(+I14-$I$11)/$I$11 -> 0 | J15: =(+J14-$J$11)/$J$11 -> 0 | K15: =(+K14-$K$11)/$K$11 -> #DIV/0! | L15: =(+L14-$L$11)/$L$11 -> 0 | N15: =(+N14-$N$11)/$N$11 -> 0 | O15: =(+O14-$O$11)/$O$11 -> 0 | P15: =(+P14-$P$11)/$P$11 -> 0 | Q15: =(+Q14-$Q$11)/$Q$11 -> 0 | R15: =(+R14-$R$11)/$R$11 -> 0 | S15: =(+S14-$S$11)/$S$11 -> 0 | T15: =(+T14-$T$11)/$T$11 -> 0 | U15: =(+U14-$U$11)/$U$11 -> 0 | V15: =(+V14-$V$11)/$V$11 -> 0 | X15: =+X14-$X$11 -> 0 | Y15: =+Y14-$Y$11 -> 0 | Z15: =+Z14-$Z$11 -> 0 | AA15: =+AA14-$AA$11 -> 0
B16: Dollar Profit Uplift | V16: =+V14-$V$11 -> 0
B18: Operating Cost -5% | C18: 81675 | D18: 100 | E18: 2.5414141 | F18: 2659644 | G18: 694735.2 | H18: 1964908.8 | I18: 3.6505396 | J18: 2822435.5 | K18: 0 | L18: 2822435.5 | N18: 69855278 | O18: 5700000 | P18: 26500000 | Q18: 5396560 | R18: 2236939.7 | S18: 2217278.5 | T18: -735677.33 | U18: 41315101 | V18: 28540178 | X18: 0.69079288 | Y18: 0.068314864 | Z18: 0.24825976 | AA18: 0.16138068
B19: Variance | C19: =(+C18-$C$11)/$C$11 -> 0 | D19: =(+D18-$D$11)/$D$11 -> 0 | E19: =(+E18-$E$11)/$E$11 -> 0 | F19: =(+F18-$F$11)/$F$11 -> 0 | G19: =(+G18-$G$11)/$G$11 -> 0 | H19: =(+H18-$H$11)/$H$11 -> 0 | I19: =(+I18-$I$11)/$I$11 -> 0 | J19: =(+J18-$J$11)/$J$11 -> 0 | K19: =(+K18-$K$11)/$K$11 -> #DIV/0! | L19: =(+L18-$L$11)/$L$11 -> 0 | N19: =(+N18-$N$11)/$N$11 -> 0 | O19: =(+O18-$O$11)/$O$11 -> 0 | P19: =(+P18-$P$11)/$P$11 -> 0 | Q19: =(+Q18-$Q$11)/$Q$11 -> 0 | R19: =(+R18-$R$11)/$R$11 -> 0 | S19: =(+S18-$S$11)/$S$11 -> 0 | T19: =(+T18-$T$11)/$T$11 -> 0 | U19: =(+U18-$U$11)/$U$11 -> 0 | V19: =(+V18-$V$11)/$V$11 -> 0 | X19: =+X18-$X$11 -> 0 | Y19: =+Y18-$Y$11 -> 0 | Z19: =+Z18-$Z$11 -> 0 | AA19: =+AA18-$AA$11 -> 0
B20: Dollar Profit Uplift | V20: =+V18-$V$11 -> 0
B22: Construction Cost - 5% | C22: 81675 | D22: 100 | E22: 2.5414141 | F22: 2659644 | G22: 694735.2 | H22: 1964908.8 | I22: 3.6505396 | J22: 2822435.5 | K22: 0 | L22: 2822435.5 | N22: 69855278 | O22: 5700000 | P22: 26500000 | Q22: 5396560 | R22: 2236939.7 | S22: 2217278.5 | T22: -735677.33 | U22: 41315101 | V22: 28540178 | X22: 0.69079288 | Y22: 0.068314864 | Z22: 0.24825976 | AA22: 0.16138068
B23: Variance | C23: =(+C22-$C$11)/$C$11 -> 0 | D23: =(+D22-$D$11)/$D$11 -> 0 | E23: =(+E22-$E$11)/$E$11 -> 0 | F23: =(+F22-$F$11)/$F$11 -> 0 | G23: =(+G22-$G$11)/$G$11 -> 0 | H23: =(+H22-$H$11)/$H$11 -> 0 | I23: =(+I22-$I$11)/$I$11 -> 0 | J23: =(+J22-$J$11)/$J$11 -> 0 | K23: =(+K22-$K$11)/$K$11 -> #DIV/0! | L23: =(+L22-$L$11)/$L$11 -> 0 | N23: =(+N22-$N$11)/$N$11 -> 0 | O23: =(+O22-$O$11)/$O$11 -> 0 | P23: =(+P22-$P$11)/$P$11 -> 0 | Q23: =(+Q22-$Q$11)/$Q$11 -> 0 | R23: =(+R22-$R$11)/$R$11 -> 0 | S23: =(+S22-$S$11)/$S$11 -> 0 | T23: =(+T22-$T$11)/$T$11 -> 0 | U23: =(+U22-$U$11)/$U$11 -> 0 | V23: =(+V22-$V$11)/$V$11 -> 0 | X23: =+X22-$X$11 -> 0 | Y23: =+Y22-$Y$11 -> 0 | Z23: =+Z22-$Z$11 -> 0 | AA23: =+AA22-$AA$11 -> 0
B24: Dollar Profit Uplift | V24: =+V22-$V$11 -> 0

Sheet Sensitiv2
B4: Sensitize
B6: Res Rent | D6: 1
B8: Operating Cost | D8: 1
B10: Construction Cost | D10: 1

Sheet Cover (2)
A5: =TODAY() -> 44642
A10: Apartment Development Model
A12: Suburban Highrise Project in Ontario
A14: ='Executive Summary'!F34&" Units" -> 100 Units
A17: Apartment Pro-forma
A20: Prepared by:
A22: SVN Rock Advisors Inc.
C24: HEADLINE NUMBERS
G26: Modified Base | I26: Base Case | K26: Variance
C28: NOI at stabilization | G28: ='Executive Summary'!H9 -> 2195867.5 | I28: 2195867.5 | K28: =+G28-I28 -> 0
C29: Capitalization Rate | G29: ='Executive Summary'!H10 -> 0.04 | I29: 0.04 | K29: =+G29-I29 -> 0
C30: Valuation | D30: @ | E30: ='Executive Summary'!D11 -> 2.9901441 | F30: per sqft avg revenue | G30: ='Executive Summary'!H11 -> 54896688 | I30: 54896688 | K30: =+G30-I30 -> 0
C31: Less: Selling costs | G31: ='Executive Summary'!H12 -> -548966.88 | I31: -548966.88 | K31: =+G31-I31 -> 0
C32: Sales Proceeds | G32: ='Executive Summary'!H13 -> 54347721 | I32: 54347721 | K32: =+G32-I32 -> 0
C33: Total Cost | G33: ='Executive Summary'!H14 -> -49187782 | I33: -49187782 | K33: =+G33-I33 -> 0
C34: Profit before taxes if sold at stabilization | G34: ='Executive Summary'!H15 -> 5159938.5 | I34: 5159938.5 | K34: =+G34-I34 -> 0
C36: Return on cost | G36: ='Executive Summary'!H17 -> 0.10490285 | I36: 0.10490285 | K36: =+G36-I36 -> 0
C37: Development Yield | G37: =G28/(-G33) -> 0.044642539 | I37: 0.044642539 | K37: =+G37-I37 -> 0
C39: IRR upon stabilization if sold | G39: ='Executive Summary'!H18 -> 0.25094511 | I39: 0.25094511 | K39: =+G39-I39 -> 0
C40: ="IRR "&'10-Yr Cash Flow IRR'!A66&"-Year" -> IRR 10-Year | G40: ='Executive Summary'!H19 -> 0.13515738 | I40: 0.13515738 | K40: =+G40-I40 -> 0
C42: Construction Costs per unit | G42: ='Development Costs'!I89 -> 491877.82 | I42: 491877.82 | K42: =+G42-I42 -> 0
C43: Construction Costs per sqft | G43: ='Development Costs'!J89 -> 572.11727 | I43: 572.11727 | K43: =+G43-I43 -> 0
C44: Value per unit at stabilization | G44: =G30/'Operating Revenue and Expenses'!F19 -> 548966.88 | I44: 548966.88 | K44: =+G44-I44 -> 0
C45: Value per sqft at stabilization | G45: =G30/'Development Costs'!I10 -> 638.5192 | I45: 638.5192 | K45: =+G45-I45 -> 0
A48: Disclaimer: RE: Use of the New Apartment Construction Financial Model
A49: SVN Rock Advisors Inc. Brokerage, Derek A. Lobo & Associates (DALA) and/or SVN Canada Inc. (herein described as "the Consultant") has developed the New Apartment Construction Financial Model (herein described as "the model") as a general guide to help a user understand the high level profitability of rental apartment construction development on a given site. The Model is developed in Microsoft Excel, and it is expected by the consultant, that the user of the model is proficient in Excel. Any accidental deletion of a cell may corrupt the entire file and/or show inaccurate results that the Consultant is not responsible for. The model is intended to provide a high level understanding of the profitability, and does not assure and/or guarantee success of a project in any way.
A50: Confidentiality Policy
A51: Intellecutal rights on this file remain with the Consultant
A52: Disclaimers:
A53: We make no guarantees and do not undertake to confirm independently that the information, result and or data provided is accurate or comprehensive. We recommend the client independently review data sources and periodically update and confirm the data used in the excel file.
A54: The consultant's principals, management, staff, contractors and associates are real estate consultants only.
A55: The Consultant makes no guarantees, written or otherwise, that if the client adopts or acts on the excel model's observations, findings, analysis or recommendations in the report that the client's project will be successful, nor do we, as real estate consultants, accept any legal or financial responsibility or liability for failure, under-performance, or termination of the client's project.
A56: Limitation of Liability:
A57: To the fullest extent permitted by applicable law, in no event shall the consultant be liable to the client or any other user for any direct, indirect, incidental, special, punitive, or consequential damages whatsoever resulting from any (i) use of the excel file, (ii) errors, mistakes, or inaccuracies of content, (iii) any bugs, viruses, or like, which may be transmitted to or through the excel file to or by any party, (iv) any loss of your data or content, (v) any errors or omissions in any content or for any loss or damage of any kind incurred as a result of your use of the file, whether based on warranty, contract, tort, or any other legal theory, and whether or not the client/users are advised of the possibility of such damanges, and/or (vi) the disclosure of information pursuant to these terms of use or a privacy policy.
A58: Despite the above, our total liability to you for any cause of action you take against us will at all times be limited to no more than $100/ - (one hundred dollars)

Sheet Cover
A5: =TODAY() -> 44642
A10: Apartment Development Model
A12: Suburban / Urban Location
A14: ='Executive Summary'!F34&" Units" -> 100 Units
A17: Apartment Pro-forma
A20: Prepared by:
A22: SVN Rock Advisors Inc.
C26: HEADLINE NUMBERS
C28: NOI at stabilization | G28: ='Executive Summary'!H9 -> 2195867.5
C29: Capitalization Rate | G29: ='Executive Summary'!H10 -> 0.04
C30: Valuation | D30: @ | E30: ='Executive Summary'!D11 -> 2.9901441 | F30: per sqft avg revenue | G30: ='Executive Summary'!H11 -> 54896688
C31: Less: Selling costs | G31: ='Executive Summary'!H12 -> -548966.88
C32: Sales Proceeds | G32: ='Executive Summary'!H13 -> 54347721
C33: Total Cost | G33: ='Executive Summary'!H14 -> -49187782
C34: Profit before taxes if sold at stabilization | G34: ='Executive Summary'!H15 -> 5159938.5
C36: Return on cost | G36: ='Executive Summary'!H17 -> 0.10490285
C37: Development Yield | G37: =G28/(-G33) -> 0.044642539
C39: IRR upon stabilization if sold | G39: ='Executive Summary'!H18 -> 0.25094511
C40: ="IRR "&'10-Yr Cash Flow IRR'!A66&"-Year" -> IRR 10-Year | G40: ='Executive Summary'!H19 -> 0.13515738
C42: Construction Costs per unit | G42: ='Development Costs'!I89 -> 491877.82
C43: Construction Costs per sqft | G43: ='Development Costs'!J89 -> 572.11727
C44: Value per unit at stabilization | G44: =G30/'Operating Revenue and Expenses'!F19 -> 548966.88
C45: Value per sqft at stabilization | G45: =G30/'Development Costs'!I10 -> 638.5192
A48: Disclaimer: RE: Use of the New Apartment Construction Financial Model
A49: SVN Rock Advisors Inc. Brokerage, Derek A. Lobo & Associates (DALA) and/or SVN Canada Inc. (herein described as "the Consultant") has developed the New Apartment Construction Financial Model (herein described as "the model") as a general guide to help a user understand the high level profitability of rental apartment construction development on a given site. The Model is developed in Microsoft Excel, and it is expected by the consultant, that the user of the model is proficient in Excel. Any accidental deletion of a cell may corrupt the entire file and/or show inaccurate results that the Consultant is not responsible for. The model is intended to provide a high level understanding of the profitability, and does not assure and/or guarantee success of a project in any way.
A50: Confidentiality Policy
A51: Intellecutal rights on this file remain with the Consultant
A52: Disclaimers:
A53: We make no guarantees and do not undertake to confirm independently that the information, result and or data provided is accurate or comprehensive. We recommend the client independently review data sources and periodically update and confirm the data used in the excel file.
A54: The consultant's principals, management, staff, contractors and associates are real estate consultants only.
A55: The Consultant makes no guarantees, written or otherwise, that if the client adopts or acts on the excel model's observations, findings, analysis or recommendations in the report that the client's project will be successful, nor do we, as real estate consultants, accept any legal or financial responsibility or liability for failure, under-performance, or termination of the client's project.
A56: Limitation of Liability:
A57: To the fullest extent permitted by applicable law, in no event shall the consultant be liable to the client or any other user for any direct, indirect, incidental, special, punitive, or consequential damages whatsoever resulting from any (i) use of the excel file, (ii) errors, mistakes, or inaccuracies of content, (iii) any bugs, viruses, or like, which may be transmitted to or through the excel file to or by any party, (iv) any loss of your data or content, (v) any errors or omissions in any content or for any loss or damage of any kind incurred as a result of your use of the file, whether based on warranty, contract, tort, or any other legal theory, and whether or not the client/users are advised of the possibility of such damanges, and/or (vi) the disclosure of information pursuant to these terms of use or a privacy policy.
A58: Despite the above, our total liability to you for any cause of action you take against us will at all times be limited to no more than $100/ - (one hundred dollars)

Sheet Executive Summary
J1: ="Currently running: "&CHOOSE(Sensitivity!$E$8,Sensitivity!$B$11,Sensitivity!$B$12,Sensitivity!$B$13) -> Currently running: Base Case
B3: =Cover!A10 -> Apartment Development Model
B4: =Cover!A12 -> Suburban / Urban Location
B5: Executive Summary
A8: OVERVIEW
B9: Net Operating Income @ Stabilization | G9: =H9 -> 2195867.5 | H9: ='Operating Revenue and Expenses'!I52 -> 2195867.5 | I9: =H9 -> 2195867.5
B10: Capitalization Rate | G10: =Sensitivity!H13 -> 0.0425 | H10: =Sensitivity!H10 -> 0.04 | I10: =Sensitivity!H12 -> 0.0375
B11: Valuation @ | D11: ='Operating Revenue and Expenses'!E52 -> 2.9901441 | E11: per sqft average revenue | G11: =G9/G10 -> 51667471 | H11: =H9/H10 -> 54896688 | I11: =I9/I10 -> 58556467
B12: Selling costs @ | D12: ='10-Yr Cash Flow IRR'!E11 -> 0.01 | G12: =-'10-Yr Cash Flow IRR'!$E$11*'Executive Summary'!G11 -> -516674.71 | H12: =-'10-Yr Cash Flow IRR'!$E$11*'Executive Summary'!H11 -> -548966.88 | I12: =-'10-Yr Cash Flow IRR'!$E$11*'Executive Summary'!I11 -> -585564.67
B13: Sales Proceeds | G13: =SUM(G11:G12) -> 51150796 | H13: =SUM(H11:H12) -> 54347721 | I13: =SUM(I11:I12) -> 57970902
B14: Total Costs | G14: =H14 -> -49187782 | H14: =-G48 -> -49187782 | I14: =H14 -> -49187782
B15: Profit before taxes if sold | G15: =SUM(G13:G14) -> 1963013.7 | H15: =SUM(H13:H14) -> 5159938.5 | I15: =SUM(I13:I14) -> 8783119.9
B17: Return on Cost | G17: =-G15/G14 -> 0.039908564 | H17: =-H15/H14 -> 0.10490285 | I17: =-I15/I14 -> 0.17856304
B18: IRR upon stabilization if sold | H18: ='Development Cash Flow'!G106 -> 0.25094511
B19: ="IRR "&'10-Yr Cash Flow IRR'!A66&"-Year" -> IRR 10-Year | H19: ='10-Yr Cash Flow IRR'!B67 -> 0.13515738
A21: SCHEDULE
G22: From | H22: To | I22: Months
B23: Land Purchase | G23: =Schedule!D13 -> 44562 | H23: =Schedule!E13 -> 44562 | I23: =Schedule!C13 -> 0
B24: Pre-Development | G24: =Schedule!D15 -> 44593 | H24: =Schedule!E15 -> 44958 | I24: =Schedule!C15 -> 12
B25: Construction period | G25: =Schedule!D17 -> 44986 | H25: =Schedule!E17 -> 45536 | I25: =Schedule!C17 -> 18
B26: Lease-up | G26: =Schedule!D19 -> 45474 | H26: =Schedule!E19 -> 45658 | I26: =Schedule!C19 -> 6
B27: Stabilized | G27: =Schedule!D21 -> 45689 | H27: =Schedule!E21 -> 45689 | I27: =Schedule!C21 -> 0
A29: UNIT MIX
B30: Unit Type | E30: Sq. Ft. | F30: No. Units | G30: % of Total | H30: Rent | I30: $/SF
B31: ='Operating Revenue and Expenses'!B16 -> 1 Bed | E31: ='Operating Revenue and Expenses'!E16 -> 25200 | F31: ='Operating Revenue and Expenses'!F16 -> 35 | G31: ='Operating Revenue and Expenses'!G16 -> 0.35 | H31: ='Operating Revenue and Expenses'!H16 -> 1990 | I31: ='Operating Revenue and Expenses'!J16 -> 2.7638889
B32: ='Operating Revenue and Expenses'!B17 -> 2 Bed | E32: ='Operating Revenue and Expenses'!E17 -> 60775 | F32: ='Operating Revenue and Expenses'!F17 -> 65 | G32: ='Operating Revenue and Expenses'!G17 -> 0.65 | H32: ='Operating Revenue and Expenses'!H17 -> 2400 | I32: ='Operating Revenue and Expenses'!J17 -> 2.5668449
B33: Res 2B part | E33: ='Operating Revenue and Expenses'!E18 -> 0 | F33: =+'Operating Revenue and Expenses'!F18 -> 0 | G33: ='Operating Revenue and Expenses'!G18 -> 0 | H33: ='Operating Revenue and Expenses'!H18 -> 0 | I33: ='Operating Revenue and Expenses'!J18 -> 0
B34: Total Res Units | E34: ='Operating Revenue and Expenses'!E19 -> 85975 | F34: ='Operating Revenue and Expenses'!F19 -> 100 | G34: ='Operating Revenue and Expenses'!G19 -> 1 | H34: ='Operating Revenue and Expenses'!H19 -> 2256.5 | I34: =+H34/E35 -> 2.6246002
B35: Average Res | E35: ='Operating Revenue and Expenses'!E20 -> 859.75 | H35: ='Operating Revenue and Expenses'!H20 -> 2256.5 | I35: ='Operating Revenue and Expenses'!J20 -> 2.6246002
A37: DEVELOPMENT COSTS
G38: Total | H38: Per Res unit | I38: Per Sqft | J38: %
B39: Land | G39: ='Development Costs'!H16 -> 5989000 | H39: ='Development Costs'!I16 -> 59890 | I39: ='Development Costs'!J16 -> 69.659785 | J39: =G39/$G$48 -> 0.12175788
B40: Construction | G40: ='Development Costs'!H22 -> 30000000 | H40: ='Development Costs'!I22 -> 419780 | I40: ='Development Costs'!J22 -> 348.93864 | J40: =G40/$G$48 -> 0.60990755
B41: Professional Fees | G41: ='Development Costs'!H41 -> 1419000 | H41: ='Development Costs'!I41 -> 14190 | I41: ='Development Costs'!J41 -> 16.504798 | J41: =G41/$G$48 -> 0.028848627
B42: Development Management | G42: ='Development Costs'!H46 -> 1254000 | H42: ='Development Costs'!I46 -> 12540 | I42: ='Development Costs'!J46 -> 14.585635 | J42: =G42/$G$48 -> 0.025494136
B43: Permits and Approvals | G43: ='Development Costs'!H59 -> 3344000 | H43: ='Development Costs'!I59 -> 33440 | I43: ='Development Costs'!J59 -> 38.895028 | J43: =G43/$G$48 -> 0.067984362
B44: Marketing and Leasing | G44: ='Development Costs'!H66 -> 726750 | H44: ='Development Costs'!I66 -> 7267.5 | I44: ='Development Costs'!J66 -> 8.4530387 | J44: =G44/$G$48 -> 0.01477501
B45: Financing and Interest | G45: ='Development Costs'!H80-'Development Costs'!H77 -> 3714932.5 | H45: ='Development Costs'!I80 -> 75350.84 | I45: ='Development Costs'!J80 -> 87.642734 | J45: =G45/$G$48 -> 0.075525513
B46: Taxes, HST, VAT | G46: ='Development Costs'!H77 -> 3820151.5 | H46: ='Development Costs'!I77 -> 38201.515 | I46: ='Development Costs'!J77 -> 44.433283 | J46: =G46/$G$48 -> 0.077664642
B47: Operating income during lease-up incl Sec Deposit | G47: ='Development Costs'!H87 -> -1080051.6 | H47: ='Development Costs'!I87 -> -10800.516 | I47: ='Development Costs'!J87 -> -12.562392 | J47: =G47/$G$48 -> -0.021957722
...

Sheet Schedule
BP1: ="Currently running: "&CHOOSE(Sensitivity!$E$8,Sensitivity!$B$11,Sensitivity!$B$12,Sensitivity!$B$13) -> Currently running: Base Case
B3: =Cover!A10 -> Apartment Development Model
B4: =Cover!A12 -> Suburban / Urban Location
B5: Schedule
B8: Project Start Date | D8: 44562
I10: =D8 -> 44562 | J10: =EDATE(I10,1) -> 44593 | K10: =EDATE(J10,1) -> 44621 | L10: =EDATE(K10,1) -> 44652 | M10: =EDATE(L10,1) -> 44682 | N10: =EDATE(M10,1) -> 44713 | O10: =EDATE(N10,1) -> 44743 | P10: =EDATE(O10,1) -> 44774 | Q10: =EDATE(P10,1) -> 44805 | ... BP10: =EDATE(BO10,1) -> 46357
C11: Duration | D11: Start Date | E11: End Date | F11: Anchored to | G11: Offset | I11: ="Q"&ROUNDUP(MONTH(I10)/3,0)&" "&YEAR(I10) -> Q1 2022 | L11: ="Q"&ROUNDUP(MONTH(L10)/3,0)&" "&YEAR(L10) -> Q2 2022 | O11: ="Q"&ROUNDUP(MONTH(O10)/3,0)&" "&YEAR(O10) -> Q3 2022 | R11: ="Q"&ROUNDUP(MONTH(R10)/3,0)&" "&YEAR(R10) -> Q4 2022 | U11: ="Q"&ROUNDUP(MONTH(U10)/3,0)&" "&YEAR(U10) -> Q1 2023 | X11: ="Q"&ROUNDUP(MONTH(X10)/3,0)&" "&YEAR(X10) -> Q2 2023 | AA11: ="Q"&ROUNDUP(MONTH(AA10)/3,0)&" "&YEAR(AA10) -> Q3 2023 | AD11: ="Q"&ROUNDUP(MONTH(AD10)/3,0)&" "&YEAR(AD10) -> Q4 2023 | AG11: ="Q"&ROUNDUP(MONTH(AG10)/3,0)&" "&YEAR(AG10) -> Q1 2024 | AJ11: ="Q"&ROUNDUP(MONTH(AJ10)/3,0)&" "&YEAR(AJ10) -> Q2 2024 | AM11: ="Q"&ROUNDUP(MONTH(AM10)/3,0)&" "&YEAR(AM10) -> Q3 2024 | AP11: ="Q"&ROUNDUP(MONTH(AP10)/3,0)&" "&YEAR(AP10) -> Q4 2024 | AS11: ="Q"&ROUNDUP(MONTH(AS10)/3,0)&" "&YEAR(AS10) -> Q1 2025 | AV11: ="Q"&ROUNDUP(MONTH(AV10)/3,0)&" "&YEAR(AV10) -> Q2 2025 | AY11: ="Q"&ROUNDUP(MONTH(AY10)/3,0)&" "&YEAR(AY10) -> Q3 2025 | BB11: ="Q"&ROUNDUP(MONTH(BB10)/3,0)&" "&YEAR(BB10) -> Q4 2025 | BE11: ="Q"&ROUNDUP(MONTH(BE10)/3,0)&" "&YEAR(BE10) -> Q1 2026 | BH11: ="Q"&ROUNDUP(MONTH(BH10)/3,0)&" "&YEAR(BH10) -> Q2 2026 | BK11: ="Q"&ROUNDUP(MONTH(BK10)/3,0)&" "&YEAR(BK10) -> Q3 2026 | BN11: ="Q"&ROUNDUP(MONTH(BN10)/3,0)&" "&YEAR(BN10) -> Q4 2026
B13: Land Purchase | C13: 0 | D13: =D8 -> 44562 | E13: =EDATE(D13,C13) -> 44562 | F13: =B8 -> Project Start Date | G13: 0 | I13: =IF(AND(I$10>=$D13,I$10<=$E13),1,"") -> 1 | J13: =IF(AND(J$10>=$D13,J$10<=$E13),1,"") | K13: =IF(AND(K$10>=$D13,K$10<=$E13),1,"") | L13: =IF(AND(L$10>=$D13,L$10<=$E13),1,"") | M13: =IF(AND(M$10>=$D13,M$10<=$E13),1,"") | N13: =IF(AND(N$10>=$D13,N$10<=$E13),1,"") | O13: =IF(AND(O$10>=$D13,O$10<=$E13),1,"") | P13: =IF(AND(P$10>=$D13,P$10<=$E13),1,"") | ... BP13: =IF(AND(BP$10>=$D13,BP$10<=$E13),1,"")
B15: Pre-Development | C15: 12 | D15: =EDATE(E13,G15+1) -> 44593 | E15: =EDATE(D15,C15) -> 44958 | F15: =B13 -> Land Purchase | G15: 0 | I15: =IF(AND(I$10>=$D15,I$10<=$E15),1,"") | J15: =IF(AND(J$10>=$D15,J$10<=$E15),1,"") -> 1 | K15: =IF(AND(K$10>=$D15,K$10<=$E15),1,"") -> 1 | L15: =IF(AND(L$10>=$D15,L$10<=$E15),1,"") -> 1 | M15: =IF(AND(M$10>=$D15,M$10<=$E15),1,"") -> 1 | N15: =IF(AND(N$10>=$D15,N$10<=$E15),1,"") -> 1 | O15: =IF(AND(O$10>=$D15,O$10<=$E15),1,"") -> 1 | P15: =IF(AND(P$10>=$D15,P$10<=$E15),1,"") -> 1 | ... BP15: =IF(AND(BP$10>=$D15,BP$10<=$E15),1,"")
B17: Construction | C17: =Sensitivity!H20 -> 18 | D17: =EDATE(E15,G17+1) -> 44986 | E17: =EDATE(D17,C17) -> 45536 | F17: =B15 -> Pre-Development | G17: 0 | I17: =IF(AND(I$10>=$D17,I$10<=$E17),1,"") | J17: =IF(AND(J$10>=$D17,J$10<=$E17),1,"") | K17: =IF(AND(K$10>=$D17,K$10<=$E17),1,"") | L17: =IF(AND(L$10>=$D17,L$10<=$E17),1,"") | M17: =IF(AND(M$10>=$D17,M$10<=$E17),1,"") | N17: =IF(AND(N$10>=$D17,N$10<=$E17),1,"") | O17: =IF(AND(O$10>=$D17,O$10<=$E17),1,"") | P17: =IF(AND(P$10>=$D17,P$10<=$E17),1,"") | ... BP17: =IF(AND(BP$10>=$D17,BP$10<=$E17),1,"")
B19: Lease-up | C19: =Sensitivity!H25 -> 6 | D19: =EDATE(E17,G19+1) -> 45474 | E19: =EDATE(D19,C19) -> 45658 | F19: =B17 -> Construction | G19: -3 | I19: =IF(AND(I$10>=$D19,I$10<=$E19),1,"") | J19: =IF(AND(J$10>=$D19,J$10<=$E19),1,"") | K19: =IF(AND(K$10>=$D19,K$10<=$E19),1,"") | L19: =IF(AND(L$10>=$D19,L$10<=$E19),1,"") | M19: =IF(AND(M$10>=$D19,M$10<=$E19),1,"") | N19: =IF(AND(N$10>=$D19,N$10<=$E19),1,"") | O19: =IF(AND(O$10>=$D19,O$10<=$E19),1,"") | P19: =IF(AND(P$10>=$D19,P$10<=$E19),1,"") | ... BP19: =IF(AND(BP$10>=$D19,BP$10<=$E19),1,"")
I20: =IF(AND(I$10>=$D20,I$10<=$E20),1,"") | J20: =IF(AND(J$10>=$D20,J$10<=$E20),1,"") | K20: =IF(AND(K$10>=$D20,K$10<=$E20),1,"") | L20: =IF(AND(L$10>=$D20,L$10<=$E20),1,"") | M20: =IF(AND(M$10>=$D20,M$10<=$E20),1,"") | N20: =IF(AND(N$10>=$D20,N$10<=$E20),1,"") | O20: =IF(AND(O$10>=$D20,O$10<=$E20),1,"") | P20: =IF(AND(P$10>=$D20,P$10<=$E20),1,"") | ... BP20: =IF(AND(BP$10>=$D20,BP$10<=$E20),1,"")
B21: Stabilized | C21: 0 | D21: =EDATE(E19,G21+1) -> 45689 | E21: =EDATE(D21,C21) -> 45689 | F21: =B19 -> Lease-up | G21: 0 | I21: =IF(AND(I$10>=$D21,I$10<=$E21),1,"") | J21: =IF(AND(J$10>=$D21,J$10<=$E21),1,"") | K21: =IF(AND(K$10>=$D21,K$10<=$E21),1,"") | L21: =IF(AND(L$10>=$D21,L$10<=$E21),1,"") | M21: =IF(AND(M$10>=$D21,M$10<=$E21),1,"") | N21: =IF(AND(N$10>=$D21,N$10<=$E21),1,"") | O21: =IF(AND(O$10>=$D21,O$10<=$E21),1,"") | P21: =IF(AND(P$10>=$D21,P$10<=$E21),1,"") | ... BP21: =IF(AND(BP$10>=$D21,BP$10<=$E21),1,"")

Sheet Operating Revenue and Expenses
J1: ="Currently running: "&CHOOSE(Sensitivity!$E$8,Sensitivity!$B$11,Sensitivity!$B$12,Sensitivity!$B$13) -> Currently running: Base Case
B3: =Cover!A10 -> Apartment Development Model
B4: =Cover!A12 -> Suburban / Urban Location
B5: Operating Revenue and Expenses
B8: Parking
B9: Residential Stalls | E9: 105
B10: Visitor Stalls | E10: 10
B11: Extra Stalls | E11: 0
B12: Total | E12: =SUM(E9:E11) -> 115 | G12: Ratio | H12: =E12/F19 -> 1.15 | I12: stall per unit
B14: Revenue
B15: Residential | D15: Avg Sq Ft | E15: Total Area | F15: No. Units | G15: % Total | H15: Monthly $ | I15: Annual $ | J15: $/Sqft
B16: 1 Bed | D16: 720 | E16: =+D16*F16 -> 25200 | F16: =100*0.35 -> 35 | G16: =F16/$F$19 -> 0.35 | H16: 1990 | I16: =+H16*F16*12 -> 835800 | J16: =I16/E16/12 -> 2.7638889
B17: 2 Bed | D17: 935 | E17: =+D17*F17 -> 60775 | F17: =100*0.65 -> 65 | G17: =F17/$F$19 -> 0.65 | H17: 2400 | I17: =+H17*F17*12 -> 1872000 | J17: =I17/E17/12 -> 2.5668449
M18: Sensitize Rent | N18: =Sensitiv2!D6 -> 1
B19: Total | D19: =+E19/F19 -> 859.75 | E19: =SUM(E16:E18) -> 85975 | F19: =SUM(F16:F18) -> 100 | G19: =SUM(G16:G18) -> 1 | H19: =+I19/12/F19 -> 2256.5 | I19: =SUM(I16:I18)*N18 -> 2707800 | J19: =I19/E19/12 -> 2.6246002
B20: Average Res | E20: =(E16+E17+E18)/F19 -> 859.75 | H20: =(I16+I17)/(F16+F17)/12 -> 2256.5 | J20: =H20/E20 -> 2.6246002
B22: Other Income
B23: Storage Lockers | E23: 100 | G23: 40 | H23: =G23*E23 -> 4000 | I23: =H23*12 -> 48000
B24: Parking Revenue | E24: =E9 -> 105 | F24: x | G24: 120 | H24: =E24*G24 -> 12600 | I24: =H24*12 -> 151200
B25: Total Other Income | I25: =SUM(I23:I24) -> 199200
B27: Total Potential Gross Revenue (including parking & storage) | H27: =+I27/F19/12 -> 2422.5 | I27: =SUM(I19,I25) -> 2907000 | J27: =+I27/E19/12 -> 2.8176796
B28: Less: Vacancy and collection loss | F28: @ | G28: 0.025 | H28: =G28*H27 -> 60.5625 | I28: =G28*I27 -> 72675
B29: Effective Gross Income | H29: =+H27-H28 -> 2361.9375 | I29: =+I27-I28 -> 2834325
B31: Operating Expenses
G32: Per Unit | H32: % | I32: Annual $
B33: Property Taxes | G33: 3200 | H33: =G33/$G$43 -> 0.41824051 | I33: =G33*$F$19 -> 320000
B34: Insurance | G34: 225 | H34: =G34/$G$43 -> 0.029407536 | I34: =G34*$F$19*N34 -> 22500 | M34: Sensitize Op Cost | N34: =+Sensitiv2!D8 -> 1
B35: Repair & Maintenance | G35: 900 | H35: =G35/$G$43 -> 0.11763014 | I35: =G35*$F$19*N35 -> 90000 | M35: Sensitize Op Cost | N35: =+N34 -> 1
B36: Utilities | G36: 1500 | H36: =G36/$G$43 -> 0.19605024 | I36: =G36*$F$19*N36 -> 150000 | M36: Sensitize Op Cost | N36: =+N35 -> 1
B37: Hydro | G37: 0 | H37: =G37/$G$43 -> 0 | I37: =G37*$F$19 -> 0 | M37: Sensitize Op Cost | N37: =+N36 -> 1
B38: Sub-Metering Revenue Share | G38: =-8*12 -> -96 | H38: =G38/$G$43 -> -0.012547215 | I38: =G38*$F$19 -> -9600 | K38: $ 8/unit/month
B39: Staff (Ops & Maint) | G39: 800 | H39: =G39/$G$43 -> 0.10456013 | I39: =G39*$F$19*N39 -> 80000 | M39: Sensitize Op Cost | N39: =+N36 -> 1
B40: Marketing | G40: 250 | H40: =G40/$G$43 -> 0.03267504 | I40: =G40*$F$19*N40 -> 25000 | M40: Sensitize Op Cost | N40: =+N39 -> 1
B41: Internet | G41: 0 | H41: =G41/$G$43 -> 0 | I41: =G41*$F$19 -> 0
B42: Management Fee | D42: 0.03 | G42: =I42/F19 -> 872.1 | H42: =G42/$G$43 -> 0.11398361 | I42: =D42*I27 -> 87210
B43: Total Expenses | G43: =I43/F19 -> 7651.1 | H43: =SUM(H33:H42) -> 1 | I43: =SUM(I33:I42) -> 765110
B44: Operating Expenses Varience | I44: =Sensitivity!H30 -> 0
B45: Operating Expenses | I45: =(1+I44)*I43 -> 765110
B46: Operating Expenses/Revenue | I46: =I45/I29 -> 0.26994434
B48: Net Operating Income and Valuation
...

Sheet Development Costs
J1: ="Currently running: "&CHOOSE(Sensitivity!$E$8,Sensitivity!$B$11,Sensitivity!$B$12,Sensitivity!$B$13) -> Currently running: Base Case
B3: =Cover!A10 -> Apartment Development Model
B4: =Cover!A12 -> Suburban / Urban Location
B5: Development Costs
B9: Number of Units: | I9: ='Operating Revenue and Expenses'!F19 -> 100 | J9: Res only
B10: Net Rentable Area: | I10: ='Operating Revenue and Expenses'!E19 -> 85975 | J10: Res
H12: Total | I12: Per unit | J12: Per Sqft
B13: LAND | M13: Contingency Prov
B14: Land | H14: =5350000+300000 -> 5650000 | I14: =H14/$I$9 -> 56500 | J14: =H14/$I$10 -> 65.716778
B15: Closing / Other Cost | G15: 0.06 | H15: =G15*H14 -> 339000 | I15: =H15/$I$9 -> 3390 | J15: =H15/$I$10 -> 3.9430067
B16: Total Land Costs | G16: =H16/$H$89 -> 0.12175788 | H16: =SUM(H14:H15) -> 5989000 | I16: =SUM(I14:I15) -> 59890 | J16: =SUM(J14:J15) -> 69.659785
B18: CONSTRUCTION
B19: Construction hard cost | H19: =28500000*M19 -> 28500000 | I19: =H19/$I$9 -> 285000 | J19: =H19/$I$10 -> 331.49171 | L19: Sensitize | M19: =+Sensitiv2!D10 -> 1
B20: Offsite/Sitework Costs | H20: 0 | I20: =H20/$I$9 -> 0 | J20: =H20/$I$10 -> 0
B21: Construction contingency | G21: =+H21/H19 -> 0.052631579 | H21: =25000000*0.06 -> 1500000 | I21: =H21/$I$9 -> 15000 | J21: =H21/$I$10 -> 17.446932 | K21: =+H21/H19 -> 0.052631579 | L21: =+H19 -> 28500000 | M21: =+H21 -> 1500000 | N21: =+M21/L21 -> 0.052631579
B22: Total Construction Costs | G22: =H22/$H$89 -> 0.60990755 | H22: =SUM(H19:H21) -> 30000000 | I22: =SUM(I14:I21) -> 419780 | J22: =SUM(J19:J21) -> 348.93864
B24: PROFESSIONAL FEES
B25: Architect | H25: =1200000*0.4 -> 480000 | I25: =H25/$I$9 -> 4800 | J25: =H25/$I$10 -> 5.5830183
B26: Landscape architect | H26: =80000*0.4 -> 32000 | I26: =H26/$I$9 -> 320 | J26: =H26/$I$10 -> 0.37220122
B27: Structural engineer | H27: =400000*0.4 -> 160000 | I27: =H27/$I$9 -> 1600 | J27: =H27/$I$10 -> 1.8610061
B28: Civil engineer | H28: 75000 | I28: =H28/$I$9 -> 750 | J28: =H28/$I$10 -> 0.87234661
B29: Mechanical & Electrical engineer | H29: =220000*0.4 -> 88000 | I29: =H29/$I$9 -> 880 | J29: =H29/$I$10 -> 1.0235534
B30: Geotechnical engineer | H30: 35000 | I30: =H30/$I$9 -> 350 | J30: =H30/$I$10 -> 0.40709509
B31: Site Servicing Engineer | H31: 0 | I31: =H31/$I$9 -> 0 | J31: =H31/$I$10 -> 0
B32: Survey | H32: 20000 | I32: =H32/$I$9 -> 200 | J32: =H32/$I$10 -> 0.23262576
B33: Env Phase 3 Cost | H33: 0 | I33: =H33/$I$9 -> 0 | J33: =H33/$I$10 -> 0
I34: =H34/$I$9 -> 0 | J34: =H34/$I$10 -> 0
B35: Others | H35: 400000 | I35: =H35/$I$9 -> 4000 | J35: =H35/$I$10 -> 4.6525153
B36: Environmental consultant | H36: 0 | I36: =H36/$I$9 -> 0 | J36: =H36/$I$10 -> 0
B37: Interior design | H37: 0 | I37: =H37/$I$9 -> 0 | J37: =H37/$I$10 -> 0
B38: Traffic consultant | H38: 0 | I38: =H38/$I$9 -> 0 | J38: =H38/$I$10 -> 0
B39: Disbursements | H39: 0 | I39: =H39/$I$9 -> 0 | J39: =H39/$I$10 -> 0
B40: Professional fee contingency | G40: 0.1 | H40: =SUM(H25:H39)*G40 -> 129000 | I40: =H40/$I$9 -> 1290 | J40: =H40/$I$10 -> 1.5004362
B41: Total Professional Fees | G41: =H41/$H$89 -> 0.028848627 | H41: =SUM(H25:H40) -> 1419000 | I41: =SUM(I25:I40) -> 14190 | J41: =SUM(J25:J40) -> 16.504798 | K41: =+H41/H22 -> 0.0473 | L41: =+H41-H40 -> 1290000 | M41: =+H40 -> 129000 | N41: =+M41/L41 -> 0.1
B43: DEVELOPMENT MANAGEMENT
B45: Development Management Fee | H45: =3300000*0.38 -> 1254000 | I45: =H45/$I$9 -> 12540 | J45: =H45/$I$10 -> 14.585635
B46: Total Development Management Fee | G46: =H46/$H$89 -> 0.025494136 | H46: =SUM(H44:H45) -> 1254000 | I46: =SUM(I44:I45) -> 12540 | J46: =SUM(J44:J45) -> 14.585635
B48: PERMITS AND APPROVALS
B49: Development Permit | H49: 0 | I49: =H49/$I$9 -> 0 | J49: =H49/$I$10 -> 0
B50: Rezoning | H50: 0 | I50: =H50/$I$9 -> 0 | J50: =H50/$I$10 -> 0
...

Sheet Sensitivity
J1: ="Currently running: "&CHOOSE(Sensitivity!$E$8,Sensitivity!$B$11,Sensitivity!$B$12,Sensitivity!$B$13) -> Currently running: Base Case
B3: =Cover!A10 -> Apartment Development Model
B4: =Cover!A12 -> Suburban / Urban Location
B5: Scenarios
D8: Select Scenario: | E8: 1
B9: SENSITIZED ASSUMPTIONS
B10: Capitalization Rate | H10: =CHOOSE($E$8,H11,H12,H13) -> 0.04
B11: Base Case | H11: 0.04
B12: Best Case | H12: 0.0375
B13: Worst Case | H13: 0.0425
B15: Construction Loan Interest Rate | H15: =CHOOSE($E$8,H16,H17,H18) -> 0.046666667
B16: Base Case | H16: =+'Debt Stack'!C20 -> 0.046666667
B17: Best Case | H17: =+H16-0.0025 -> 0.044166667
B18: Worst Case | H18: =+H16+0.0025 -> 0.049166667
B20: Construction Period (Months) | H20: =CHOOSE($E$8,H21,H22,H23) -> 18
B21: Base Case | H21: 18
B22: Best Case | H22: =H21-3 -> 15
B23: Worst Case | H23: =H21+3 -> 21
B25: Lease-up Period (Months) | H25: =CHOOSE($E$8,H26,H27,H28) -> 6
B26: Base Case | H26: 6
B27: Best Case | H27: =H26-2 -> 4
B28: Worst Case | H28: =H26+2 -> 8
B30: Operating Expense Varience | H30: =CHOOSE($E$8,H31,H32,H33) -> 0
B31: Base Case | H31: 0
B32: Best Case | H32: -0.05
B33: Worst Case | H33: 0.05

Sheet Debt Stack
H1: ='Executive Summary'!J1 -> Currently running: Base Case
B4: ='Executive Summary'!B3:I3 -> Apartment Development Model
B5: ='Executive Summary'!B4:I4 -> Suburban / Urban Location
B8: DEBT STACK
B11: Blended Construction Interest Rate Calucator
D12: Int Rate | E12: Component Int
B13: Total Equity | C13: =+'Development Cash Flow'!D109 -> 0.10142553
B14: Total Debt | C14: =1-C13 -> 0.89857447
B16: Total Debt | C16: 0.9
B17: Mezannine Debt | C17: 0.15 | D17: 0.08 | E17: =+C17*D17 -> 0.012
B18: Regular Bank Debt | C18: =+C16-C17 -> 0.75 | D18: 0.04 | E18: =+C18*D18 -> 0.03
B19: Total Debt | C19: =C17+C18 -> 0.9 | E19: =+E17+E18 -> 0.042
B20: Blended Construction Interest Rate | C20: =+E19/C19 -> 0.046666667
B25: Note 1: Double check the Total Debt Ratio from DCF page. | E25: ='Development Cash Flow'!D108 -> 0.89857447 | F25: =E25-C16 -> -0.0014255329 | G25: < Diff
B26: 2: Client to confirm if Mezannine Debt, otherwise take 0%

Sheet Development Cash Flow
B2: =Cover!A10 -> Apartment Development Model
B3: =Cover!A12 -> Suburban / Urban Location
B5: Cash Flow | I5: =YEAR(I7) -> 2022 | J5: =YEAR(J7) -> 2022 | K5: =YEAR(K7) -> 2022 | L5: =YEAR(L7) -> 2022 | M5: =YEAR(M7) -> 2022 | N5: =YEAR(N7) -> 2022 | O5: =YEAR(O7) -> 2022 | P5: =YEAR(P7) -> 2022 | ... CZ5: =YEAR(CZ7) -> 2029
I6: 1 | J6: 2 | K6: 3 | L6: 4 | M6: 5 | N6: 6 | O6: 7 | P6: 8 | Q6: 9 | R6: 10 | S6: 11 | T6: 12 | U6: 13 | V6: 14 | W6: 15 | X6: 16 | Y6: 17 | Z6: 18 | AA6: 19 | AB6: 20 | AC6: 21 | AD6: 22 | AE6: 23 | AF6: 24 | AG6: 25 | AH6: 26 | AI6: 27 | AJ6: 28 | AK6: 29 | AL6: 30 | AM6: 31 | AN6: 32 | AO6: 33 | AP6: 34 | AQ6: 35 | AR6: 36 | AS6: 37 | AT6: 38 | AU6: 39 | AV6: 40 | AW6: 41 | AX6: 42 | AY6: 43 | AZ6: 44 | BA6: 45 | BB6: 46 | BC6: 47 | BD6: 48 | BE6: 49 | BF6: 50 | BG6: 51 | BH6: 52 | BI6: 53 | BJ6: 54 | BK6: 55 | BL6: 56 | BM6: 57 | BN6: 58 | BO6: 59 | BP6: 60 | BQ6: 61 | BR6: 62 | BS6: 63 | BT6: 64 | BU6: 65 | BV6: 66 | BW6: 67 | BX6: 68 | BY6: 69 | BZ6: 70 | CA6: 71 | CB6: 72 | CC6: 73 | CD6: 74 | CE6: 75 | CF6: 76 | CG6: 77 | CH6: 78 | CI6: 79 | CJ6: 80 | CK6: 81 | CL6: 82 | CM6: 83 | CN6: 84 | CO6: 85 | CP6: 86 | CQ6: 87 | CR6: 88 | CS6: 89 | CT6: 90 | CU6: 91 | CV6: 92 | CW6: 93 | CX6: 94 | CY6: 95 | CZ6: 96
B7: Items | C7: Budget | D7: Variance | E7: Total Cashflow | F7: Start | G7: End | H7: Months | I7: =Schedule!D8 -> 44562 | J7: =EDATE(I7,1) -> 44593 | K7: =EDATE(J7,1) -> 44621 | L7: =EDATE(K7,1) -> 44652 | M7: =EDATE(L7,1) -> 44682 | N7: =EDATE(M7,1) -> 44713 | O7: =EDATE(N7,1) -> 44743 | P7: =EDATE(O7,1) -> 44774 | Q7: =EDATE(P7,1) -> 44805 | ... CZ7: =EDATE(CY7,1) -> 47453
B8: LEASE-UP SCHEDULE
B9: Number of Units Completed | C9: ='Development Costs'!$I$9 -> 100 | D9: =ROUND(C9-E9,0) -> 0 | E9: =SUM(I9:CZ9) -> 100 | I9: =IF(I7=Schedule!$E$17,'Development Cash Flow'!$C$9,0) -> 0 | J9: =IF(J7=Schedule!$E$17,'Development Cash Flow'!$C$9,0) -> 0 | K9: =IF(K7=Schedule!$E$17,'Development Cash Flow'!$C$9,0) -> 0 | L9: =IF(L7=Schedule!$E$17,'Development Cash Flow'!$C$9,0) -> 0 | M9: =IF(M7=Schedule!$E$17,'Development Cash Flow'!$C$9,0) -> 0 | N9: =IF(N7=Schedule!$E$17,'Development Cash Flow'!$C$9,0) -> 0 | O9: =IF(O7=Schedule!$E$17,'Development Cash Flow'!$C$9,0) -> 0 | P9: =IF(P7=Schedule!$E$17,'Development Cash Flow'!$C$9,0) -> 0 | ... CZ9: =IF(CZ7=Schedule!$E$17,'Development Cash Flow'!$C$9,0) -> 0
B10: Cumulative Units Complete | C10: ='Development Costs'!$I$9 -> 100 | D10: =ROUND(C10-E10,0) -> 0 | E10: =MAX(I10:CZ10) -> 100 | I10: =I9 -> 0 | J10: =I10+J9 -> 0 | K10: =J10+K9 -> 0 | L10: =K10+L9 -> 0 | M10: =L10+M9 -> 0 | N10: =M10+N9 -> 0 | O10: =N10+O9 -> 0 | P10: =O10+P9 -> 0 | Q10: =P10+Q9 -> 0 | ... CZ10: =CY10+CZ9 -> 100
B11: Percentage Completed | E11: =MAX(I11:CZ11) -> 1 | I11: =I10/'Development Costs'!$I$9 -> 0 | J11: =J10/'Development Costs'!$I$9 -> 0 | K11: =K10/'Development Costs'!$I$9 -> 0 | L11: =L10/'Development Costs'!$I$9 -> 0 | M11: =M10/'Development Costs'!$I$9 -> 0 | N11: =N10/'Development Costs'!$I$9 -> 0 | O11: =O10/'Development Costs'!$I$9 -> 0 | P11: =P10/'Development Costs'!$I$9 -> 0 | ... CZ11: =CZ10/'Development Costs'!$I$9 -> 1
B12: New Units Leased | C12: ='Development Costs'!$I$9 -> 100 | D12: =ROUND(C12-E12,0) -> 0 | E12: =SUM(I12:CZ12) -> 100 | F12: =Schedule!D19 -> 45474 | G12: =Schedule!E19 -> 45658 | H12: =DATEDIF(F12,G12,"m")+1 -> 7 | I12: =IF(AND(I$7<=$G12,I$7>=$F12,$H12<>0,$H12<>""),$C12/$H12,0) -> 0 | J12: =IF(AND(J$7<=$G12,J$7>=$F12,$H12<>0,$H12<>""),$C12/$H12,0) -> 0 | K12: =IF(AND(K$7<=$G12,K$7>=$F12,$H12<>0,$H12<>""),$C12/$H12,0) -> 0 | L12: =IF(AND(L$7<=$G12,L$7>=$F12,$H12<>0,$H12<>""),$C12/$H12,0) -> 0 | M12: =IF(AND(M$7<=$G12,M$7>=$F12,$H12<>0,$H12<>""),$C12/$H12,0) -> 0 | N12: =IF(AND(N$7<=$G12,N$7>=$F12,$H12<>0,$H12<>""),$C12/$H12,0) -> 0 | O12: =IF(AND(O$7<=$G12,O$7>=$F12,$H12<>0,$H12<>""),$C12/$H12,0) -> 0 | P12: =IF(AND(P$7<=$G12,P$7>=$F12,$H12<>0,$H12<>""),$C12/$H12,0) -> 0 | ... CZ12: =IF(AND(CZ$7<=$G12,CZ$7>=$F12,$H12<>0,$H12<>""),$C12/$H12,0) -> 0
B13: Cumulative Units Leased | C13: ='Development Costs'!$I$9 -> 100 | D13: =ROUND(C13-E13,0) -> 0 | E13: =MAX(I13:CZ13) -> 100 | I13: =I12 -> 0 | J13: =I13+J12 -> 0 | K13: =J13+K12 -> 0 | L13: =K13+L12 -> 0 | M13: =L13+M12 -> 0 | N13: =M13+N12 -> 0 | O13: =N13+O12 -> 0 | P13: =O13+P12 -> 0 | Q13: =P13+Q12 -> 0 | ... CZ13: =CY13+CZ12 -> 100
B14: Percentage Leased | E14: =MAX(I14:CZ14) -> 1 | I14: =I13/'Development Costs'!$I$9 -> 0 | J14: =J13/'Development Costs'!$I$9 -> 0 | K14: =K13/'Development Costs'!$I$9 -> 0 | L14: =L13/'Development Costs'!$I$9 -> 0 | M14: =M13/'Development Costs'!$I$9 -> 0 | N14: =N13/'Development Costs'!$I$9 -> 0 | O14: =O13/'Development Costs'!$I$9 -> 0 | P14: =P13/'Development Costs'!$I$9 -> 0 | ... CZ14: =CZ13/'Development Costs'!$I$9 -> 1
B15: Units Occupied | C15: ='Development Costs'!$I$9 -> 100 | D15: =ROUND(C15-E15,0) -> 0 | E15: =SUM(I15:CZ15) -> 100 | I15: 0 | J15: =IF(I$7>=$F$9,MIN(J10,J13)-I16,0) -> 0 | K15: =IF(J$7>=$F$9,MIN(K10,K13)-J16,0) -> 0 | L15: =IF(K$7>=$F$9,MIN(L10,L13)-K16,0) -> 0 | M15: =IF(L$7>=$F$9,MIN(M10,M13)-L16,0) -> 0 | N15: =IF(M$7>=$F$9,MIN(N10,N13)-M16,0) -> 0 | O15: =IF(N$7>=$F$9,MIN(O10,O13)-N16,0) -> 0 | P15: =IF(O$7>=$F$9,MIN(P10,P13)-O16,0) -> 0 | Q15: =IF(P$7>=$F$9,MIN(Q10,Q13)-P16,0) -> 0 | ... CZ15: =IF(CY$7>=$F$9,MIN(CZ10,CZ13)-CY16,0) -> 0
B16: Cumulative Units Occupied | C16: ='Development Costs'!$I$9 -> 100 | D16: =ROUND(C16-E16,0) -> 0 | E16: =MAX(I16:CZ16) -> 100 | I16: =I15 -> 0 | J16: =I16+J15 -> 0 | K16: =J16+K15 -> 0 | L16: =K16+L15 -> 0 | M16: =L16+M15 -> 0 | N16: =M16+N15 -> 0 | O16: =N16+O15 -> 0 | P16: =O16+P15 -> 0 | Q16: =P16+Q15 -> 0 | ... CZ16: =CY16+CZ15 -> 100
B17: Percentage Occupied | E17: =MAX(I17:CZ17) -> 1 | I17: =I16/'Development Costs'!$I$9 -> 0 | J17: =J16/'Development Costs'!$I$9 -> 0 | K17: =K16/'Development Costs'!$I$9 -> 0 | L17: =L16/'Development Costs'!$I$9 -> 0 | M17: =M16/'Development Costs'!$I$9 -> 0 | N17: =N16/'Development Costs'!$I$9 -> 0 | O17: =O16/'Development Costs'!$I$9 -> 0 | P17: =P16/'Development Costs'!$I$9 -> 0 | ... CZ17: =CZ16/'Development Costs'!$I$9 -> 1
B19: OPERATING INCOME
B20: Revenue Inflation Factor | I20: =(1+'10-Yr Cash Flow IRR'!$E$9)^(YEAR(I7)-YEAR(Schedule!$D$8)) -> 1 | J20: =(1+'10-Yr Cash Flow IRR'!$E$9)^(YEAR(J7)-YEAR(Schedule!$D$8)) -> 1 | K20: =(1+'10-Yr Cash Flow IRR'!$E$9)^(YEAR(K7)-YEAR(Schedule!$D$8)) -> 1 | L20: =(1+'10-Yr Cash Flow IRR'!$E$9)^(YEAR(L7)-YEAR(Schedule!$D$8)) -> 1 | M20: =(1+'10-Yr Cash Flow IRR'!$E$9)^(YEAR(M7)-YEAR(Schedule!$D$8)) -> 1 | N20: =(1+'10-Yr Cash Flow IRR'!$E$9)^(YEAR(N7)-YEAR(Schedule!$D$8)) -> 1 | O20: =(1+'10-Yr Cash Flow IRR'!$E$9)^(YEAR(O7)-YEAR(Schedule!$D$8)) -> 1 | P20: =(1+'10-Yr Cash Flow IRR'!$E$9)^(YEAR(P7)-YEAR(Schedule!$D$8)) -> 1 | ... CZ20: =(1+'10-Yr Cash Flow IRR'!$E$9)^(YEAR(CZ7)-YEAR(Schedule!$D$8)) -> 1.1486857
B21: Cost Inflation Factor | I21: =(1+'10-Yr Cash Flow IRR'!$E$10)^(YEAR(I7)-YEAR(Schedule!$D$8)) -> 1 | J21: =(1+'10-Yr Cash Flow IRR'!$E$9)^(YEAR(J7)-YEAR(Schedule!$D$8)) -> 1 | K21: =(1+'10-Yr Cash Flow IRR'!$E$9)^(YEAR(K7)-YEAR(Schedule!$D$8)) -> 1 | L21: =(1+'10-Yr Cash Flow IRR'!$E$9)^(YEAR(L7)-YEAR(Schedule!$D$8)) -> 1 | M21: =(1+'10-Yr Cash Flow IRR'!$E$9)^(YEAR(M7)-YEAR(Schedule!$D$8)) -> 1 | N21: =(1+'10-Yr Cash Flow IRR'!$E$9)^(YEAR(N7)-YEAR(Schedule!$D$8)) -> 1 | O21: =(1+'10-Yr Cash Flow IRR'!$E$9)^(YEAR(O7)-YEAR(Schedule!$D$8)) -> 1 | P21: =(1+'10-Yr Cash Flow IRR'!$E$9)^(YEAR(P7)-YEAR(Schedule!$D$8)) -> 1 | Q21: =(1+'10-Yr Cash Flow IRR'!$E$9)^(YEAR(Q7)-YEAR(Schedule!$D$8)) -> 1 | ... CZ21: =(1+'10-Yr Cash Flow IRR'!$E$9)^(YEAR(CZ7)-YEAR(Schedule!$D$8)) -> 1.1486857
B22: Security Deposit | C22: =-'Development Costs'!H83 -> 252757.01 | E22: =SUM(I22:CZ22) -> 252757.01 | I22: =+'Operating Revenue and Expenses'!$I$27/'Operating Revenue and Expenses'!$F$19/12*I12*I20 -> 0 | J22: =+'Operating Revenue and Expenses'!$I$27/'Operating Revenue and Expenses'!$F$19/12*J12*J20 -> 0 | K22: =+'Operating Revenue and Expenses'!$I$27/'Operating Revenue and Expenses'!$F$19/12*K12*K20 -> 0 | L22: =+'Operating Revenue and Expenses'!$I$27/'Operating Revenue and Expenses'!$F$19/12*L12*L20 -> 0 | M22: =+'Operating Revenue and Expenses'!$I$27/'Operating Revenue and Expenses'!$F$19/12*M12*M20 -> 0 | N22: =+'Operating Revenue and Expenses'!$I$27/'Operating Revenue and Expenses'!$F$19/12*N12*N20 -> 0 | O22: =+'Operating Revenue and Expenses'!$I$27/'Operating Revenue and Expenses'!$F$19/12*O12*O20 -> 0 | P22: =+'Operating Revenue and Expenses'!$I$27/'Operating Revenue and Expenses'!$F$19/12*P12*P20 -> 0 | ... CZ22: =+'Operating Revenue and Expenses'!$I$27/'Operating Revenue and Expenses'!$F$19/12*CZ12*CZ20 -> 0
B23: Revenue | C23: =-'Development Costs'!H84 -> 1162250.2 | D23: =ROUND(C23-E23,0) -> 0 | E23: =SUM(I23:CZ23) -> 1162250.2 | I23: =IF(I111="PUD",'Operating Revenue and Expenses'!$I$27/12*I$17*I$20,0) -> 0 | J23: =IF(J111="PUD",'Operating Revenue and Expenses'!$I$27/12*J$17*J$20,0) -> 0 | K23: =IF(K111="PUD",'Operating Revenue and Expenses'!$I$27/12*K$17*K$20,0) -> 0 | L23: =IF(L111="PUD",'Operating Revenue and Expenses'!$I$27/12*L$17*L$20,0) -> 0 | M23: =IF(M111="PUD",'Operating Revenue and Expenses'!$I$27/12*M$17*M$20,0) -> 0 | N23: =IF(N111="PUD",'Operating Revenue and Expenses'!$I$27/12*N$17*N$20,0) -> 0 | O23: =IF(O111="PUD",'Operating Revenue and Expenses'!$I$27/12*O$17*O$20,0) -> 0 | P23: =IF(P111="PUD",'Operating Revenue and Expenses'!$I$27/12*P$17*P$20,0) -> 0 | ... CZ23: =IF(CZ111="PUD",'Operating Revenue and Expenses'!$I$27/12*CZ$17*CZ$20,0) -> 0
B24: Vacancy Provision | C24: =-'Development Costs'!H85 -> -29056.254 | D24: =ROUND(C24-E24,0) -> 0 | E24: =SUM(I24:CZ24) -> -29056.254 | I24: =IF(I111="PUD",-'Operating Revenue and Expenses'!$I$28/12*I$17*I$20,0) -> 0 | J24: =IF(J111="PUD",-'Operating Revenue and Expenses'!$I$28/12*J$17*J$20,0) -> 0 | K24: =IF(K111="PUD",-'Operating Revenue and Expenses'!$I$28/12*K$17*K$20,0) -> 0 | L24: =IF(L111="PUD",-'Operating Revenue and Expenses'!$I$28/12*L$17*L$20,0) -> 0 | M24: =IF(M111="PUD",-'Operating Revenue and Expenses'!$I$28/12*M$17*M$20,0) -> 0 | N24: =IF(N111="PUD",-'Operating Revenue and Expenses'!$I$28/12*N$17*N$20,0) -> 0 | O24: =IF(O111="PUD",-'Operating Revenue and Expenses'!$I$28/12*O$17*O$20,0) -> 0 | P24: =IF(P111="PUD",-'Operating Revenue and Expenses'!$I$28/12*P$17*P$20,0) -> 0 | ... CZ24: =IF(CZ111="PUD",-'Operating Revenue and Expenses'!$I$28/12*CZ$17*CZ$20,0) -> 0
B25: Operating Expenses | C25: =-'Development Costs'!H86 -> -305899.28 | D25: =ROUND(C25-E25,0) -> 0 | E25: =SUM(I25:CZ25) -> -305899.28 | I25: =IF(I111="PUD",-'Operating Revenue and Expenses'!$I$45/12*I$17*I$21,0) -> 0 | J25: =IF(J111="PUD",-'Operating Revenue and Expenses'!$I$45/12*J$17*J$21,0) -> 0 | K25: =IF(K111="PUD",-'Operating Revenue and Expenses'!$I$45/12*K$17*K$21,0) -> 0 | L25: =IF(L111="PUD",-'Operating Revenue and Expenses'!$I$45/12*L$17*L$21,0) -> 0 | M25: =IF(M111="PUD",-'Operating Revenue and Expenses'!$I$45/12*M$17*M$21,0) -> 0 | N25: =IF(N111="PUD",-'Operating Revenue and Expenses'!$I$45/12*N$17*N$21,0) -> 0 | O25: =IF(O111="PUD",-'Operating Revenue and Expenses'!$I$45/12*O$17*O$21,0) -> 0 | P25: =IF(P111="PUD",-'Operating Revenue and Expenses'!$I$45/12*P$17*P$21,0) -> 0 | ... CZ25: =IF(CZ111="PUD",-'Operating Revenue and Expenses'!$I$45/12*CZ$17*CZ$21,0) -> 0
B26: NOI | C26: =SUM(C23:C25) -> 827294.62 | E26: =SUM(I26:CZ26)+E21 -> 827294.62 | I26: =SUM(I23:I25) -> 0 | J26: =SUM(J23:J25) -> 0 | K26: =SUM(K23:K25) -> 0 | L26: =SUM(L23:L25) -> 0 | M26: =SUM(M23:M25) -> 0 | N26: =SUM(N23:N25) -> 0 | O26: =SUM(O23:O25) -> 0 | P26: =SUM(P23:P25) -> 0 | ... CZ26: =SUM(CZ23:CZ25) -> 0
B28: LAND
B29: ='Development Costs'!B14 -> Land | C29: =-'Development Costs'!H14 -> -5650000 | D29: =ROUND(C29-E29,0) -> 0 | E29: =SUM(I29:CZ29) -> -5650000 | F29: =Schedule!D13 -> 44562 | G29: =Schedule!E13 -> 44562 | H29: =DATEDIF(F29,G29,"m")+1 -> 1 | I29: =IF(AND(I$7<=$G29,I$7>=$F29,$H29<>0,$H29<>""),$C29/$H29,0) -> -5650000 | J29: =IF(AND(J$7<=$G29,J$7>=$F29,$H29<>0,$H29<>""),$C29/$H29,0) -> 0 | K29: =IF(AND(K$7<=$G29,K$7>=$F29,$H29<>0,$H29<>""),$C29/$H29,0) -> 0 | L29: =IF(AND(L$7<=$G29,L$7>=$F29,$H29<>0,$H29<>""),$C29/$H29,0) -> 0 | M29: =IF(AND(M$7<=$G29,M$7>=$F29,$H29<>0,$H29<>""),$C29/$H29,0) -> 0 | N29: =IF(AND(N$7<=$G29,N$7>=$F29,$H29<>0,$H29<>""),$C29/$H29,0) -> 0 | O29: =IF(AND(O$7<=$G29,O$7>=$F29,$H29<>0,$H29<>""),$C29/$H29,0) -> 0 | P29: =IF(AND(P$7<=$G29,P$7>=$F29,$H29<>0,$H29<>""),$C29/$H29,0) -> 0 | ... CZ29: =IF(AND(CZ$7<=$G29,CZ$7>=$F29,$H29<>0,$H29<>""),$C29/$H29,0) -> 0
B30: ='Development Costs'!B15 -> Closing / Other Cost | C30: =-'Development Costs'!H15 -> -339000 | D30: =ROUND(C30-E30,0) -> 0 | E30: =SUM(I30:CZ30) -> -339000 | F30: =F29 -> 44562 | G30: =G29 -> 44562 | H30: =DATEDIF(F30,G30,"m")+1 -> 1 | I30: =IF(AND(I$7<=$G30,I$7>=$F30,$H30<>0,$H30<>""),$C30/$H30,0) -> -339000 | J30: =IF(AND(J$7<=$G30,J$7>=$F30,$H30<>0,$H30<>""),$C30/$H30,0) -> 0 | K30: =IF(AND(K$7<=$G30,K$7>=$F30,$H30<>0,$H30<>""),$C30/$H30,0) -> 0 | L30: =IF(AND(L$7<=$G30,L$7>=$F30,$H30<>0,$H30<>""),$C30/$H30,0) -> 0 | M30: =IF(AND(M$7<=$G30,M$7>=$F30,$H30<>0,$H30<>""),$C30/$H30,0) -> 0 | N30: =IF(AND(N$7<=$G30,N$7>=$F30,$H30<>0,$H30<>""),$C30/$H30,0) -> 0 | O30: =IF(AND(O$7<=$G30,O$7>=$F30,$H30<>0,$H30<>""),$C30/$H30,0) -> 0 | P30: =IF(AND(P$7<=$G30,P$7>=$F30,$H30<>0,$H30<>""),$C30/$H30,0) -> 0 | ... CZ30: =IF(AND(CZ$7<=$G30,CZ$7>=$F30,$H30<>0,$H30<>""),$C30/$H30,0) -> 0
B31: ='Development Costs'!B16 -> Total Land Costs | C31: =-'Development Costs'!H16 -> -5989000 | D31: =C31-E31 -> 0 | E31: =SUM(I31:CZ31) -> -5989000 | I31: =SUM(I29:I30) -> -5989000 | J31: =SUM(J29:J30) -> 0 | K31: =SUM(K29:K30) -> 0 | L31: =SUM(L29:L30) -> 0 | M31: =SUM(M29:M30) -> 0 | N31: =SUM(N29:N30) -> 0 | O31: =SUM(O29:O30) -> 0 | P31: =SUM(P29:P30) -> 0 | ... CZ31: =SUM(CZ29:CZ30) -> 0
B33: CONSTRUCTION
A34: Steep | B34: S Curve Option:
A35: Moderately Steep | B35: 2 | C35: S-curve StDev: | D35: =H36/B35 -> 9.5
A36: Moderate | B36: S Curve Distribution | C36: 1 | D36: =C36-E36 -> 0 | E36: =SUM(I36:CZ36) -> 1 | F36: =F41 -> 44986 | G36: =G41 -> 45536 | H36: =DATEDIF(F36,G36,"m")+1 -> 19 | I36: =IF(AND(I$7>=$F36,I$7<=$G36),(_xlfn.NORM.DIST((YEAR(I$7)-YEAR($F36))*12+MONTH(I$7)-MONTH($F36)+1,$H36/2,$D35,TRUE)-_xlfn.NORM.DIST((YEAR(I$7)-YEAR($F36))*12+MONTH(I$7)-MONTH($F36),$H36/2,$D35,TRUE))/(1-2*_xlfn.NORM.DIST(0,$H36/2,$D35,TRUE))*$C36,0) -> 0 | J36: =IF(AND(J$7>=$F36,J$7<=$G36),(_xlfn.NORM.DIST((YEAR(J$7)-YEAR($F36))*12+MONTH(J$7)-MONTH($F36)+1,$H36/2,$D35,TRUE)-_xlfn.NORM.DIST((YEAR(J$7)-YEAR($F36))*12+MONTH(J$7)-MONTH($F36),$H36/2,$D35,TRUE))/(1-2*_xlfn.NORM.DIST(0,$H36/2,$D35,TRUE))*$C36,0) -> 0 | K36: =IF(AND(K$7>=$F36,K$7<=$G36),(_xlfn.NORM.DIST((YEAR(K$7)-YEAR($F36))*12+MONTH(K$7)-MONTH($F36)+1,$H36/2,$D35,TRUE)-_xlfn.NORM.DIST((YEAR(K$7)-YEAR($F36))*12+MONTH(K$7)-MONTH($F36),$H36/2,$D35,TRUE))/(1-2*_xlfn.NORM.DIST(0,$H36/2,$D35,TRUE))*$C36,0) -> 0 | L36: =IF(AND(L$7>=$F36,L$7<=$G36),(_xlfn.NORM.DIST((YEAR(L$7)-YEAR($F36))*12+MONTH(L$7)-MONTH($F36)+1,$H36/2,$D35,TRUE)-_xlfn.NORM.DIST((YEAR(L$7)-YEAR($F36))*12+MONTH(L$7)-MONTH($F36),$H36/2,$D35,TRUE))/(1-2*_xlfn.NORM.DIST(0,$H36/2,$D35,TRUE))*$C36,0) -> 0 | M36: =IF(AND(M$7>=$F36,M$7<=$G36),(_xlfn.NORM.DIST((YEAR(M$7)-YEAR($F36))*12+MONTH(M$7)-MONTH($F36)+1,$H36/2,$D35,TRUE)-_xlfn.NORM.DIST((YEAR(M$7)-YEAR($F36))*12+MONTH(M$7)-MONTH($F36),$H36/2,$D35,TRUE))/(1-2*_xlfn.NORM.DIST(0,$H36/2,$D35,TRUE))*$C36,0) -> 0 | N36: =IF(AND(N$7>=$F36,N$7<=$G36),(_xlfn.NORM.DIST((YEAR(N$7)-YEAR($F36))*12+MONTH(N$7)-MONTH($F36)+1,$H36/2,$D35,TRUE)-_xlfn.NORM.DIST((YEAR(N$7)-YEAR($F36))*12+MONTH(N$7)-MONTH($F36),$H36/2,$D35,TRUE))/(1-2*_xlfn.NORM.DIST(0,$H36/2,$D35,TRUE))*$C36,0) -> 0 | O36: =IF(AND(O$7>=$F36,O$7<=$G36),(_xlfn.NORM.DIST((YEAR(O$7)-YEAR($F36))*12+MONTH(O$7)-MONTH($F36)+1,$H36/2,$D35,TRUE)-_xlfn.NORM.DIST((YEAR(O$7)-YEAR($F36))*12+MONTH(O$7)-MONTH($F36),$H36/2,$D35,TRUE))/(1-2*_xlfn.NORM.DIST(0,$H36/2,$D35,TRUE))*$C36,0) -> 0 | P36: =IF(AND(P$7>=$F36,P$7<=$G36),(_xlfn.NORM.DIST((YEAR(P$7)-YEAR($F36))*12+MONTH(P$7)-MONTH($F36)+1,$H36/2,$D35,TRUE)-_xlfn.NORM.DIST((YEAR(P$7)-YEAR($F36))*12+MONTH(P$7)-MONTH($F36),$H36/2,$D35,TRUE))/(1-2*_xlfn.NORM.DIST(0,$H36/2,$D35,TRUE))*$C36,0) -> 0 | ... CZ36: =IF(AND(CZ$7>=$F36,CZ$7<=$G36),(_xlfn.NORM.DIST((YEAR(CZ$7)-YEAR($F36))*12+MONTH(CZ$7)-MONTH($F36)+1,$H36/2,$D35,TRUE)-_xlfn.NORM.DIST((YEAR(CZ$7)-YEAR($F36))*12+MONTH(CZ$7)-MONTH($F36),$H36/2,$D35,TRUE))/(1-2*_xlfn.NORM.DIST(0,$H36/2,$D35,TRUE))*$C36,0) -> 0
A37: Moderately Flat | B37: Even Distribution | C37: 1 | D37: =C37-E37 -> 0 | E37: =SUM(I37:CZ37) -> 1 | F37: =F41 -> 44986 | G37: =G41 -> 45536 | H37: =DATEDIF(F37,G37,"m")+1 -> 19 | I37: =IF(AND(I$7<=$G37,I$7>=$F37,$H37<>0,$H37<>""),$C37/$H37,0) -> 0 | J37: =IF(AND(J$7<=$G37,J$7>=$F37,$H37<>0,$H37<>""),$C37/$H37,0) -> 0 | K37: =IF(AND(K$7<=$G37,K$7>=$F37,$H37<>0,$H37<>""),$C37/$H37,0) -> 0 | L37: =IF(AND(L$7<=$G37,L$7>=$F37,$H37<>0,$H37<>""),$C37/$H37,0) -> 0 | M37: =IF(AND(M$7<=$G37,M$7>=$F37,$H37<>0,$H37<>""),$C37/$H37,0) -> 0 | N37: =IF(AND(N$7<=$G37,N$7>=$F37,$H37<>0,$H37<>""),$C37/$H37,0) -> 0 | O37: =IF(AND(O$7<=$G37,O$7>=$F37,$H37<>0,$H37<>""),$C37/$H37,0) -> 0 | P37: =IF(AND(P$7<=$G37,P$7>=$F37,$H37<>0,$H37<>""),$C37/$H37,0) -> 0 | ... CZ37: =IF(AND(CZ$7<=$G37,CZ$7>=$F37,$H37<>0,$H37<>""),$C37/$H37,0) -> 0
B38: Construction Cost Option:
B39: 1
B40: Construction % Completion | I40: =CHOOSE($B$39,I36,I37) -> 0 | J40: =CHOOSE($B$39,J36,J37)+I40 -> 0 | K40: =CHOOSE($B$39,K36,K37)+J40 -> 0 | L40: =CHOOSE($B$39,L36,L37)+K40 -> 0 | M40: =CHOOSE($B$39,M36,M37)+L40 -> 0 | N40: =CHOOSE($B$39,N36,N37)+M40 -> 0 | O40: =CHOOSE($B$39,O36,O37)+N40 -> 0 | P40: =CHOOSE($B$39,P36,P37)+O40 -> 0 | Q40: =CHOOSE($B$39,Q36,Q37)+P40 -> 0 | ... CZ40: =CHOOSE($B$39,CZ36,CZ37)+CY40 -> 1
B41: ='Development Costs'!B19 -> Construction hard cost | C41: =-'Development Costs'!H19 -> -28500000 | D41: =ROUND(C41-E41,0) -> 0 | E41: =SUM(I41:CZ41) -> -28500000 | F41: =Schedule!D17 -> 44986 | G41: =Schedule!E17 -> 45536 | H41: =DATEDIF(F41,G41,"m")+1 -> 19 | I41: =I40*$C$41 -> 0 | J41: =(J40-I40)*$C$41 -> 0 | K41: =(K40-J40)*$C$41 -> 0 | L41: =(L40-K40)*$C$41 -> 0 | M41: =(M40-L40)*$C$41 -> 0 | N41: =(N40-M40)*$C$41 -> 0 | O41: =(O40-N40)*$C$41 -> 0 | P41: =(P40-O40)*$C$41 -> 0 | Q41: =(Q40-P40)*$C$41 -> 0 | ... CZ41: =(CZ40-CY40)*$C$41 -> 0
B42: ='Development Costs'!B20 -> Offsite/Sitework Costs | C42: =-'Development Costs'!H20 -> 0 | D42: =ROUND(C42-E42,0) -> 0 | E42: =SUM(I42:CZ42) -> 0 | F42: =F41 -> 44986 | G42: =G41 -> 45536 | H42: =DATEDIF(F42,G42,"m")+1 -> 19 | I42: =IF(AND(I$7<=$G42,I$7>=$F42,$H42<>0,$H42<>""),$C42/$H42,0) -> 0 | J42: =IF(AND(J$7<=$G42,J$7>=$F42,$H42<>0,$H42<>""),$C42/$H42,0) -> 0 | K42: =IF(AND(K$7<=$G42,K$7>=$F42,$H42<>0,$H42<>""),$C42/$H42,0) -> 0 | L42: =IF(AND(L$7<=$G42,L$7>=$F42,$H42<>0,$H42<>""),$C42/$H42,0) -> 0 | M42: =IF(AND(M$7<=$G42,M$7>=$F42,$H42<>0,$H42<>""),$C42/$H42,0) -> 0 | N42: =IF(AND(N$7<=$G42,N$7>=$F42,$H42<>0,$H42<>""),$C42/$H42,0) -> 0 | O42: =IF(AND(O$7<=$G42,O$7>=$F42,$H42<>0,$H42<>""),$C42/$H42,0) -> 0 | P42: =IF(AND(P$7<=$G42,P$7>=$F42,$H42<>0,$H42<>""),$C42/$H42,0) -> 0 | ... CZ42: =IF(AND(CZ$7<=$G42,CZ$7>=$F42,$H42<>0,$H42<>""),$C42/$H42,0) -> 0
B43: ='Development Costs'!B21 -> Construction contingency | C43: =-'Development Costs'!H21 -> -1500000 | D43: =ROUND(C43-E43,0) -> 0 | E43: =SUM(I43:CZ43) -> -1500000 | F43: =F41 -> 44986 | G43: =G41 -> 45536 | H43: =DATEDIF(F43,G43,"m")+1 -> 19 | I43: =IF(AND(I$7<=$G43,I$7>=$F43,$H43<>0,$H43<>""),$C43/$H43,0) -> 0 | J43: =IF(AND(J$7<=$G43,J$7>=$F43,$H43<>0,$H43<>""),$C43/$H43,0) -> 0 | K43: =IF(AND(K$7<=$G43,K$7>=$F43,$H43<>0,$H43<>""),$C43/$H43,0) -> 0 | L43: =IF(AND(L$7<=$G43,L$7>=$F43,$H43<>0,$H43<>""),$C43/$H43,0) -> 0 | M43: =IF(AND(M$7<=$G43,M$7>=$F43,$H43<>0,$H43<>""),$C43/$H43,0) -> 0 | N43: =IF(AND(N$7<=$G43,N$7>=$F43,$H43<>0,$H43<>""),$C43/$H43,0) -> 0 | O43: =IF(AND(O$7<=$G43,O$7>=$F43,$H43<>0,$H43<>""),$C43/$H43,0) -> 0 | P43: =IF(AND(P$7<=$G43,P$7>=$F43,$H43<>0,$H43<>""),$C43/$H43,0) -> 0 | ... CZ43: =IF(AND(CZ$7<=$G43,CZ$7>=$F43,$H43<>0,$H43<>""),$C43/$H43,0) -> 0
B44: ='Development Costs'!B22 -> Total Construction Costs | C44: =-'Development Costs'!H22 -> -30000000 | D44: =C44-E44 -> 0 | E44: =SUM(I44:CZ44) -> -30000000 | I44: =SUM(I41:I43) -> 0 | J44: =SUM(J41:J43) -> 0 | K44: =SUM(K41:K43) -> 0 | L44: =SUM(L41:L43) -> 0 | M44: =SUM(M41:M43) -> 0 | N44: =SUM(N41:N43) -> 0 | O44: =SUM(O41:O43) -> 0 | P44: =SUM(P41:P43) -> 0 | ... CZ44: =SUM(CZ41:CZ43) -> 0
B46: PROFESSIONAL FEES
...

Sheet 10-Yr Cash Flow IRR
M1: ="Currently running: "&CHOOSE(Sensitivity!$E$8,Sensitivity!$B$11,Sensitivity!$B$12,Sensitivity!$B$13) -> Currently running: Base Case
A2: =Cover!A10 -> Apartment Development Model
A3: =Cover!A12 -> Suburban / Urban Location
A4: Stabilized Rental Cash Flow Analysis
B8: OTHER ASSUMPTIONS
B9: Annual Revenue Inflation | E9: 0.02 | H9: Annualized NOI at Stabilization | K9: ='Operating Revenue and Expenses'!I52 -> 2195867.5
B10: Annual Cost Inflation | E10: 0.02 | H10: Capitalization Rate | K10: ='Operating Revenue and Expenses'!E51 -> 0.04
B11: Selling Costs | E11: 0.01 | H11: Value | K11: =K9/K10 -> 54896688
B12: Min. NOI Coverage | E12: 1.1 | H12: Maximum Allowable Permanent Loan Amount | K12: =MIN(E13*K11,-PV(E14,E15,K9/E12)) -> 34760878
B13: Max. LTV @ Stabilization | E13: 0.75 | H13: Choose Loan Option: | K13: 1 | S13: Maximum Allowable Loan
B14: Permanent Loan Interest Rate | E14: 0.03 | H14: Permanent Loan Principal | K14: =IF(K13=1,K12,MIN(K12,'Development Cash Flow'!E100)) -> 34760878 | S14: Lesser of Construction Loan and Max Loan
B15: Loan Term (years) | E15: 25 | H15: Equity Requirement | K15: ='Development Costs'!H89-'10-Yr Cash Flow IRR'!K14 -> 14426905 | L15: =K14/K11 -> 0.63320537 | M15: LTV
B16: Construction Loan Ratio | E16: =+'Development Cash Flow'!D108 -> 0.89857447 | H16: Annual Debt Service | K16: =-PMT(E14/12,E15*12,K14)*12 -> 1978080.2 | L16: =K9/K16 -> 1.1101004 | M16: NOI Coverage
B19: YEAR | C19: 1 | D19: 2 | E19: 3 | F19: 4 | G19: 5 | H19: 6 | I19: 7 | J19: 8 | K19: 9 | L19: 10
C20: =YEAR(Schedule!D8) -> 2022 | D20: =C20+1 -> 2023 | E20: =D20+1 -> 2024 | F20: =E20+1 -> 2025 | G20: =F20+1 -> 2026 | H20: =G20+1 -> 2027 | I20: =H20+1 -> 2028 | J20: =I20+1 -> 2029 | K20: =J20+1 -> 2030 | L20: =K20+1 -> 2031
A21: Stabilized Holding Months | C21: =IF(C$20<YEAR(Schedule!$E$21),0,IF(C$20=YEAR(Schedule!$E$21),12-MONTH(Schedule!$E$21),12)) -> 0 | D21: =IF(D$20<YEAR(Schedule!$E$21),0,IF(D$20=YEAR(Schedule!$E$21),12-MONTH(Schedule!$E$21),12)) -> 0 | E21: =IF(E$20<YEAR(Schedule!$E$21),0,IF(E$20=YEAR(Schedule!$E$21),12-MONTH(Schedule!$E$21),12)) -> 0 | F21: =IF(F$20<YEAR(Schedule!$E$21),0,IF(F$20=YEAR(Schedule!$E$21),12-MONTH(Schedule!$E$21),12)) -> 10 | G21: =IF(G$20<YEAR(Schedule!$E$21),0,IF(G$20=YEAR(Schedule!$E$21),12-MONTH(Schedule!$E$21),12)) -> 12 | H21: =IF(H$20<YEAR(Schedule!$E$21),0,IF(H$20=YEAR(Schedule!$E$21),12-MONTH(Schedule!$E$21),12)) -> 12 | I21: =IF(I$20<YEAR(Schedule!$E$21),0,IF(I$20=YEAR(Schedule!$E$21),12-MONTH(Schedule!$E$21),12)) -> 12 | J21: =IF(J$20<YEAR(Schedule!$E$21),0,IF(J$20=YEAR(Schedule!$E$21),12-MONTH(Schedule!$E$21),12)) -> 12 | ... L21: =IF(L$20<YEAR(Schedule!$E$21),0,IF(L$20=YEAR(Schedule!$E$21),12-MONTH(Schedule!$E$21),12)) -> 12
A22: Revenue Inflation Factor | C22: =(1+$E$9)^(C20-YEAR(Schedule!$D$8)) -> 1 | D22: =(1+$E$9)^(D20-YEAR(Schedule!$D$8)) -> 1.02 | E22: =(1+$E$9)^(E20-YEAR(Schedule!$D$8)) -> 1.0404 | F22: =(1+$E$9)^(F20-YEAR(Schedule!$D$8)) -> 1.061208 | G22: =(1+$E$9)^(G20-YEAR(Schedule!$D$8)) -> 1.0824322 | H22: =(1+$E$9)^(H20-YEAR(Schedule!$D$8)) -> 1.1040808 | I22: =(1+$E$9)^(I20-YEAR(Schedule!$D$8)) -> 1.1261624 | J22: =(1+$E$9)^(J20-YEAR(Schedule!$D$8)) -> 1.1486857 | ... L22: =(1+$E$9)^(L20-YEAR(Schedule!$D$8)) -> 1.1950926
A23: Cost Inflation Factor | C23: =(1+$E$10)^(C20-YEAR(Schedule!$D$8)) -> 1 | D23: =(1+$E$10)^(D20-YEAR(Schedule!$D$8)) -> 1.02 | E23: =(1+$E$10)^(E20-YEAR(Schedule!$D$8)) -> 1.0404 | F23: =(1+$E$10)^(F20-YEAR(Schedule!$D$8)) -> 1.061208 | G23: =(1+$E$10)^(G20-YEAR(Schedule!$D$8)) -> 1.0824322 | H23: =(1+$E$10)^(H20-YEAR(Schedule!$D$8)) -> 1.1040808 | I23: =(1+$E$10)^(I20-YEAR(Schedule!$D$8)) -> 1.1261624 | J23: =(1+$E$10)^(J20-YEAR(Schedule!$D$8)) -> 1.1486857 | ... L23: =(1+$E$10)^(L20-YEAR(Schedule!$D$8)) -> 1.1950926
